Workbook
Name AxisCol: '3. Matrix'!$C$6:$C$47
Name DocStatus: '2. Details'!$C$14
Name DomainCol: '3. Matrix'!$B$6:$B$47
Name EngagementType: '2. Details'!$C$13
Name EvidenceInHand: '2. Details'!$C$15
Name InvalidNA: '3. Matrix'!$S$6:$S$47
Name InvalidNT: '3. Matrix'!$T$6:$T$47
Name InvalidScore: '3. Matrix'!$AC$6:$AC$47
Name LevelCol: '3. Matrix'!$D$6:$D$47
Name MaxPoints: '3. Matrix'!$O$6:$O$47
Name MustBlank: '3. Matrix'!$R$6:$R$47
Name MustFail: '3. Matrix'!$P$6:$P$47
Name MustPartial: '3. Matrix'!$Q$6:$Q$47
Name Organisation: '2. Details'!$C$7
Name Points: '3. Matrix'!$N$6:$N$47
Name ReportRef: '2. Details'!$C$6
Name ReportTitle: '2. Details'!$C$5
Name ReviewDate: '2. Details'!$C$20
Name Reviewer: '2. Details'!$C$19
Name ScoreCol: '3. Matrix'!$I$6:$I$47
Name ScoredFlags: '3. Matrix'!$W$6:$W$47
Name ShouldFail: '3. Matrix'!$U$6:$U$47
Name ShouldPartial: '3. Matrix'!$V$6:$V$47
Name StandardsEra: '2. Details'!$C$16

Sheet 1. Instructions & Advisory
B2: Internal Audit Report Evaluation Matrix (GIAS 2024 Conformance)
B3: Scored from the Global Internal Audit Standards (GIAS 2024 edition, effective 9 January 2025). Prepared by Majid Mumtaz | CIA, ACA, FCCA, GRCP, GRCA, COSO ERM | Director of Internal Audit & Risk Advisory, Veritux Advisory | Author of The Audit Signal. Professional QAIP gate and engagement scoring architecture.
B5: What this matrix is, and what it is not
B6: This matrix tests one communication against the Requirements in the Standards. The lines that govern a final engagement communication are Standards 15.1, 14.5, 14.4, 14.3, 14.2, 14.1, 13.4, 13.3, 13.1, 11.2, 11.3, 11.4, 11.5, 5.1, and 5.2. Standard 15.2, confirming that actions were implemented, is follow-up. It is not scored on the first assignment report. A line taken from a Requirement is a Must. A line taken from considerations is a Should. Standards 11.4 and 11.5 are Requirements that apply only when the facts exist, so G6 and G7 are Must and are N/A on an ordinary engagement. ICAEW does not publish a separate standard for the form of an internal audit report. Where an ICAEW member performs internal audit, the Standards above are the reporting requirements. The ICAEW Code of Ethics tracks Principles 1, 2, and 5 of the Standards. Those principles are scored here only through Standards 11.2, 5.1, and 5.2. The Chartered IIA Internal Audit Code of Practice, section C, describes reporting to the audit committee across the year, including an annual opinion. It is not used as a scored line on an engagement report. An opinion on the whole organisation is a different product. Score it with document type Overall opinion. That uses Standard 11.3, not the Code.
B10: Start with the document, not the first line
B11: On 2. Details, set the type, the status, and what evidence you have. Not an engagement report: stop. The scorecard returns Outside this matrix. A risk assessment or an annual plan is not scored as a failed audit report. Draft: score the lines, and use Not tested on approval, owners, dates, and management replies that are still open. The decision is prefixed Draft. A draft is not treated as an issued report that failed approval. Report only: if the page is silent on chief audit executive approval, on distribution, or on a confidentiality restriction, enter Not tested. Those requirements still exist. This review cannot see them. Not tested does not, by itself, withhold the report. Score 0 only when the record shows the requirement was broken. On an ordinary assurance or advisory report, score G6 and G7 as N/A. They apply only when this document corrects a significant error, or shows that management accepted risk above appetite.
B14: Two results
B15: Findings index: criteria, condition, cause, effect, priority, evidence, and whether significant points stand out. Close index: objectives, scope, limitations, the conclusion, the actions, the seven qualities in Standard 11.2, and issuance. A report can test well and still not be issuable. The two indexes keep those facts apart. The issue decision uses the gate, not the higher index.
B18: How to score
B19: Score | C19: Label | D19: Use it when
B20: 3 | C20: Strong | D20: The requirement is met, and the report states it specifically enough that the reader can use the point.
B21: 2 | C21: Met | D21: The requirement is met.
B22: 1 | C22: Partly met | D22: The point is present, but it is generic, incomplete, or not usable for a decision. A stated conclusion that the report then disclaims scores 1 on E1, not 0.
B23: 0 | C23: Not met | D23: Missing, contradicted, or misleading. A count of findings, with no conclusion, scores 0 on E1.
B24: N/A | C24: Not applicable | D24: Only where column L says Yes. When E1 is 0, the formula switches E2 off. Do not enter a second score for the missing conclusion.
B25: Not tested | C25: Not tested | D25: Only where the matrix says Not tested is permitted. The page or the file does not contain the evidence. Excluded from the index and from the gate.
B27: Issue decision
B28: Not tested and permitted N/A are ignored by the gate and by both indexes. A Met is 2 out of a maximum of 3, so a report that meets every scored line shows 67%. The decision is the gate. Column G on 3. Matrix looks up 6. Standards. Where a line uses a consideration rather than a Requirement, the label says so. Column H switches E2 off when E1 is 0, B2 off when B1 is N/A, D1 to D5 off when C1 is N/A, G3 off before 9 January 2025, and O1 to O5 off unless the document type is Overall opinion. The gap list shows the first 12 gaps. The counts above it include the rest. Yellow cells are the inputs. The other cells are protected so a sort or a typed formula does not break the workbook. Use Review, Unprotect Sheet. There is no password. The findings sheet holds 20 findings. Its counts feed column H. They do not write the score.
B30: Decision | C30: Rule
B31: Outside this matrix | C31: Document type is Not an engagement report.
B32: Draft — plus the gate below | C32: Status is Draft. The gate says what would happen if this text were issued as it stands.
B33: Not started | C33: No scores have been entered.
B34: Withhold | C34: Any Must that was scored is 0, any Must that should have been scored is blank, or the score is not 3, 2, 1, 0, N/A, or Not tested.
B35: Revise before issue | C35: No Must is 0, but at least one Must is 1, or three or more Should items are 0.
B36: Accept, and record the gaps | C36: Every scored Must is 2 or 3, and at least one Should is 0 or 1, with fewer than three Should items at 0.
B37: Accept | C37: Every scored Must is 2 or 3, and no Should is 0 or 1.
B39: This workbook paraphrases the Global Internal Audit Standards so a reviewer can score one communication. It is not the Standards. It is not published or endorsed by the Institute of Internal Auditors or by ICAEW. Where the workbook and the Standards differ, follow the Standards. Edition used: 9 January 2024, effective 9 January 2025.
B40: Tool: Internal Audit Report Evaluation Matrix (GIAS 2024 Conformance) | Author: Majid Mumtaz | CIA, ACA, FCCA, GRCP, GRCA, COSO ERM | Director, Veritux Advisory | Author of The Audit Signal
B41: Author & Advisory: Majid Mumtaz | CIA, ACA, FCCA, GRCP, GRCA, COSO ERM | Director of Internal Audit & Risk Advisory, Veritux Advisory | Author of The Audit Signal (LinkedIn Newsletter)
B42: Executive Portfolio: https://majidrajpar.github.io/portfolio_my/ | The Audit Signal Newsletter: https://www.linkedin.com/newsletters/the-audit-signal-7339153291630510080/ | LinkedIn: https://www.linkedin.com/in/majid-m-4b097118/
B43: Continuous Controls Monitoring (CCM) Advisory Note:
B44: For automating recurring audit ratings and continuous controls telemetry directly from your ERP/data warehouse, see the CCM Telemetry Architect: https://majidrajpar.github.io/portfolio_my/tools/ccm-telemetry-architect/

Sheet 2. Details
B2: Engagement details
B3: Yellow cells are inputs. Set type, status, evidence, and the standards era before scoring.
B4: Field | C4: Entry | D4: Note
B5: Report title | D5: Title as it appears on the communication.
B6: Report reference | D6: Document number or engagement code.
B7: Organisation | D7: Entity under review.
B8: Activity reviewed | D8: Process, function, or risk area.
B9: Period covered | D9: The period the conclusion relates to.
B10: Fieldwork completed | D10: Date fieldwork ended.
B11: Report date | D11: Date of the version under review. Use the printed date.
B12: Version | D12: Draft number, or Final.
B13: Document type | D13: Assurance, Advisory, Overall opinion, or Not an engagement report.
B14: Status | D14: Final or Draft.
B15: Evidence in this review | D15: Report only, or Report and file.
B16: Standards era | D16: Before 9 January 2025, or On or after 9 January 2025. This drives line G3.
... B21: File reference | D21: Where the working papers are, if they were used.
B23: Scope of this review
B24: Record what you could not see: a missing appendix, a sanitized copy, or a file that was not opened. Redaction is not an audit failure. Enter Not tested on an owner, a date, or timeliness when the copy has removed them.

Sheet 3. Matrix
A1: Evaluation matrix
A2: Column G looks up the Standard on 6. Standards. Column H is a formula and shows when another line switches this one off. Score in column I: 3, 2, 1, 0, N/A, or Not tested. N/A and Not tested only where the columns say Yes. A score of 0, 1, N/A, or Not tested needs a comment.
A3: =IF(ReportTitle="","Set 2. Details first.","Report: "&ReportTitle&" | "&IF(EngagementType="","(set document type)",EngagementType)&" | "&IF(DocStatus="","(set status)",DocStatus)&" | "&IF(StandardsEra="","(set standards era)",StandardsEra))
A5: Ref | B5: Domain | C5: Index | D5: Level | E5: Criterion | F5: What the standard requires | G5: Source | H5: Depends on | I5: Score | J5: Evidence | K5: Comment | L5: N/A ok | M5: Not tested ok | N5: Points | O5: Max | P5: Must0 | Q5: Must1 | R5: MustBlank | S5: BadNA | T5: BadNT | U5: Should0 | V5: Should1 | W5: Scored | X5: Num | Y5: Gap | Z5: GapNo | AA5: Switch | AB5: StdKey | AC5: BadScore
A6: A1 | B6: Objectives and scope | C6: Close | D6: Must | E6: Objectives state the purpose and the specific goals | F6: The report states what the engagement set out to achieve, specifically enough that the conclusion can answer it. A single line that only says the work reviewed the existence and effectiveness of key controls scores 1. | G6: ="13.3 "&INDEX('6. Standards'!$B$5:$B$21,MATCH("13.3",'6. Standards'!$A$5:$A$21,0))&" — "&INDEX('6. Standards'!$C$5:$C$21,MATCH("13.3",'6. Standards'!$A$5:$A$21,0))&CHAR(10)&"15.1 "&INDEX('6. Standards'!$B$5:$B$21,MATCH("15.1",'6. Standards'!$A$5:$A$21,0))&" — "&INDEX('6. Standards'!$C$5:$C$21,MATCH("15.1",'6. Standards'!$A$5:$A$21,0)) | H6: ="No other line switches this off." | L6: No | M6: No | N6: =IF(OR(OR(AA6,AND(UPPER(TRIM(I6&""))="N/A",L6="Yes"),AND(UPPER(TRIM(I6&""))="NOT TESTED",M6="Yes")),OR(AND(UPPER(TRIM(I6&""))="N/A",L6<>"Yes"),AND(UPPER(TRIM(I6&""))="NOT TESTED",M6<>"Yes"),AND(NOT(I6=""),NOT(UPPER(TRIM(I6&""))="N/A"),NOT(UPPER(TRIM(I6&""))="NOT TESTED"),NOT(AND(ISNUMBER(IFERROR(VALUE(I6&""),"")),OR(IFERROR(VALUE(I6&""),"")=0,IFERROR(VALUE(I6&""),"")=1,IFERROR(VALUE(I6&""),"")=2,IFERROR(VALUE(I6&""),"")=3)))))),0,IF(AND(ISNUMBER(IFERROR(VALUE(I6&""),"")),OR(IFERROR(VALUE(I6&""),"")=0,IFERROR(VALUE(I6&""),"")=1,IFERROR(VALUE(I6&""),"")=2,IFERROR(VALUE(I6&""),"")=3)),IFERROR(VALUE(I6&""),"")*IF(D6="Must",2,1),0)) | O6: =IF(OR(AA6,AND(UPPER(TRIM(I6&""))="N/A",L6="Yes"),AND(UPPER(TRIM(I6&""))="NOT TESTED",M6="Yes")),0,IF(OR(OR(AND(UPPER(TRIM(I6&""))="N/A",L6<>"Yes"),AND(UPPER(TRIM(I6&""))="NOT TESTED",M6<>"Yes"),AND(NOT(I6=""),NOT(UPPER(TRIM(I6&""))="N/A"),NOT(UPPER(TRIM(I6&""))="NOT TESTED"),NOT(AND(ISNUMBER(IFERROR(VALUE(I6&""),"")),OR(IFERROR(VALUE(I6&""),"")=0,IFERROR(VALUE(I6&""),"")=1,IFERROR(VALUE(I6&""),"")=2,IFERROR(VALUE(I6&""),"")=3))))),AND(ISNUMBER(IFERROR(VALUE(I6&""),"")),OR(IFERROR(VALUE(I6&""),"")=0,IFERROR(VALUE(I6&""),"")=1,IFERROR(VALUE(I6&""),"")=2,IFERROR(VALUE(I6&""),"")=3))),3*IF(D6="Must",2,1),0)) | P6: =IF(OR(AA6,NOT(AND(D6="Must",ISNUMBER(X6),X6=0))),0,1) | Q6: =IF(OR(AA6,NOT(AND(D6="Must",ISNUMBER(X6),X6=1))),0,1) | R6: =IF(AND(NOT(AA6),D6="Must",I6=""),1,0) | S6: =IF(AND(NOT(AA6),UPPER(TRIM(I6&""))="N/A",L6<>"Yes"),1,0) | T6: =IF(AND(NOT(AA6),UPPER(TRIM(I6&""))="NOT TESTED",M6<>"Yes"),1,0) | U6: =IF(OR(AA6,NOT(AND(D6="Should",ISNUMBER(X6),X6=0))),0,1) | V6: =IF(OR(AA6,NOT(AND(D6="Should",ISNUMBER(X6),X6=1))),0,1) | W6: =IF(OR(I6="",AA6),0,1) | X6: =IF(I6="","",IF(UPPER(TRIM(I6&""))="N/A","N/A",IF(UPPER(TRIM(I6&""))="NOT TESTED","NT",IF(AND(ISNUMBER(IFERROR(VALUE(I6&""),"")),OR(IFERROR(VALUE(I6&""),"")=0,IFERROR(VALUE(I6&""),"")=1,IFERROR(VALUE(I6&""),"")=2,IFERROR(VALUE(I6&""),"")=3)),IFERROR(VALUE(I6&""),""),"BAD")))) | Y6: =IF(OR(AA6,NOT(OR(AND(D6="Must",I6="",SUM($W$6:$W$47)>0),AND(ISNUMBER(X6),X6<2),AND(UPPER(TRIM(I6&""))="N/A",L6<>"Yes"),AND(UPPER(TRIM(I6&""))="NOT TESTED",M6<>"Yes"),AND(NOT(I6=""),NOT(UPPER(TRIM(I6&""))="N/A"),NOT(UPPER(TRIM(I6&""))="NOT TESTED"),NOT(AND(ISNUMBER(IFERROR(VALUE(I6&""),"")),OR(IFERROR(VALUE(I6&""),"")=0,IFERROR(VALUE(I6&""),"")=1,IFERROR(VALUE(I6&""),"")=2,IFERROR(VALUE(I6&""),"")=3))))))),0,1) | Z6: =IF(Y6=1,COUNTIF($Y$6:Y6,1),0) | AA6: =OR(AND(LEFT(A6,1)="O",EngagementType<>"Overall opinion"),AND(A6="G3",StandardsEra="Before 9 January 2025"),AND(A6="E2",OR(INDEX($I$6:$I$47,MATCH("E1",$A$6:$A$47,0))=0,INDEX($I$6:$I$47,MATCH("E1",$A$6:$A$47,0))="0")),AND(A6="B2",UPPER(TRIM(INDEX($I$6:$I$47,MATCH("B1",$A$6:$A$47,0))&""))="N/A"),AND(OR(A6="D1",A6="D2",A6="D3",A6="D4",A6="D5"),UPPER(TRIM(INDEX($I$6:$I$47,MATCH("C1",$A$6:$A$47,0))&""))="N/A")) | AB6: 13.3;15.1 | AC6: =IF(AND(NOT(AA6),AND(NOT(I6=""),NOT(UPPER(TRIM(I6&""))="N/A"),NOT(UPPER(TRIM(I6&""))="NOT TESTED"),NOT(AND(ISNUMBER(IFERROR(VALUE(I6&""),"")),OR(IFERROR(VALUE(I6&""),"")=0,IFERROR(VALUE(I6&""),"")=1,IFERROR(VALUE(I6&""),"")=2,IFERROR(VALUE(I6&""),"")=3))))),1,0)
A7: A2 | B7: Objectives and scope | C7: Close | D7: Must | E7: Scope sets the boundaries | F7: Scope names the activities, the locations or units, the processes or systems, and the period, and it is wide enough to meet the objectives. A period and a process name, with no units and no boundary, scores 1. | G7: ="13.3 "&INDEX('6. Standards'!$B$5:$B$21,MATCH("13.3",'6. Standards'!$A$5:$A$21,0))&" — "&INDEX('6. Standards'!$C$5:$C$21,MATCH("13.3",'6. Standards'!$A$5:$A$21,0))&CHAR(10)&"15.1 "&INDEX('6. Standards'!$B$5:$B$21,MATCH("15.1",'6. Standards'!$A$5:$A$21,0))&" — "&INDEX('6. Standards'!$C$5:$C$21,MATCH("15.1",'6. Standards'!$A$5:$A$21,0)) | H7: ="No other line switches this off." | L7: No | M7: No | N7: =IF(OR(OR(AA7,AND(UPPER(TRIM(I7&""))="N/A",L7="Yes"),AND(UPPER(TRIM(I7&""))="NOT TESTED",M7="Yes")),OR(AND(UPPER(TRIM(I7&""))="N/A",L7<>"Yes"),AND(UPPER(TRIM(I7&""))="NOT TESTED",M7<>"Yes"),AND(NOT(I7=""),NOT(UPPER(TRIM(I7&""))="N/A"),NOT(UPPER(TRIM(I7&""))="NOT TESTED"),NOT(AND(ISNUMBER(IFERROR(VALUE(I7&""),"")),OR(IFERROR(VALUE(I7&""),"")=0,IFERROR(VALUE(I7&""),"")=1,IFERROR(VALUE(I7&""),"")=2,IFERROR(VALUE(I7&""),"")=3)))))),0,IF(AND(ISNUMBER(IFERROR(VALUE(I7&""),"")),OR(IFERROR(VALUE(I7&""),"")=0,IFERROR(VALUE(I7&""),"")=1,IFERROR(VALUE(I7&""),"")=2,IFERROR(VALUE(I7&""),"")=3)),IFERROR(VALUE(I7&""),"")*IF(D7="Must",2,1),0)) | O7: =IF(OR(AA7,AND(UPPER(TRIM(I7&""))="N/A",L7="Yes"),AND(UPPER(TRIM(I7&""))="NOT TESTED",M7="Yes")),0,IF(OR(OR(AND(UPPER(TRIM(I7&""))="N/A",L7<>"Yes"),AND(UPPER(TRIM(I7&""))="NOT TESTED",M7<>"Yes"),AND(NOT(I7=""),NOT(UPPER(TRIM(I7&""))="N/A"),NOT(UPPER(TRIM(I7&""))="NOT TESTED"),NOT(AND(ISNUMBER(IFERROR(VALUE(I7&""),"")),OR(IFERROR(VALUE(I7&""),"")=0,IFERROR(VALUE(I7&""),"")=1,IFERROR(VALUE(I7&""),"")=2,IFERROR(VALUE(I7&""),"")=3))))),AND(ISNUMBER(IFERROR(VALUE(I7&""),"")),OR(IFERROR(VALUE(I7&""),"")=0,IFERROR(VALUE(I7&""),"")=1,IFERROR(VALUE(I7&""),"")=2,IFERROR(VALUE(I7&""),"")=3))),3*IF(D7="Must",2,1),0)) | P7: =IF(OR(AA7,NOT(AND(D7="Must",ISNUMBER(X7),X7=0))),0,1) | Q7: =IF(OR(AA7,NOT(AND(D7="Must",ISNUMBER(X7),X7=1))),0,1) | R7: =IF(AND(NOT(AA7),D7="Must",I7=""),1,0) | S7: =IF(AND(NOT(AA7),UPPER(TRIM(I7&""))="N/A",L7<>"Yes"),1,0) | T7: =IF(AND(NOT(AA7),UPPER(TRIM(I7&""))="NOT TESTED",M7<>"Yes"),1,0) | U7: =IF(OR(AA7,NOT(AND(D7="Should",ISNUMBER(X7),X7=0))),0,1) | V7: =IF(OR(AA7,NOT(AND(D7="Should",ISNUMBER(X7),X7=1))),0,1) | W7: =IF(OR(I7="",AA7),0,1) | X7: =IF(I7="","",IF(UPPER(TRIM(I7&""))="N/A","N/A",IF(UPPER(TRIM(I7&""))="NOT TESTED","NT",IF(AND(ISNUMBER(IFERROR(VALUE(I7&""),"")),OR(IFERROR(VALUE(I7&""),"")=0,IFERROR(VALUE(I7&""),"")=1,IFERROR(VALUE(I7&""),"")=2,IFERROR(VALUE(I7&""),"")=3)),IFERROR(VALUE(I7&""),""),"BAD")))) | Y7: =IF(OR(AA7,NOT(OR(AND(D7="Must",I7="",SUM($W$6:$W$47)>0),AND(ISNUMBER(X7),X7<2),AND(UPPER(TRIM(I7&""))="N/A",L7<>"Yes"),AND(UPPER(TRIM(I7&""))="NOT TESTED",M7<>"Yes"),AND(NOT(I7=""),NOT(UPPER(TRIM(I7&""))="N/A"),NOT(UPPER(TRIM(I7&""))="NOT TESTED"),NOT(AND(ISNUMBER(IFERROR(VALUE(I7&""),"")),OR(IFERROR(VALUE(I7&""),"")=0,IFERROR(VALUE(I7&""),"")=1,IFERROR(VALUE(I7&""),"")=2,IFERROR(VALUE(I7&""),"")=3))))))),0,1) | Z7: =IF(Y7=1,COUNTIF($Y$6:Y7,1),0) | AA7: =OR(AND(LEFT(A7,1)="O",EngagementType<>"Overall opinion"),AND(A7="G3",StandardsEra="Before 9 January 2025"),AND(A7="E2",OR(INDEX($I$6:$I$47,MATCH("E1",$A$6:$A$47,0))=0,INDEX($I$6:$I$47,MATCH("E1",$A$6:$A$47,0))="0")),AND(A7="B2",UPPER(TRIM(INDEX($I$6:$I$47,MATCH("B1",$A$6:$A$47,0))&""))="N/A"),AND(OR(A7="D1",A7="D2",A7="D3",A7="D4",A7="D5"),UPPER(TRIM(INDEX($I$6:$I$47,MATCH("C1",$A$6:$A$47,0))&""))="N/A")) | AB7: 13.3;15.1 | AC7: =IF(AND(NOT(AA7),AND(NOT(I7=""),NOT(UPPER(TRIM(I7&""))="N/A"),NOT(UPPER(TRIM(I7&""))="NOT TESTED"),NOT(AND(ISNUMBER(IFERROR(VALUE(I7&""),"")),OR(IFERROR(VALUE(I7&""),"")=0,IFERROR(VALUE(I7&""),"")=1,IFERROR(VALUE(I7&""),"")=2,IFERROR(VALUE(I7&""),"")=3))))),1,0)
A8: A3 | B8: Objectives and scope | C8: Close | D8: Must | E8: Scope limitations are explained | F8: A limitation that stopped the work is described, with its effect on the conclusion. Use N/A when the report does not show a scope limitation. A general sentence that the work may not have found every weakness, with no effect on the conclusion, scores 1. | G8: ="15.1 "&INDEX('6. Standards'!$B$5:$B$21,MATCH("15.1",'6. Standards'!$A$5:$A$21,0))&" — "&INDEX('6. Standards'!$C$5:$C$21,MATCH("15.1",'6. Standards'!$A$5:$A$21,0))&CHAR(10)&"13.3 "&INDEX('6. Standards'!$B$5:$B$21,MATCH("13.3",'6. Standards'!$A$5:$A$21,0))&" — "&INDEX('6. Standards'!$C$5:$C$21,MATCH("13.3",'6. Standards'!$A$5:$A$21,0)) | H8: ="No other line switches this off." | L8: Yes | M8: No | N8: =IF(OR(OR(AA8,AND(UPPER(TRIM(I8&""))="N/A",L8="Yes"),AND(UPPER(TRIM(I8&""))="NOT TESTED",M8="Yes")),OR(AND(UPPER(TRIM(I8&""))="N/A",L8<>"Yes"),AND(UPPER(TRIM(I8&""))="NOT TESTED",M8<>"Yes"),AND(NOT(I8=""),NOT(UPPER(TRIM(I8&""))="N/A"),NOT(UPPER(TRIM(I8&""))="NOT TESTED"),NOT(AND(ISNUMBER(IFERROR(VALUE(I8&""),"")),OR(IFERROR(VALUE(I8&""),"")=0,IFERROR(VALUE(I8&""),"")=1,IFERROR(VALUE(I8&""),"")=2,IFERROR(VALUE(I8&""),"")=3)))))),0,IF(AND(ISNUMBER(IFERROR(VALUE(I8&""),"")),OR(IFERROR(VALUE(I8&""),"")=0,IFERROR(VALUE(I8&""),"")=1,IFERROR(VALUE(I8&""),"")=2,IFERROR(VALUE(I8&""),"")=3)),IFERROR(VALUE(I8&""),"")*IF(D8="Must",2,1),0)) | O8: =IF(OR(AA8,AND(UPPER(TRIM(I8&""))="N/A",L8="Yes"),AND(UPPER(TRIM(I8&""))="NOT TESTED",M8="Yes")),0,IF(OR(OR(AND(UPPER(TRIM(I8&""))="N/A",L8<>"Yes"),AND(UPPER(TRIM(I8&""))="NOT TESTED",M8<>"Yes"),AND(NOT(I8=""),NOT(UPPER(TRIM(I8&""))="N/A"),NOT(UPPER(TRIM(I8&""))="NOT TESTED"),NOT(AND(ISNUMBER(IFERROR(VALUE(I8&""),"")),OR(IFERROR(VALUE(I8&""),"")=0,IFERROR(VALUE(I8&""),"")=1,IFERROR(VALUE(I8&""),"")=2,IFERROR(VALUE(I8&""),"")=3))))),AND(ISNUMBER(IFERROR(VALUE(I8&""),"")),OR(IFERROR(VALUE(I8&""),"")=0,IFERROR(VALUE(I8&""),"")=1,IFERROR(VALUE(I8&""),"")=2,IFERROR(VALUE(I8&""),"")=3))),3*IF(D8="Must",2,1),0)) | P8: =IF(OR(AA8,NOT(AND(D8="Must",ISNUMBER(X8),X8=0))),0,1) | Q8: =IF(OR(AA8,NOT(AND(D8="Must",ISNUMBER(X8),X8=1))),0,1) | R8: =IF(AND(NOT(AA8),D8="Must",I8=""),1,0) | S8: =IF(AND(NOT(AA8),UPPER(TRIM(I8&""))="N/A",L8<>"Yes"),1,0) | T8: =IF(AND(NOT(AA8),UPPER(TRIM(I8&""))="NOT TESTED",M8<>"Yes"),1,0) | U8: =IF(OR(AA8,NOT(AND(D8="Should",ISNUMBER(X8),X8=0))),0,1) | V8: =IF(OR(AA8,NOT(AND(D8="Should",ISNUMBER(X8),X8=1))),0,1) | W8: =IF(OR(I8="",AA8),0,1) | X8: =IF(I8="","",IF(UPPER(TRIM(I8&""))="N/A","N/A",IF(UPPER(TRIM(I8&""))="NOT TESTED","NT",IF(AND(ISNUMBER(IFERROR(VALUE(I8&""),"")),OR(IFERROR(VALUE(I8&""),"")=0,IFERROR(VALUE(I8&""),"")=1,IFERROR(VALUE(I8&""),"")=2,IFERROR(VALUE(I8&""),"")=3)),IFERROR(VALUE(I8&""),""),"BAD")))) | Y8: =IF(OR(AA8,NOT(OR(AND(D8="Must",I8="",SUM($W$6:$W$47)>0),AND(ISNUMBER(X8),X8<2),AND(UPPER(TRIM(I8&""))="N/A",L8<>"Yes"),AND(UPPER(TRIM(I8&""))="NOT TESTED",M8<>"Yes"),AND(NOT(I8=""),NOT(UPPER(TRIM(I8&""))="N/A"),NOT(UPPER(TRIM(I8&""))="NOT TESTED"),NOT(AND(ISNUMBER(IFERROR(VALUE(I8&""),"")),OR(IFERROR(VALUE(I8&""),"")=0,IFERROR(VALUE(I8&""),"")=1,IFERROR(VALUE(I8&""),"")=2,IFERROR(VALUE(I8&""),"")=3))))))),0,1) | Z8: =IF(Y8=1,COUNTIF($Y$6:Y8,1),0) | AA8: =OR(AND(LEFT(A8,1)="O",EngagementType<>"Overall opinion"),AND(A8="G3",StandardsEra="Before 9 January 2025"),AND(A8="E2",OR(INDEX($I$6:$I$47,MATCH("E1",$A$6:$A$47,0))=0,INDEX($I$6:$I$47,MATCH("E1",$A$6:$A$47,0))="0")),AND(A8="B2",UPPER(TRIM(INDEX($I$6:$I$47,MATCH("B1",$A$6:$A$47,0))&""))="N/A"),AND(OR(A8="D1",A8="D2",A8="D3",A8="D4",A8="D5"),UPPER(TRIM(INDEX($I$6:$I$47,MATCH("C1",$A$6:$A$47,0))&""))="N/A")) | AB8: 15.1;13.3 | AC8: =IF(AND(NOT(AA8),AND(NOT(I8=""),NOT(UPPER(TRIM(I8&""))="N/A"),NOT(UPPER(TRIM(I8&""))="NOT TESTED"),NOT(AND(ISNUMBER(IFERROR(VALUE(I8&""),"")),OR(IFERROR(VALUE(I8&""),"")=0,IFERROR(VALUE(I8&""),"")=1,IFERROR(VALUE(I8&""),"")=2,IFERROR(VALUE(I8&""),"")=3))))),1,0)
A9: B1 | B9: Criteria | C9: Findings | D9: Must | E9: Evaluation criteria are identified | F9: The report names the benchmark: a policy, law, regulation, contract, framework, or stated control objective. “As per practice” or “key controls,” with no source, scores 1. Use N/A only for an advisory engagement whose terms did not require criteria. | G9: ="13.4 "&INDEX('6. Standards'!$B$5:$B$21,MATCH("13.4",'6. Standards'!$A$5:$A$21,0))&" — "&INDEX('6. Standards'!$C$5:$C$21,MATCH("13.4",'6. Standards'!$A$5:$A$21,0))&CHAR(10)&"14.2 "&INDEX('6. Standards'!$B$5:$B$21,MATCH("14.2",'6. Standards'!$A$5:$A$21,0))&" — "&INDEX('6. Standards'!$C$5:$C$21,MATCH("14.2",'6. Standards'!$A$5:$A$21,0)) | H9: ="No other line switches this off."&IF(COUNTA('4. Findings'!A8:A27)=0,""," Findings sheet, criteria: "&COUNTIF('4. Findings'!C$8:C$27,"Y")&" Y, "&COUNTIF('4. Findings'!C$8:C$27,"P")&" P, "&COUNTIF('4. Findings'!C$8:C$27,"N")&" N.") | L9: Yes | M9: No | N9: =IF(OR(OR(AA9,AND(UPPER(TRIM(I9&""))="N/A",L9="Yes"),AND(UPPER(TRIM(I9&""))="NOT TESTED",M9="Yes")),OR(AND(UPPER(TRIM(I9&""))="N/A",L9<>"Yes"),AND(UPPER(TRIM(I9&""))="NOT TESTED",M9<>"Yes"),AND(NOT(I9=""),NOT(UPPER(TRIM(I9&""))="N/A"),NOT(UPPER(TRIM(I9&""))="NOT TESTED"),NOT(AND(ISNUMBER(IFERROR(VALUE(I9&""),"")),OR(IFERROR(VALUE(I9&""),"")=0,IFERROR(VALUE(I9&""),"")=1,IFERROR(VALUE(I9&""),"")=2,IFERROR(VALUE(I9&""),"")=3)))))),0,IF(AND(ISNUMBER(IFERROR(VALUE(I9&""),"")),OR(IFERROR(VALUE(I9&""),"")=0,IFERROR(VALUE(I9&""),"")=1,IFERROR(VALUE(I9&""),"")=2,IFERROR(VALUE(I9&""),"")=3)),IFERROR(VALUE(I9&""),"")*IF(D9="Must",2,1),0)) | O9: =IF(OR(AA9,AND(UPPER(TRIM(I9&""))="N/A",L9="Yes"),AND(UPPER(TRIM(I9&""))="NOT TESTED",M9="Yes")),0,IF(OR(OR(AND(UPPER(TRIM(I9&""))="N/A",L9<>"Yes"),AND(UPPER(TRIM(I9&""))="NOT TESTED",M9<>"Yes"),AND(NOT(I9=""),NOT(UPPER(TRIM(I9&""))="N/A"),NOT(UPPER(TRIM(I9&""))="NOT TESTED"),NOT(AND(ISNUMBER(IFERROR(VALUE(I9&""),"")),OR(IFERROR(VALUE(I9&""),"")=0,IFERROR(VALUE(I9&""),"")=1,IFERROR(VALUE(I9&""),"")=2,IFERROR(VALUE(I9&""),"")=3))))),AND(ISNUMBER(IFERROR(VALUE(I9&""),"")),OR(IFERROR(VALUE(I9&""),"")=0,IFERROR(VALUE(I9&""),"")=1,IFERROR(VALUE(I9&""),"")=2,IFERROR(VALUE(I9&""),"")=3))),3*IF(D9="Must",2,1),0)) | P9: =IF(OR(AA9,NOT(AND(D9="Must",ISNUMBER(X9),X9=0))),0,1) | Q9: =IF(OR(AA9,NOT(AND(D9="Must",ISNUMBER(X9),X9=1))),0,1) | R9: =IF(AND(NOT(AA9),D9="Must",I9=""),1,0) | S9: =IF(AND(NOT(AA9),UPPER(TRIM(I9&""))="N/A",L9<>"Yes"),1,0) | T9: =IF(AND(NOT(AA9),UPPER(TRIM(I9&""))="NOT TESTED",M9<>"Yes"),1,0) | U9: =IF(OR(AA9,NOT(AND(D9="Should",ISNUMBER(X9),X9=0))),0,1) | V9: =IF(OR(AA9,NOT(AND(D9="Should",ISNUMBER(X9),X9=1))),0,1) | W9: =IF(OR(I9="",AA9),0,1) | X9: =IF(I9="","",IF(UPPER(TRIM(I9&""))="N/A","N/A",IF(UPPER(TRIM(I9&""))="NOT TESTED","NT",IF(AND(ISNUMBER(IFERROR(VALUE(I9&""),"")),OR(IFERROR(VALUE(I9&""),"")=0,IFERROR(VALUE(I9&""),"")=1,IFERROR(VALUE(I9&""),"")=2,IFERROR(VALUE(I9&""),"")=3)),IFERROR(VALUE(I9&""),""),"BAD")))) | Y9: =IF(OR(AA9,NOT(OR(AND(D9="Must",I9="",SUM($W$6:$W$47)>0),AND(ISNUMBER(X9),X9<2),AND(UPPER(TRIM(I9&""))="N/A",L9<>"Yes"),AND(UPPER(TRIM(I9&""))="NOT TESTED",M9<>"Yes"),AND(NOT(I9=""),NOT(UPPER(TRIM(I9&""))="N/A"),NOT(UPPER(TRIM(I9&""))="NOT TESTED"),NOT(AND(ISNUMBER(IFERROR(VALUE(I9&""),"")),OR(IFERROR(VALUE(I9&""),"")=0,IFERROR(VALUE(I9&""),"")=1,IFERROR(VALUE(I9&""),"")=2,IFERROR(VALUE(I9&""),"")=3))))))),0,1) | Z9: =IF(Y9=1,COUNTIF($Y$6:Y9,1),0) | AA9: =OR(AND(LEFT(A9,1)="O",EngagementType<>"Overall opinion"),AND(A9="G3",StandardsEra="Before 9 January 2025"),AND(A9="E2",OR(INDEX($I$6:$I$47,MATCH("E1",$A$6:$A$47,0))=0,INDEX($I$6:$I$47,MATCH("E1",$A$6:$A$47,0))="0")),AND(A9="B2",UPPER(TRIM(INDEX($I$6:$I$47,MATCH("B1",$A$6:$A$47,0))&""))="N/A"),AND(OR(A9="D1",A9="D2",A9="D3",A9="D4",A9="D5"),UPPER(TRIM(INDEX($I$6:$I$47,MATCH("C1",$A$6:$A$47,0))&""))="N/A")) | AB9: 13.4;14.2 | AC9: =IF(AND(NOT(AA9),AND(NOT(I9=""),NOT(UPPER(TRIM(I9&""))="N/A"),NOT(UPPER(TRIM(I9&""))="NOT TESTED"),NOT(AND(ISNUMBER(IFERROR(VALUE(I9&""),"")),OR(IFERROR(VALUE(I9&""),"")=0,IFERROR(VALUE(I9&""),"")=1,IFERROR(VALUE(I9&""),"")=2,IFERROR(VALUE(I9&""),"")=3))))),1,0)
A10: B2 | B10: Criteria | C10: Findings | D10: Must | E10: Criteria are adequate | F10: The criteria are relevant, aligned to the objectives of the activity, and able to support a reliable comparison. Another competent auditor could apply them. Use N/A when B1 is N/A. | G10: ="13.4 "&INDEX('6. Standards'!$B$5:$B$21,MATCH("13.4",'6. Standards'!$A$5:$A$21,0))&" — "&INDEX('6. Standards'!$C$5:$C$21,MATCH("13.4",'6. Standards'!$A$5:$A$21,0)) | H10: =IF(UPPER(TRIM(INDEX($I$6:$I$47,MATCH("B1",$A$6:$A$47,0))&""))="N/A","Off. "&INDEX($A$6:$A$47,MATCH("B1",$A$6:$A$47,0))&" is N/A, so this line is not scored.","On. Use N/A only when "&INDEX($A$6:$A$47,MATCH("B1",$A$6:$A$47,0))&" is N/A. "&INDEX($A$6:$A$47,MATCH("B1",$A$6:$A$47,0))&" is "&IF(INDEX($I$6:$I$47,MATCH("B1",$A$6:$A$47,0))="","blank",INDEX($I$6:$I$47,MATCH("B1",$A$6:$A$47,0)))&".")&IF(COUNTA('4. Findings'!A8:A27)=0,""," Findings sheet, criteria: "&COUNTIF('4. Findings'!C$8:C$27,"Y")&" Y, "&COUNTIF('4. Findings'!C$8:C$27,"P")&" P, "&COUNTIF('4. Findings'!C$8:C$27,"N")&" N.") | L10: Yes | M10: No | N10: =IF(OR(OR(AA10,AND(UPPER(TRIM(I10&""))="N/A",L10="Yes"),AND(UPPER(TRIM(I10&""))="NOT TESTED",M10="Yes")),OR(AND(UPPER(TRIM(I10&""))="N/A",L10<>"Yes"),AND(UPPER(TRIM(I10&""))="NOT TESTED",M10<>"Yes"),AND(NOT(I10=""),NOT(UPPER(TRIM(I10&""))="N/A"),NOT(UPPER(TRIM(I10&""))="NOT TESTED"),NOT(AND(ISNUMBER(IFERROR(VALUE(I10&""),"")),OR(IFERROR(VALUE(I10&""),"")=0,IFERROR(VALUE(I10&""),"")=1,IFERROR(VALUE(I10&""),"")=2,IFERROR(VALUE(I10&""),"")=3)))))),0,IF(AND(ISNUMBER(IFERROR(VALUE(I10&""),"")),OR(IFERROR(VALUE(I10&""),"")=0,IFERROR(VALUE(I10&""),"")=1,IFERROR(VALUE(I10&""),"")=2,IFERROR(VALUE(I10&""),"")=3)),IFERROR(VALUE(I10&""),"")*IF(D10="Must",2,1),0)) | O10: =IF(OR(AA10,AND(UPPER(TRIM(I10&""))="N/A",L10="Yes"),AND(UPPER(TRIM(I10&""))="NOT TESTED",M10="Yes")),0,IF(OR(OR(AND(UPPER(TRIM(I10&""))="N/A",L10<>"Yes"),AND(UPPER(TRIM(I10&""))="NOT TESTED",M10<>"Yes"),AND(NOT(I10=""),NOT(UPPER(TRIM(I10&""))="N/A"),NOT(UPPER(TRIM(I10&""))="NOT TESTED"),NOT(AND(ISNUMBER(IFERROR(VALUE(I10&""),"")),OR(IFERROR(VALUE(I10&""),"")=0,IFERROR(VALUE(I10&""),"")=1,IFERROR(VALUE(I10&""),"")=2,IFERROR(VALUE(I10&""),"")=3))))),AND(ISNUMBER(IFERROR(VALUE(I10&""),"")),OR(IFERROR(VALUE(I10&""),"")=0,IFERROR(VALUE(I10&""),"")=1,IFERROR(VALUE(I10&""),"")=2,IFERROR(VALUE(I10&""),"")=3))),3*IF(D10="Must",2,1),0)) | P10: =IF(OR(AA10,NOT(AND(D10="Must",ISNUMBER(X10),X10=0))),0,1) | Q10: =IF(OR(AA10,NOT(AND(D10="Must",ISNUMBER(X10),X10=1))),0,1) | R10: =IF(AND(NOT(AA10),D10="Must",I10=""),1,0) | S10: =IF(AND(NOT(AA10),UPPER(TRIM(I10&""))="N/A",L10<>"Yes"),1,0) | T10: =IF(AND(NOT(AA10),UPPER(TRIM(I10&""))="NOT TESTED",M10<>"Yes"),1,0) | U10: =IF(OR(AA10,NOT(AND(D10="Should",ISNUMBER(X10),X10=0))),0,1) | V10: =IF(OR(AA10,NOT(AND(D10="Should",ISNUMBER(X10),X10=1))),0,1) | W10: =IF(OR(I10="",AA10),0,1) | X10: =IF(I10="","",IF(UPPER(TRIM(I10&""))="N/A","N/A",IF(UPPER(TRIM(I10&""))="NOT TESTED","NT",IF(AND(ISNUMBER(IFERROR(VALUE(I10&""),"")),OR(IFERROR(VALUE(I10&""),"")=0,IFERROR(VALUE(I10&""),"")=1,IFERROR(VALUE(I10&""),"")=2,IFERROR(VALUE(I10&""),"")=3)),IFERROR(VALUE(I10&""),""),"BAD")))) | Y10: =IF(OR(AA10,NOT(OR(AND(D10="Must",I10="",SUM($W$6:$W$47)>0),AND(ISNUMBER(X10),X10<2),AND(UPPER(TRIM(I10&""))="N/A",L10<>"Yes"),AND(UPPER(TRIM(I10&""))="NOT TESTED",M10<>"Yes"),AND(NOT(I10=""),NOT(UPPER(TRIM(I10&""))="N/A"),NOT(UPPER(TRIM(I10&""))="NOT TESTED"),NOT(AND(ISNUMBER(IFERROR(VALUE(I10&""),"")),OR(IFERROR(VALUE(I10&""),"")=0,IFERROR(VALUE(I10&""),"")=1,IFERROR(VALUE(I10&""),"")=2,IFERROR(VALUE(I10&""),"")=3))))))),0,1) | Z10: =IF(Y10=1,COUNTIF($Y$6:Y10,1),0) | AA10: =OR(AND(LEFT(A10,1)="O",EngagementType<>"Overall opinion"),AND(A10="G3",StandardsEra="Before 9 January 2025"),AND(A10="E2",OR(INDEX($I$6:$I$47,MATCH("E1",$A$6:$A$47,0))=0,INDEX($I$6:$I$47,MATCH("E1",$A$6:$A$47,0))="0")),AND(A10="B2",UPPER(TRIM(INDEX($I$6:$I$47,MATCH("B1",$A$6:$A$47,0))&""))="N/A"),AND(OR(A10="D1",A10="D2",A10="D3",A10="D4",A10="D5"),UPPER(TRIM(INDEX($I$6:$I$47,MATCH("C1",$A$6:$A$47,0))&""))="N/A")) | AB10: 13.4 | AC10: =IF(AND(NOT(AA10),AND(NOT(I10=""),NOT(UPPER(TRIM(I10&""))="N/A"),NOT(UPPER(TRIM(I10&""))="NOT TESTED"),NOT(AND(ISNUMBER(IFERROR(VALUE(I10&""),"")),OR(IFERROR(VALUE(I10&""),"")=0,IFERROR(VALUE(I10&""),"")=1,IFERROR(VALUE(I10&""),"")=2,IFERROR(VALUE(I10&""),"")=3))))),1,0)
A11: C1 | B11: Findings | C11: Findings | D11: Must | E11: Condition is set against the criteria | F11: Each finding states what is happening and how that differs from the criteria. Use N/A only when the engagement has no findings. In that case the conclusion must give the positive assurance required by Standard 14.2. | G11: ="14.2 "&INDEX('6. Standards'!$B$5:$B$21,MATCH("14.2",'6. Standards'!$A$5:$A$21,0))&" — "&INDEX('6. Standards'!$C$5:$C$21,MATCH("14.2",'6. Standards'!$A$5:$A$21,0)) | H11: ="No other line switches this off. Use N/A only when the engagement has no findings."&IF(COUNTA('4. Findings'!A8:A27)=0,""," Findings sheet, condition: "&COUNTIF('4. Findings'!D$8:D$27,"Y")&" Y, "&COUNTIF('4. Findings'!D$8:D$27,"P")&" P, "&COUNTIF('4. Findings'!D$8:D$27,"N")&" N.") | L11: Yes | M11: No | N11: =IF(OR(OR(AA11,AND(UPPER(TRIM(I11&""))="N/A",L11="Yes"),AND(UPPER(TRIM(I11&""))="NOT TESTED",M11="Yes")),OR(AND(UPPER(TRIM(I11&""))="N/A",L11<>"Yes"),AND(UPPER(TRIM(I11&""))="NOT TESTED",M11<>"Yes"),AND(NOT(I11=""),NOT(UPPER(TRIM(I11&""))="N/A"),NOT(UPPER(TRIM(I11&""))="NOT TESTED"),NOT(AND(ISNUMBER(IFERROR(VALUE(I11&""),"")),OR(IFERROR(VALUE(I11&""),"")=0,IFERROR(VALUE(I11&""),"")=1,IFERROR(VALUE(I11&""),"")=2,IFERROR(VALUE(I11&""),"")=3)))))),0,IF(AND(ISNUMBER(IFERROR(VALUE(I11&""),"")),OR(IFERROR(VALUE(I11&""),"")=0,IFERROR(VALUE(I11&""),"")=1,IFERROR(VALUE(I11&""),"")=2,IFERROR(VALUE(I11&""),"")=3)),IFERROR(VALUE(I11&""),"")*IF(D11="Must",2,1),0)) | O11: =IF(OR(AA11,AND(UPPER(TRIM(I11&""))="N/A",L11="Yes"),AND(UPPER(TRIM(I11&""))="NOT TESTED",M11="Yes")),0,IF(OR(OR(AND(UPPER(TRIM(I11&""))="N/A",L11<>"Yes"),AND(UPPER(TRIM(I11&""))="NOT TESTED",M11<>"Yes"),AND(NOT(I11=""),NOT(UPPER(TRIM(I11&""))="N/A"),NOT(UPPER(TRIM(I11&""))="NOT TESTED"),NOT(AND(ISNUMBER(IFERROR(VALUE(I11&""),"")),OR(IFERROR(VALUE(I11&""),"")=0,IFERROR(VALUE(I11&""),"")=1,IFERROR(VALUE(I11&""),"")=2,IFERROR(VALUE(I11&""),"")=3))))),AND(ISNUMBER(IFERROR(VALUE(I11&""),"")),OR(IFERROR(VALUE(I11&""),"")=0,IFERROR(VALUE(I11&""),"")=1,IFERROR(VALUE(I11&""),"")=2,IFERROR(VALUE(I11&""),"")=3))),3*IF(D11="Must",2,1),0)) | P11: =IF(OR(AA11,NOT(AND(D11="Must",ISNUMBER(X11),X11=0))),0,1) | Q11: =IF(OR(AA11,NOT(AND(D11="Must",ISNUMBER(X11),X11=1))),0,1) | R11: =IF(AND(NOT(AA11),D11="Must",I11=""),1,0) | S11: =IF(AND(NOT(AA11),UPPER(TRIM(I11&""))="N/A",L11<>"Yes"),1,0) | T11: =IF(AND(NOT(AA11),UPPER(TRIM(I11&""))="NOT TESTED",M11<>"Yes"),1,0) | U11: =IF(OR(AA11,NOT(AND(D11="Should",ISNUMBER(X11),X11=0))),0,1) | V11: =IF(OR(AA11,NOT(AND(D11="Should",ISNUMBER(X11),X11=1))),0,1) | W11: =IF(OR(I11="",AA11),0,1) | X11: =IF(I11="","",IF(UPPER(TRIM(I11&""))="N/A","N/A",IF(UPPER(TRIM(I11&""))="NOT TESTED","NT",IF(AND(ISNUMBER(IFERROR(VALUE(I11&""),"")),OR(IFERROR(VALUE(I11&""),"")=0,IFERROR(VALUE(I11&""),"")=1,IFERROR(VALUE(I11&""),"")=2,IFERROR(VALUE(I11&""),"")=3)),IFERROR(VALUE(I11&""),""),"BAD")))) | Y11: =IF(OR(AA11,NOT(OR(AND(D11="Must",I11="",SUM($W$6:$W$47)>0),AND(ISNUMBER(X11),X11<2),AND(UPPER(TRIM(I11&""))="N/A",L11<>"Yes"),AND(UPPER(TRIM(I11&""))="NOT TESTED",M11<>"Yes"),AND(NOT(I11=""),NOT(UPPER(TRIM(I11&""))="N/A"),NOT(UPPER(TRIM(I11&""))="NOT TESTED"),NOT(AND(ISNUMBER(IFERROR(VALUE(I11&""),"")),OR(IFERROR(VALUE(I11&""),"")=0,IFERROR(VALUE(I11&""),"")=1,IFERROR(VALUE(I11&""),"")=2,IFERROR(VALUE(I11&""),"")=3))))))),0,1) | Z11: =IF(Y11=1,COUNTIF($Y$6:Y11,1),0) | AA11: =OR(AND(LEFT(A11,1)="O",EngagementType<>"Overall opinion"),AND(A11="G3",StandardsEra="Before 9 January 2025"),AND(A11="E2",OR(INDEX($I$6:$I$47,MATCH("E1",$A$6:$A$47,0))=0,INDEX($I$6:$I$47,MATCH("E1",$A$6:$A$47,0))="0")),AND(A11="B2",UPPER(TRIM(INDEX($I$6:$I$47,MATCH("B1",$A$6:$A$47,0))&""))="N/A"),AND(OR(A11="D1",A11="D2",A11="D3",A11="D4",A11="D5"),UPPER(TRIM(INDEX($I$6:$I$47,MATCH("C1",$A$6:$A$47,0))&""))="N/A")) | AB11: 14.2 | AC11: =IF(AND(NOT(AA11),AND(NOT(I11=""),NOT(UPPER(TRIM(I11&""))="N/A"),NOT(UPPER(TRIM(I11&""))="NOT TESTED"),NOT(AND(ISNUMBER(IFERROR(VALUE(I11&""),"")),OR(IFERROR(VALUE(I11&""),"")=0,IFERROR(VALUE(I11&""),"")=1,IFERROR(VALUE(I11&""),"")=2,IFERROR(VALUE(I11&""),"")=3))))),1,0)
A12: C2 | B12: Findings | C12: Findings | D12: Must | E12: Root cause is identified when it can be | F12: The report gives the cause of the difference and, where it can be determined, the root cause. Saying the cause could not be determined, and why, scores 2. Restating the condition scores 1. Silence scores 1. Score 0 only when a significant finding asserts a cause that the evidence contradicts. | G12: ="14.3 "&INDEX('6. Standards'!$B$5:$B$21,MATCH("14.3",'6. Standards'!$A$5:$A$21,0))&" — "&INDEX('6. Standards'!$C$5:$C$21,MATCH("14.3",'6. Standards'!$A$5:$A$21,0)) | H12: ="No other line switches this off."&IF(COUNTA('4. Findings'!A8:A27)=0,""," Findings sheet, cause: "&COUNTIF('4. Findings'!E$8:E$27,"Y")&" Y, "&COUNTIF('4. Findings'!E$8:E$27,"P")&" P, "&COUNTIF('4. Findings'!E$8:E$27,"N")&" N.") | L12: No | M12: No | N12: =IF(OR(OR(AA12,AND(UPPER(TRIM(I12&""))="N/A",L12="Yes"),AND(UPPER(TRIM(I12&""))="NOT TESTED",M12="Yes")),OR(AND(UPPER(TRIM(I12&""))="N/A",L12<>"Yes"),AND(UPPER(TRIM(I12&""))="NOT TESTED",M12<>"Yes"),AND(NOT(I12=""),NOT(UPPER(TRIM(I12&""))="N/A"),NOT(UPPER(TRIM(I12&""))="NOT TESTED"),NOT(AND(ISNUMBER(IFERROR(VALUE(I12&""),"")),OR(IFERROR(VALUE(I12&""),"")=0,IFERROR(VALUE(I12&""),"")=1,IFERROR(VALUE(I12&""),"")=2,IFERROR(VALUE(I12&""),"")=3)))))),0,IF(AND(ISNUMBER(IFERROR(VALUE(I12&""),"")),OR(IFERROR(VALUE(I12&""),"")=0,IFERROR(VALUE(I12&""),"")=1,IFERROR(VALUE(I12&""),"")=2,IFERROR(VALUE(I12&""),"")=3)),IFERROR(VALUE(I12&""),"")*IF(D12="Must",2,1),0)) | O12: =IF(OR(AA12,AND(UPPER(TRIM(I12&""))="N/A",L12="Yes"),AND(UPPER(TRIM(I12&""))="NOT TESTED",M12="Yes")),0,IF(OR(OR(AND(UPPER(TRIM(I12&""))="N/A",L12<>"Yes"),AND(UPPER(TRIM(I12&""))="NOT TESTED",M12<>"Yes"),AND(NOT(I12=""),NOT(UPPER(TRIM(I12&""))="N/A"),NOT(UPPER(TRIM(I12&""))="NOT TESTED"),NOT(AND(ISNUMBER(IFERROR(VALUE(I12&""),"")),OR(IFERROR(VALUE(I12&""),"")=0,IFERROR(VALUE(I12&""),"")=1,IFERROR(VALUE(I12&""),"")=2,IFERROR(VALUE(I12&""),"")=3))))),AND(ISNUMBER(IFERROR(VALUE(I12&""),"")),OR(IFERROR(VALUE(I12&""),"")=0,IFERROR(VALUE(I12&""),"")=1,IFERROR(VALUE(I12&""),"")=2,IFERROR(VALUE(I12&""),"")=3))),3*IF(D12="Must",2,1),0)) | P12: =IF(OR(AA12,NOT(AND(D12="Must",ISNUMBER(X12),X12=0))),0,1) | Q12: =IF(OR(AA12,NOT(AND(D12="Must",ISNUMBER(X12),X12=1))),0,1) | R12: =IF(AND(NOT(AA12),D12="Must",I12=""),1,0) | S12: =IF(AND(NOT(AA12),UPPER(TRIM(I12&""))="N/A",L12<>"Yes"),1,0) | T12: =IF(AND(NOT(AA12),UPPER(TRIM(I12&""))="NOT TESTED",M12<>"Yes"),1,0) | U12: =IF(OR(AA12,NOT(AND(D12="Should",ISNUMBER(X12),X12=0))),0,1) | V12: =IF(OR(AA12,NOT(AND(D12="Should",ISNUMBER(X12),X12=1))),0,1) | W12: =IF(OR(I12="",AA12),0,1) | X12: =IF(I12="","",IF(UPPER(TRIM(I12&""))="N/A","N/A",IF(UPPER(TRIM(I12&""))="NOT TESTED","NT",IF(AND(ISNUMBER(IFERROR(VALUE(I12&""),"")),OR(IFERROR(VALUE(I12&""),"")=0,IFERROR(VALUE(I12&""),"")=1,IFERROR(VALUE(I12&""),"")=2,IFERROR(VALUE(I12&""),"")=3)),IFERROR(VALUE(I12&""),""),"BAD")))) | Y12: =IF(OR(AA12,NOT(OR(AND(D12="Must",I12="",SUM($W$6:$W$47)>0),AND(ISNUMBER(X12),X12<2),AND(UPPER(TRIM(I12&""))="N/A",L12<>"Yes"),AND(UPPER(TRIM(I12&""))="NOT TESTED",M12<>"Yes"),AND(NOT(I12=""),NOT(UPPER(TRIM(I12&""))="N/A"),NOT(UPPER(TRIM(I12&""))="NOT TESTED"),NOT(AND(ISNUMBER(IFERROR(VALUE(I12&""),"")),OR(IFERROR(VALUE(I12&""),"")=0,IFERROR(VALUE(I12&""),"")=1,IFERROR(VALUE(I12&""),"")=2,IFERROR(VALUE(I12&""),"")=3))))))),0,1) | Z12: =IF(Y12=1,COUNTIF($Y$6:Y12,1),0) | AA12: =OR(AND(LEFT(A12,1)="O",EngagementType<>"Overall opinion"),AND(A12="G3",StandardsEra="Before 9 January 2025"),AND(A12="E2",OR(INDEX($I$6:$I$47,MATCH("E1",$A$6:$A$47,0))=0,INDEX($I$6:$I$47,MATCH("E1",$A$6:$A$47,0))="0")),AND(A12="B2",UPPER(TRIM(INDEX($I$6:$I$47,MATCH("B1",$A$6:$A$47,0))&""))="N/A"),AND(OR(A12="D1",A12="D2",A12="D3",A12="D4",A12="D5"),UPPER(TRIM(INDEX($I$6:$I$47,MATCH("C1",$A$6:$A$47,0))&""))="N/A")) | AB12: 14.3 | AC12: =IF(AND(NOT(AA12),AND(NOT(I12=""),NOT(UPPER(TRIM(I12&""))="N/A"),NOT(UPPER(TRIM(I12&""))="NOT TESTED"),NOT(AND(ISNUMBER(IFERROR(VALUE(I12&""),"")),OR(IFERROR(VALUE(I12&""),"")=0,IFERROR(VALUE(I12&""),"")=1,IFERROR(VALUE(I12&""),"")=2,IFERROR(VALUE(I12&""),"")=3))))),1,0)
A13: C3 | B13: Findings | C13: Findings | D13: Must | E13: Effect is evaluated | F13: The report states the effect, including the impact and, where it changes the rating, the likelihood, on governance, risk management, or control. A generic line such as “financial loss” or “business interruption,” with no link to the finding, scores 1. | G13: ="14.3 "&INDEX('6. Standards'!$B$5:$B$21,MATCH("14.3",'6. Standards'!$A$5:$A$21,0))&" — "&INDEX('6. Standards'!$C$5:$C$21,MATCH("14.3",'6. Standards'!$A$5:$A$21,0)) | H13: ="No other line switches this off."&IF(COUNTA('4. Findings'!A8:A27)=0,""," Findings sheet, effect: "&COUNTIF('4. Findings'!F$8:F$27,"Y")&" Y, "&COUNTIF('4. Findings'!F$8:F$27,"P")&" P, "&COUNTIF('4. Findings'!F$8:F$27,"N")&" N.") | L13: No | M13: No | N13: =IF(OR(OR(AA13,AND(UPPER(TRIM(I13&""))="N/A",L13="Yes"),AND(UPPER(TRIM(I13&""))="NOT TESTED",M13="Yes")),OR(AND(UPPER(TRIM(I13&""))="N/A",L13<>"Yes"),AND(UPPER(TRIM(I13&""))="NOT TESTED",M13<>"Yes"),AND(NOT(I13=""),NOT(UPPER(TRIM(I13&""))="N/A"),NOT(UPPER(TRIM(I13&""))="NOT TESTED"),NOT(AND(ISNUMBER(IFERROR(VALUE(I13&""),"")),OR(IFERROR(VALUE(I13&""),"")=0,IFERROR(VALUE(I13&""),"")=1,IFERROR(VALUE(I13&""),"")=2,IFERROR(VALUE(I13&""),"")=3)))))),0,IF(AND(ISNUMBER(IFERROR(VALUE(I13&""),"")),OR(IFERROR(VALUE(I13&""),"")=0,IFERROR(VALUE(I13&""),"")=1,IFERROR(VALUE(I13&""),"")=2,IFERROR(VALUE(I13&""),"")=3)),IFERROR(VALUE(I13&""),"")*IF(D13="Must",2,1),0)) | O13: =IF(OR(AA13,AND(UPPER(TRIM(I13&""))="N/A",L13="Yes"),AND(UPPER(TRIM(I13&""))="NOT TESTED",M13="Yes")),0,IF(OR(OR(AND(UPPER(TRIM(I13&""))="N/A",L13<>"Yes"),AND(UPPER(TRIM(I13&""))="NOT TESTED",M13<>"Yes"),AND(NOT(I13=""),NOT(UPPER(TRIM(I13&""))="N/A"),NOT(UPPER(TRIM(I13&""))="NOT TESTED"),NOT(AND(ISNUMBER(IFERROR(VALUE(I13&""),"")),OR(IFERROR(VALUE(I13&""),"")=0,IFERROR(VALUE(I13&""),"")=1,IFERROR(VALUE(I13&""),"")=2,IFERROR(VALUE(I13&""),"")=3))))),AND(ISNUMBER(IFERROR(VALUE(I13&""),"")),OR(IFERROR(VALUE(I13&""),"")=0,IFERROR(VALUE(I13&""),"")=1,IFERROR(VALUE(I13&""),"")=2,IFERROR(VALUE(I13&""),"")=3))),3*IF(D13="Must",2,1),0)) | P13: =IF(OR(AA13,NOT(AND(D13="Must",ISNUMBER(X13),X13=0))),0,1) | Q13: =IF(OR(AA13,NOT(AND(D13="Must",ISNUMBER(X13),X13=1))),0,1) | R13: =IF(AND(NOT(AA13),D13="Must",I13=""),1,0) | S13: =IF(AND(NOT(AA13),UPPER(TRIM(I13&""))="N/A",L13<>"Yes"),1,0) | T13: =IF(AND(NOT(AA13),UPPER(TRIM(I13&""))="NOT TESTED",M13<>"Yes"),1,0) | U13: =IF(OR(AA13,NOT(AND(D13="Should",ISNUMBER(X13),X13=0))),0,1) | V13: =IF(OR(AA13,NOT(AND(D13="Should",ISNUMBER(X13),X13=1))),0,1) | W13: =IF(OR(I13="",AA13),0,1) | X13: =IF(I13="","",IF(UPPER(TRIM(I13&""))="N/A","N/A",IF(UPPER(TRIM(I13&""))="NOT TESTED","NT",IF(AND(ISNUMBER(IFERROR(VALUE(I13&""),"")),OR(IFERROR(VALUE(I13&""),"")=0,IFERROR(VALUE(I13&""),"")=1,IFERROR(VALUE(I13&""),"")=2,IFERROR(VALUE(I13&""),"")=3)),IFERROR(VALUE(I13&""),""),"BAD")))) | Y13: =IF(OR(AA13,NOT(OR(AND(D13="Must",I13="",SUM($W$6:$W$47)>0),AND(ISNUMBER(X13),X13<2),AND(UPPER(TRIM(I13&""))="N/A",L13<>"Yes"),AND(UPPER(TRIM(I13&""))="NOT TESTED",M13<>"Yes"),AND(NOT(I13=""),NOT(UPPER(TRIM(I13&""))="N/A"),NOT(UPPER(TRIM(I13&""))="NOT TESTED"),NOT(AND(ISNUMBER(IFERROR(VALUE(I13&""),"")),OR(IFERROR(VALUE(I13&""),"")=0,IFERROR(VALUE(I13&""),"")=1,IFERROR(VALUE(I13&""),"")=2,IFERROR(VALUE(I13&""),"")=3))))))),0,1) | Z13: =IF(Y13=1,COUNTIF($Y$6:Y13,1),0) | AA13: =OR(AND(LEFT(A13,1)="O",EngagementType<>"Overall opinion"),AND(A13="G3",StandardsEra="Before 9 January 2025"),AND(A13="E2",OR(INDEX($I$6:$I$47,MATCH("E1",$A$6:$A$47,0))=0,INDEX($I$6:$I$47,MATCH("E1",$A$6:$A$47,0))="0")),AND(A13="B2",UPPER(TRIM(INDEX($I$6:$I$47,MATCH("B1",$A$6:$A$47,0))&""))="N/A"),AND(OR(A13="D1",A13="D2",A13="D3",A13="D4",A13="D5"),UPPER(TRIM(INDEX($I$6:$I$47,MATCH("C1",$A$6:$A$47,0))&""))="N/A")) | AB13: 14.3 | AC13: =IF(AND(NOT(AA13),AND(NOT(I13=""),NOT(UPPER(TRIM(I13&""))="N/A"),NOT(UPPER(TRIM(I13&""))="NOT TESTED"),NOT(AND(ISNUMBER(IFERROR(VALUE(I13&""),"")),OR(IFERROR(VALUE(I13&""),"")=0,IFERROR(VALUE(I13&""),"")=1,IFERROR(VALUE(I13&""),"")=2,IFERROR(VALUE(I13&""),"")=3))))),1,0)
A14: C4 | B14: Findings | C14: Findings | D14: Must | E14: Findings are prioritised | F14: Every finding has a significance or priority, using the function’s scale, and the scale is defined or referenced. Labels with no meaning score 1. No priority scores 0. Use N/A for an advisory engagement that did not undertake to prioritise findings. | G14: ="14.3 "&INDEX('6. Standards'!$B$5:$B$21,MATCH("14.3",'6. Standards'!$A$5:$A$21,0))&" — "&INDEX('6. Standards'!$C$5:$C$21,MATCH("14.3",'6. Standards'!$A$5:$A$21,0))&CHAR(10)&"15.1 "&INDEX('6. Standards'!$B$5:$B$21,MATCH("15.1",'6. Standards'!$A$5:$A$21,0))&" — "&INDEX('6. Standards'!$C$5:$C$21,MATCH("15.1",'6. Standards'!$A$5:$A$21,0)) | H14: ="No other line switches this off."&IF(COUNTA('4. Findings'!A8:A27)=0,""," Findings sheet, priority: "&COUNTIF('4. Findings'!G$8:G$27,"Y")&" Y, "&COUNTIF('4. Findings'!G$8:G$27,"P")&" P, "&COUNTIF('4. Findings'!G$8:G$27,"N")&" N.") | L14: Yes | M14: No | N14: =IF(OR(OR(AA14,AND(UPPER(TRIM(I14&""))="N/A",L14="Yes"),AND(UPPER(TRIM(I14&""))="NOT TESTED",M14="Yes")),OR(AND(UPPER(TRIM(I14&""))="N/A",L14<>"Yes"),AND(UPPER(TRIM(I14&""))="NOT TESTED",M14<>"Yes"),AND(NOT(I14=""),NOT(UPPER(TRIM(I14&""))="N/A"),NOT(UPPER(TRIM(I14&""))="NOT TESTED"),NOT(AND(ISNUMBER(IFERROR(VALUE(I14&""),"")),OR(IFERROR(VALUE(I14&""),"")=0,IFERROR(VALUE(I14&""),"")=1,IFERROR(VALUE(I14&""),"")=2,IFERROR(VALUE(I14&""),"")=3)))))),0,IF(AND(ISNUMBER(IFERROR(VALUE(I14&""),"")),OR(IFERROR(VALUE(I14&""),"")=0,IFERROR(VALUE(I14&""),"")=1,IFERROR(VALUE(I14&""),"")=2,IFERROR(VALUE(I14&""),"")=3)),IFERROR(VALUE(I14&""),"")*IF(D14="Must",2,1),0)) | O14: =IF(OR(AA14,AND(UPPER(TRIM(I14&""))="N/A",L14="Yes"),AND(UPPER(TRIM(I14&""))="NOT TESTED",M14="Yes")),0,IF(OR(OR(AND(UPPER(TRIM(I14&""))="N/A",L14<>"Yes"),AND(UPPER(TRIM(I14&""))="NOT TESTED",M14<>"Yes"),AND(NOT(I14=""),NOT(UPPER(TRIM(I14&""))="N/A"),NOT(UPPER(TRIM(I14&""))="NOT TESTED"),NOT(AND(ISNUMBER(IFERROR(VALUE(I14&""),"")),OR(IFERROR(VALUE(I14&""),"")=0,IFERROR(VALUE(I14&""),"")=1,IFERROR(VALUE(I14&""),"")=2,IFERROR(VALUE(I14&""),"")=3))))),AND(ISNUMBER(IFERROR(VALUE(I14&""),"")),OR(IFERROR(VALUE(I14&""),"")=0,IFERROR(VALUE(I14&""),"")=1,IFERROR(VALUE(I14&""),"")=2,IFERROR(VALUE(I14&""),"")=3))),3*IF(D14="Must",2,1),0)) | P14: =IF(OR(AA14,NOT(AND(D14="Must",ISNUMBER(X14),X14=0))),0,1) | Q14: =IF(OR(AA14,NOT(AND(D14="Must",ISNUMBER(X14),X14=1))),0,1) | R14: =IF(AND(NOT(AA14),D14="Must",I14=""),1,0) | S14: =IF(AND(NOT(AA14),UPPER(TRIM(I14&""))="N/A",L14<>"Yes"),1,0) | T14: =IF(AND(NOT(AA14),UPPER(TRIM(I14&""))="NOT TESTED",M14<>"Yes"),1,0) | U14: =IF(OR(AA14,NOT(AND(D14="Should",ISNUMBER(X14),X14=0))),0,1) | V14: =IF(OR(AA14,NOT(AND(D14="Should",ISNUMBER(X14),X14=1))),0,1) | W14: =IF(OR(I14="",AA14),0,1) | X14: =IF(I14="","",IF(UPPER(TRIM(I14&""))="N/A","N/A",IF(UPPER(TRIM(I14&""))="NOT TESTED","NT",IF(AND(ISNUMBER(IFERROR(VALUE(I14&""),"")),OR(IFERROR(VALUE(I14&""),"")=0,IFERROR(VALUE(I14&""),"")=1,IFERROR(VALUE(I14&""),"")=2,IFERROR(VALUE(I14&""),"")=3)),IFERROR(VALUE(I14&""),""),"BAD")))) | Y14: =IF(OR(AA14,NOT(OR(AND(D14="Must",I14="",SUM($W$6:$W$47)>0),AND(ISNUMBER(X14),X14<2),AND(UPPER(TRIM(I14&""))="N/A",L14<>"Yes"),AND(UPPER(TRIM(I14&""))="NOT TESTED",M14<>"Yes"),AND(NOT(I14=""),NOT(UPPER(TRIM(I14&""))="N/A"),NOT(UPPER(TRIM(I14&""))="NOT TESTED"),NOT(AND(ISNUMBER(IFERROR(VALUE(I14&""),"")),OR(IFERROR(VALUE(I14&""),"")=0,IFERROR(VALUE(I14&""),"")=1,IFERROR(VALUE(I14&""),"")=2,IFERROR(VALUE(I14&""),"")=3))))))),0,1) | Z14: =IF(Y14=1,COUNTIF($Y$6:Y14,1),0) | AA14: =OR(AND(LEFT(A14,1)="O",EngagementType<>"Overall opinion"),AND(A14="G3",StandardsEra="Before 9 January 2025"),AND(A14="E2",OR(INDEX($I$6:$I$47,MATCH("E1",$A$6:$A$47,0))=0,INDEX($I$6:$I$47,MATCH("E1",$A$6:$A$47,0))="0")),AND(A14="B2",UPPER(TRIM(INDEX($I$6:$I$47,MATCH("B1",$A$6:$A$47,0))&""))="N/A"),AND(OR(A14="D1",A14="D2",A14="D3",A14="D4",A14="D5"),UPPER(TRIM(INDEX($I$6:$I$47,MATCH("C1",$A$6:$A$47,0))&""))="N/A")) | AB14: 14.3;15.1 | AC14: =IF(AND(NOT(AA14),AND(NOT(I14=""),NOT(UPPER(TRIM(I14&""))="N/A"),NOT(UPPER(TRIM(I14&""))="NOT TESTED"),NOT(AND(ISNUMBER(IFERROR(VALUE(I14&""),"")),OR(IFERROR(VALUE(I14&""),"")=0,IFERROR(VALUE(I14&""),"")=1,IFERROR(VALUE(I14&""),"")=2,IFERROR(VALUE(I14&""),"")=3))))),1,0)
A15: C5 | B15: Findings | C15: Findings | D15: Must | E15: The basis of the finding is in the report | F15: A reader can see relevant, reliable, and sufficient evidence: what was tested, the population or sample, and the result. Redacted names or amounts do not fail this line when the test and the result remain readable. | G15: ="14.1 "&INDEX('6. Standards'!$B$5:$B$21,MATCH("14.1",'6. Standards'!$A$5:$A$21,0))&" — "&INDEX('6. Standards'!$C$5:$C$21,MATCH("14.1",'6. Standards'!$A$5:$A$21,0))&CHAR(10)&"11.2 "&INDEX('6. Standards'!$B$5:$B$21,MATCH("11.2",'6. Standards'!$A$5:$A$21,0))&" — "&INDEX('6. Standards'!$C$5:$C$21,MATCH("11.2",'6. Standards'!$A$5:$A$21,0)) | H15: ="No other line switches this off."&IF(COUNTA('4. Findings'!A8:A27)=0,""," Findings sheet, evidence: "&COUNTIF('4. Findings'!H$8:H$27,"Y")&" Y, "&COUNTIF('4. Findings'!H$8:H$27,"P")&" P, "&COUNTIF('4. Findings'!H$8:H$27,"N")&" N.") | L15: No | M15: No | N15: =IF(OR(OR(AA15,AND(UPPER(TRIM(I15&""))="N/A",L15="Yes"),AND(UPPER(TRIM(I15&""))="NOT TESTED",M15="Yes")),OR(AND(UPPER(TRIM(I15&""))="N/A",L15<>"Yes"),AND(UPPER(TRIM(I15&""))="NOT TESTED",M15<>"Yes"),AND(NOT(I15=""),NOT(UPPER(TRIM(I15&""))="N/A"),NOT(UPPER(TRIM(I15&""))="NOT TESTED"),NOT(AND(ISNUMBER(IFERROR(VALUE(I15&""),"")),OR(IFERROR(VALUE(I15&""),"")=0,IFERROR(VALUE(I15&""),"")=1,IFERROR(VALUE(I15&""),"")=2,IFERROR(VALUE(I15&""),"")=3)))))),0,IF(AND(ISNUMBER(IFERROR(VALUE(I15&""),"")),OR(IFERROR(VALUE(I15&""),"")=0,IFERROR(VALUE(I15&""),"")=1,IFERROR(VALUE(I15&""),"")=2,IFERROR(VALUE(I15&""),"")=3)),IFERROR(VALUE(I15&""),"")*IF(D15="Must",2,1),0)) | O15: =IF(OR(AA15,AND(UPPER(TRIM(I15&""))="N/A",L15="Yes"),AND(UPPER(TRIM(I15&""))="NOT TESTED",M15="Yes")),0,IF(OR(OR(AND(UPPER(TRIM(I15&""))="N/A",L15<>"Yes"),AND(UPPER(TRIM(I15&""))="NOT TESTED",M15<>"Yes"),AND(NOT(I15=""),NOT(UPPER(TRIM(I15&""))="N/A"),NOT(UPPER(TRIM(I15&""))="NOT TESTED"),NOT(AND(ISNUMBER(IFERROR(VALUE(I15&""),"")),OR(IFERROR(VALUE(I15&""),"")=0,IFERROR(VALUE(I15&""),"")=1,IFERROR(VALUE(I15&""),"")=2,IFERROR(VALUE(I15&""),"")=3))))),AND(ISNUMBER(IFERROR(VALUE(I15&""),"")),OR(IFERROR(VALUE(I15&""),"")=0,IFERROR(VALUE(I15&""),"")=1,IFERROR(VALUE(I15&""),"")=2,IFERROR(VALUE(I15&""),"")=3))),3*IF(D15="Must",2,1),0)) | P15: =IF(OR(AA15,NOT(AND(D15="Must",ISNUMBER(X15),X15=0))),0,1) | Q15: =IF(OR(AA15,NOT(AND(D15="Must",ISNUMBER(X15),X15=1))),0,1) | R15: =IF(AND(NOT(AA15),D15="Must",I15=""),1,0) | S15: =IF(AND(NOT(AA15),UPPER(TRIM(I15&""))="N/A",L15<>"Yes"),1,0) | T15: =IF(AND(NOT(AA15),UPPER(TRIM(I15&""))="NOT TESTED",M15<>"Yes"),1,0) | U15: =IF(OR(AA15,NOT(AND(D15="Should",ISNUMBER(X15),X15=0))),0,1) | V15: =IF(OR(AA15,NOT(AND(D15="Should",ISNUMBER(X15),X15=1))),0,1) | W15: =IF(OR(I15="",AA15),0,1) | X15: =IF(I15="","",IF(UPPER(TRIM(I15&""))="N/A","N/A",IF(UPPER(TRIM(I15&""))="NOT TESTED","NT",IF(AND(ISNUMBER(IFERROR(VALUE(I15&""),"")),OR(IFERROR(VALUE(I15&""),"")=0,IFERROR(VALUE(I15&""),"")=1,IFERROR(VALUE(I15&""),"")=2,IFERROR(VALUE(I15&""),"")=3)),IFERROR(VALUE(I15&""),""),"BAD")))) | Y15: =IF(OR(AA15,NOT(OR(AND(D15="Must",I15="",SUM($W$6:$W$47)>0),AND(ISNUMBER(X15),X15<2),AND(UPPER(TRIM(I15&""))="N/A",L15<>"Yes"),AND(UPPER(TRIM(I15&""))="NOT TESTED",M15<>"Yes"),AND(NOT(I15=""),NOT(UPPER(TRIM(I15&""))="N/A"),NOT(UPPER(TRIM(I15&""))="NOT TESTED"),NOT(AND(ISNUMBER(IFERROR(VALUE(I15&""),"")),OR(IFERROR(VALUE(I15&""),"")=0,IFERROR(VALUE(I15&""),"")=1,IFERROR(VALUE(I15&""),"")=2,IFERROR(VALUE(I15&""),"")=3))))))),0,1) | Z15: =IF(Y15=1,COUNTIF($Y$6:Y15,1),0) | AA15: =OR(AND(LEFT(A15,1)="O",EngagementType<>"Overall opinion"),AND(A15="G3",StandardsEra="Before 9 January 2025"),AND(A15="E2",OR(INDEX($I$6:$I$47,MATCH("E1",$A$6:$A$47,0))=0,INDEX($I$6:$I$47,MATCH("E1",$A$6:$A$47,0))="0")),AND(A15="B2",UPPER(TRIM(INDEX($I$6:$I$47,MATCH("B1",$A$6:$A$47,0))&""))="N/A"),AND(OR(A15="D1",A15="D2",A15="D3",A15="D4",A15="D5"),UPPER(TRIM(INDEX($I$6:$I$47,MATCH("C1",$A$6:$A$47,0))&""))="N/A")) | AB15: 14.1;11.2 | AC15: =IF(AND(NOT(AA15),AND(NOT(I15=""),NOT(UPPER(TRIM(I15&""))="N/A"),NOT(UPPER(TRIM(I15&""))="NOT TESTED"),NOT(AND(ISNUMBER(IFERROR(VALUE(I15&""),"")),OR(IFERROR(VALUE(I15&""),"")=0,IFERROR(VALUE(I15&""),"")=1,IFERROR(VALUE(I15&""),"")=2,IFERROR(VALUE(I15&""),"")=3))))),1,0)
A16: C6 | B16: Findings | C16: Findings | D16: Should | E16: Effective performance is acknowledged | F16: Where the work found processes operating effectively, the report says so. An exception-only report that is silent on effective controls scores 1. Score 2 when the report found no effective area and does not invent one. The conclusion’s own acknowledgment of effective processes is scored on E1. | G16: ="11.3 "&INDEX('6. Standards'!$B$5:$B$21,MATCH("11.3",'6. Standards'!$A$5:$A$21,0))&" — "&"considerations"&CHAR(10)&"14.5 "&INDEX('6. Standards'!$B$5:$B$21,MATCH("14.5",'6. Standards'!$A$5:$A$21,0))&" — "&"Requirements, scored on E1" | H16: ="See "&INDEX($A$6:$A$47,MATCH("E1",$A$6:$A$47,0))&". Standard 14.5 requires the conclusion to acknowledge effective processes. That judgment is scored on "&INDEX($A$6:$A$47,MATCH("E1",$A$6:$A$47,0))&", which is "&IF(INDEX($I$6:$I$47,MATCH("E1",$A$6:$A$47,0))="","blank",INDEX($I$6:$I$47,MATCH("E1",$A$6:$A$47,0)))&". This line scores the narrative." | L16: No | M16: No | N16: =IF(OR(OR(AA16,AND(UPPER(TRIM(I16&""))="N/A",L16="Yes"),AND(UPPER(TRIM(I16&""))="NOT TESTED",M16="Yes")),OR(AND(UPPER(TRIM(I16&""))="N/A",L16<>"Yes"),AND(UPPER(TRIM(I16&""))="NOT TESTED",M16<>"Yes"),AND(NOT(I16=""),NOT(UPPER(TRIM(I16&""))="N/A"),NOT(UPPER(TRIM(I16&""))="NOT TESTED"),NOT(AND(ISNUMBER(IFERROR(VALUE(I16&""),"")),OR(IFERROR(VALUE(I16&""),"")=0,IFERROR(VALUE(I16&""),"")=1,IFERROR(VALUE(I16&""),"")=2,IFERROR(VALUE(I16&""),"")=3)))))),0,IF(AND(ISNUMBER(IFERROR(VALUE(I16&""),"")),OR(IFERROR(VALUE(I16&""),"")=0,IFERROR(VALUE(I16&""),"")=1,IFERROR(VALUE(I16&""),"")=2,IFERROR(VALUE(I16&""),"")=3)),IFERROR(VALUE(I16&""),"")*IF(D16="Must",2,1),0)) | O16: =IF(OR(AA16,AND(UPPER(TRIM(I16&""))="N/A",L16="Yes"),AND(UPPER(TRIM(I16&""))="NOT TESTED",M16="Yes")),0,IF(OR(OR(AND(UPPER(TRIM(I16&""))="N/A",L16<>"Yes"),AND(UPPER(TRIM(I16&""))="NOT TESTED",M16<>"Yes"),AND(NOT(I16=""),NOT(UPPER(TRIM(I16&""))="N/A"),NOT(UPPER(TRIM(I16&""))="NOT TESTED"),NOT(AND(ISNUMBER(IFERROR(VALUE(I16&""),"")),OR(IFERROR(VALUE(I16&""),"")=0,IFERROR(VALUE(I16&""),"")=1,IFERROR(VALUE(I16&""),"")=2,IFERROR(VALUE(I16&""),"")=3))))),AND(ISNUMBER(IFERROR(VALUE(I16&""),"")),OR(IFERROR(VALUE(I16&""),"")=0,IFERROR(VALUE(I16&""),"")=1,IFERROR(VALUE(I16&""),"")=2,IFERROR(VALUE(I16&""),"")=3))),3*IF(D16="Must",2,1),0)) | P16: =IF(OR(AA16,NOT(AND(D16="Must",ISNUMBER(X16),X16=0))),0,1) | Q16: =IF(OR(AA16,NOT(AND(D16="Must",ISNUMBER(X16),X16=1))),0,1) | R16: =IF(AND(NOT(AA16),D16="Must",I16=""),1,0) | S16: =IF(AND(NOT(AA16),UPPER(TRIM(I16&""))="N/A",L16<>"Yes"),1,0) | T16: =IF(AND(NOT(AA16),UPPER(TRIM(I16&""))="NOT TESTED",M16<>"Yes"),1,0) | U16: =IF(OR(AA16,NOT(AND(D16="Should",ISNUMBER(X16),X16=0))),0,1) | V16: =IF(OR(AA16,NOT(AND(D16="Should",ISNUMBER(X16),X16=1))),0,1) | W16: =IF(OR(I16="",AA16),0,1) | X16: =IF(I16="","",IF(UPPER(TRIM(I16&""))="N/A","N/A",IF(UPPER(TRIM(I16&""))="NOT TESTED","NT",IF(AND(ISNUMBER(IFERROR(VALUE(I16&""),"")),OR(IFERROR(VALUE(I16&""),"")=0,IFERROR(VALUE(I16&""),"")=1,IFERROR(VALUE(I16&""),"")=2,IFERROR(VALUE(I16&""),"")=3)),IFERROR(VALUE(I16&""),""),"BAD")))) | Y16: =IF(OR(AA16,NOT(OR(AND(D16="Must",I16="",SUM($W$6:$W$47)>0),AND(ISNUMBER(X16),X16<2),AND(UPPER(TRIM(I16&""))="N/A",L16<>"Yes"),AND(UPPER(TRIM(I16&""))="NOT TESTED",M16<>"Yes"),AND(NOT(I16=""),NOT(UPPER(TRIM(I16&""))="N/A"),NOT(UPPER(TRIM(I16&""))="NOT TESTED"),NOT(AND(ISNUMBER(IFERROR(VALUE(I16&""),"")),OR(IFERROR(VALUE(I16&""),"")=0,IFERROR(VALUE(I16&""),"")=1,IFERROR(VALUE(I16&""),"")=2,IFERROR(VALUE(I16&""),"")=3))))))),0,1) | Z16: =IF(Y16=1,COUNTIF($Y$6:Y16,1),0) | AA16: =OR(AND(LEFT(A16,1)="O",EngagementType<>"Overall opinion"),AND(A16="G3",StandardsEra="Before 9 January 2025"),AND(A16="E2",OR(INDEX($I$6:$I$47,MATCH("E1",$A$6:$A$47,0))=0,INDEX($I$6:$I$47,MATCH("E1",$A$6:$A$47,0))="0")),AND(A16="B2",UPPER(TRIM(INDEX($I$6:$I$47,MATCH("B1",$A$6:$A$47,0))&""))="N/A"),AND(OR(A16="D1",A16="D2",A16="D3",A16="D4",A16="D5"),UPPER(TRIM(INDEX($I$6:$I$47,MATCH("C1",$A$6:$A$47,0))&""))="N/A")) | AB16: 11.3;14.5 | AC16: =IF(AND(NOT(AA16),AND(NOT(I16=""),NOT(UPPER(TRIM(I16&""))="N/A"),NOT(UPPER(TRIM(I16&""))="NOT TESTED"),NOT(AND(ISNUMBER(IFERROR(VALUE(I16&""),"")),OR(IFERROR(VALUE(I16&""),"")=0,IFERROR(VALUE(I16&""),"")=1,IFERROR(VALUE(I16&""),"")=2,IFERROR(VALUE(I16&""),"")=3))))),1,0)
A17: D1 | B17: Actions | C17: Close | D17: Must | E17: The action addresses the cause and the gap | F17: Each finding has a recommendation or an agreed action that closes the gap, mitigates the risk, or addresses the root cause. An action that only restates the symptom scores 1. Use N/A when there are no findings. | G17: ="14.4 "&INDEX('6. Standards'!$B$5:$B$21,MATCH("14.4",'6. Standards'!$A$5:$A$21,0))&" — "&INDEX('6. Standards'!$C$5:$C$21,MATCH("14.4",'6. Standards'!$A$5:$A$21,0))&CHAR(10)&"15.1 "&INDEX('6. Standards'!$B$5:$B$21,MATCH("15.1",'6. Standards'!$A$5:$A$21,0))&" — "&INDEX('6. Standards'!$C$5:$C$21,MATCH("15.1",'6. Standards'!$A$5:$A$21,0)) | H17: =IF(UPPER(TRIM(INDEX($I$6:$I$47,MATCH("C1",$A$6:$A$47,0))&""))="N/A","Off. "&INDEX($A$6:$A$47,MATCH("C1",$A$6:$A$47,0))&" is N/A, so there are no findings and actions are not scored.","On while "&INDEX($A$6:$A$47,MATCH("C1",$A$6:$A$47,0))&" is scored. "&INDEX($A$6:$A$47,MATCH("C1",$A$6:$A$47,0))&" is "&IF(INDEX($I$6:$I$47,MATCH("C1",$A$6:$A$47,0))="","blank",INDEX($I$6:$I$47,MATCH("C1",$A$6:$A$47,0)))&".")&IF(COUNTA('4. Findings'!A8:A27)=0,""," Findings sheet, action: "&COUNTIF('4. Findings'!I$8:I$27,"Y")&" Y, "&COUNTIF('4. Findings'!I$8:I$27,"P")&" P, "&COUNTIF('4. Findings'!I$8:I$27,"N")&" N.") | L17: Yes | M17: No | N17: =IF(OR(OR(AA17,AND(UPPER(TRIM(I17&""))="N/A",L17="Yes"),AND(UPPER(TRIM(I17&""))="NOT TESTED",M17="Yes")),OR(AND(UPPER(TRIM(I17&""))="N/A",L17<>"Yes"),AND(UPPER(TRIM(I17&""))="NOT TESTED",M17<>"Yes"),AND(NOT(I17=""),NOT(UPPER(TRIM(I17&""))="N/A"),NOT(UPPER(TRIM(I17&""))="NOT TESTED"),NOT(AND(ISNUMBER(IFERROR(VALUE(I17&""),"")),OR(IFERROR(VALUE(I17&""),"")=0,IFERROR(VALUE(I17&""),"")=1,IFERROR(VALUE(I17&""),"")=2,IFERROR(VALUE(I17&""),"")=3)))))),0,IF(AND(ISNUMBER(IFERROR(VALUE(I17&""),"")),OR(IFERROR(VALUE(I17&""),"")=0,IFERROR(VALUE(I17&""),"")=1,IFERROR(VALUE(I17&""),"")=2,IFERROR(VALUE(I17&""),"")=3)),IFERROR(VALUE(I17&""),"")*IF(D17="Must",2,1),0)) | O17: =IF(OR(AA17,AND(UPPER(TRIM(I17&""))="N/A",L17="Yes"),AND(UPPER(TRIM(I17&""))="NOT TESTED",M17="Yes")),0,IF(OR(OR(AND(UPPER(TRIM(I17&""))="N/A",L17<>"Yes"),AND(UPPER(TRIM(I17&""))="NOT TESTED",M17<>"Yes"),AND(NOT(I17=""),NOT(UPPER(TRIM(I17&""))="N/A"),NOT(UPPER(TRIM(I17&""))="NOT TESTED"),NOT(AND(ISNUMBER(IFERROR(VALUE(I17&""),"")),OR(IFERROR(VALUE(I17&""),"")=0,IFERROR(VALUE(I17&""),"")=1,IFERROR(VALUE(I17&""),"")=2,IFERROR(VALUE(I17&""),"")=3))))),AND(ISNUMBER(IFERROR(VALUE(I17&""),"")),OR(IFERROR(VALUE(I17&""),"")=0,IFERROR(VALUE(I17&""),"")=1,IFERROR(VALUE(I17&""),"")=2,IFERROR(VALUE(I17&""),"")=3))),3*IF(D17="Must",2,1),0)) | P17: =IF(OR(AA17,NOT(AND(D17="Must",ISNUMBER(X17),X17=0))),0,1) | Q17: =IF(OR(AA17,NOT(AND(D17="Must",ISNUMBER(X17),X17=1))),0,1) | R17: =IF(AND(NOT(AA17),D17="Must",I17=""),1,0) | S17: =IF(AND(NOT(AA17),UPPER(TRIM(I17&""))="N/A",L17<>"Yes"),1,0) | T17: =IF(AND(NOT(AA17),UPPER(TRIM(I17&""))="NOT TESTED",M17<>"Yes"),1,0) | U17: =IF(OR(AA17,NOT(AND(D17="Should",ISNUMBER(X17),X17=0))),0,1) | V17: =IF(OR(AA17,NOT(AND(D17="Should",ISNUMBER(X17),X17=1))),0,1) | W17: =IF(OR(I17="",AA17),0,1) | X17: =IF(I17="","",IF(UPPER(TRIM(I17&""))="N/A","N/A",IF(UPPER(TRIM(I17&""))="NOT TESTED","NT",IF(AND(ISNUMBER(IFERROR(VALUE(I17&""),"")),OR(IFERROR(VALUE(I17&""),"")=0,IFERROR(VALUE(I17&""),"")=1,IFERROR(VALUE(I17&""),"")=2,IFERROR(VALUE(I17&""),"")=3)),IFERROR(VALUE(I17&""),""),"BAD")))) | Y17: =IF(OR(AA17,NOT(OR(AND(D17="Must",I17="",SUM($W$6:$W$47)>0),AND(ISNUMBER(X17),X17<2),AND(UPPER(TRIM(I17&""))="N/A",L17<>"Yes"),AND(UPPER(TRIM(I17&""))="NOT TESTED",M17<>"Yes"),AND(NOT(I17=""),NOT(UPPER(TRIM(I17&""))="N/A"),NOT(UPPER(TRIM(I17&""))="NOT TESTED"),NOT(AND(ISNUMBER(IFERROR(VALUE(I17&""),"")),OR(IFERROR(VALUE(I17&""),"")=0,IFERROR(VALUE(I17&""),"")=1,IFERROR(VALUE(I17&""),"")=2,IFERROR(VALUE(I17&""),"")=3))))))),0,1) | Z17: =IF(Y17=1,COUNTIF($Y$6:Y17,1),0) | AA17: =OR(AND(LEFT(A17,1)="O",EngagementType<>"Overall opinion"),AND(A17="G3",StandardsEra="Before 9 January 2025"),AND(A17="E2",OR(INDEX($I$6:$I$47,MATCH("E1",$A$6:$A$47,0))=0,INDEX($I$6:$I$47,MATCH("E1",$A$6:$A$47,0))="0")),AND(A17="B2",UPPER(TRIM(INDEX($I$6:$I$47,MATCH("B1",$A$6:$A$47,0))&""))="N/A"),AND(OR(A17="D1",A17="D2",A17="D3",A17="D4",A17="D5"),UPPER(TRIM(INDEX($I$6:$I$47,MATCH("C1",$A$6:$A$47,0))&""))="N/A")) | AB17: 14.4;15.1 | AC17: =IF(AND(NOT(AA17),AND(NOT(I17=""),NOT(UPPER(TRIM(I17&""))="N/A"),NOT(UPPER(TRIM(I17&""))="NOT TESTED"),NOT(AND(ISNUMBER(IFERROR(VALUE(I17&""),"")),OR(IFERROR(VALUE(I17&""),"")=0,IFERROR(VALUE(I17&""),"")=1,IFERROR(VALUE(I17&""),"")=2,IFERROR(VALUE(I17&""),"")=3))))),1,0)
