Workbook

Sheet Dashboard_Report
A2: EXECUTIVE INTERNAL AUDIT DASHBOARD: INDUSTRIAL PACKAGING MANUFACTURING PLANT
A3: Continuous Controls Monitoring & Trench Operational Telemetry Assurance Model | Facility: Al-Quoz Plant #4 (Dubai Industrial City)
A5: Audit Scope: | B5: Secondary Corrugated Packaging (B, C, E Flute & Converting) | E5: Audit Period: | F5: Q3-Q4 2026 (12-Month Telemetry Review) | I5: Lead Auditor: | J5: Majid Mumtaz | CIA, ACA, FCCA, GRCP, GRCA, COSO ERM | L5: Review Date: | M5: 30-Oct-2026
A7: OVERALL AUDIT OPINION | C7: WEIGHTED PLANT SCORE | E7: TOTAL CONTROLS TESTED | G7: CRITICAL DEFICIENCIES | I7: HIGH RISK DEFICIENCIES | K7: MEDIUM DEFICIENCIES | M7: EST. FINANCIAL EXPOSURE
A8: =Pillar_Summary!K11 | C8: =Pillar_Summary!G11 | E8: =Pillar_Summary!D11 | G8: =Pillar_Summary!H11 | I8: =Pillar_Summary!I11 | K8: =Pillar_Summary!J11 | M8: 311000
A11: SECTION 1: FIVE CORE ASSURANCE PILLARS SCORECARD
A12: Pillar ID | B12: Core Assurance Pillar Name | E12: Procedures | F12: Max Pts | G12: Earned Pts | H12: Score % | I12: Critical Fails | J12: High Gaps | K12: Med Gaps | L12: Fiduciary Assurance Rating
A13: =Pillar_Summary!A6 | B13: =Pillar_Summary!B6 | E13: =Pillar_Summary!D6 | F13: =Pillar_Summary!E6 | G13: =Pillar_Summary!F6 | H13: =Pillar_Summary!G6 | I13: =Pillar_Summary!H6 | J13: =Pillar_Summary!I6 | K13: =Pillar_Summary!J6 | L13: =Pillar_Summary!K6
A14: =Pillar_Summary!A7 | B14: =Pillar_Summary!B7 | E14: =Pillar_Summary!D7 | F14: =Pillar_Summary!E7 | G14: =Pillar_Summary!F7 | H14: =Pillar_Summary!G7 | I14: =Pillar_Summary!H7 | J14: =Pillar_Summary!I7 | K14: =Pillar_Summary!J7 | L14: =Pillar_Summary!K7
A15: =Pillar_Summary!A8 | B15: =Pillar_Summary!B8 | E15: =Pillar_Summary!D8 | F15: =Pillar_Summary!E8 | G15: =Pillar_Summary!F8 | H15: =Pillar_Summary!G8 | I15: =Pillar_Summary!H8 | J15: =Pillar_Summary!I8 | K15: =Pillar_Summary!J8 | L15: =Pillar_Summary!K8
A16: =Pillar_Summary!A9 | B16: =Pillar_Summary!B9 | E16: =Pillar_Summary!D9 | F16: =Pillar_Summary!E9 | G16: =Pillar_Summary!F9 | H16: =Pillar_Summary!G9 | I16: =Pillar_Summary!H9 | J16: =Pillar_Summary!I9 | K16: =Pillar_Summary!J9 | L16: =Pillar_Summary!K9
A17: =Pillar_Summary!A10 | B17: =Pillar_Summary!B10 | E17: =Pillar_Summary!D10 | F17: =Pillar_Summary!E10 | G17: =Pillar_Summary!F10 | H17: =Pillar_Summary!G10 | I17: =Pillar_Summary!H10 | J17: =Pillar_Summary!I10 | K17: =Pillar_Summary!J10 | L17: =Pillar_Summary!K10
A18: CONSOLIDATED ASSURANCE OPINION | E18: =SUM(E13:E17) | F18: =SUM(F13:F17) | G18: =SUM(G13:G17) | H18: =IF(F18>0, G18/F18, 0) | I18: =SUM(I13:I17) | J18: =SUM(J13:J17) | K18: =SUM(K13:K17) | L18: =Pillar_Summary!K11
A20: SECTION 2: OPERATIONAL DOMAIN BREAKDOWN & CONTROL PERFORMANCE
A21: Code | B21: Operational Manufacturing Domain | E21: Tests | F21: Max Pts | G21: Earned Pts | H21: Domain Score | I21: Critical Fails | J21: High Gaps | K21: Med Gaps | L21: Domain Compliance Rating
A22: RAW | B22: Raw Material Management & Paper Reel Logistics | E22: =COUNTA('AP_1_RAW_Paper_Logistics'!A12:A16) | F22: ='AP_1_RAW_Paper_Logistics'!M17 | G22: ='AP_1_RAW_Paper_Logistics'!L17 | H22: =IF(F22>0, G22/F22, 0) | I22: ='AP_1_RAW_Paper_Logistics'!F7 | J22: ='AP_1_RAW_Paper_Logistics'!G7 | K22: ='AP_1_RAW_Paper_Logistics'!H7 | L22: ='AP_1_RAW_Paper_Logistics'!J7
A23: COR | B23: Corrugator Wet End & Dry End Operations | E23: =COUNTA('AP_2_COR_Corrugator'!A12:A16) | F23: ='AP_2_COR_Corrugator'!M17 | G23: ='AP_2_COR_Corrugator'!L17 | H23: =IF(F23>0, G23/F23, 0) | I23: ='AP_2_COR_Corrugator'!F7 | J23: ='AP_2_COR_Corrugator'!G7 | K23: ='AP_2_COR_Corrugator'!H7 | L23: ='AP_2_COR_Corrugator'!J7
A24: CON | B24: Converting, Printing & Finishing Operations | E24: =COUNTA('AP_3_CON_Converting'!A12:A16) | F24: ='AP_3_CON_Converting'!M17 | G24: ='AP_3_CON_Converting'!L17 | H24: =IF(F24>0, G24/F24, 0) | I24: ='AP_3_CON_Converting'!F7 | J24: ='AP_3_CON_Converting'!G7 | K24: ='AP_3_CON_Converting'!H7 | L24: ='AP_3_CON_Converting'!J7
A25: SCP | B25: Scrap, Baling & Mass Balance | E25: =COUNTA('AP_4_SCP_Scrap_Baling'!A12:A16) | F25: ='AP_4_SCP_Scrap_Baling'!M17 | G25: ='AP_4_SCP_Scrap_Baling'!L17 | H25: =IF(F25>0, G25/F25, 0) | I25: ='AP_4_SCP_Scrap_Baling'!F7 | J25: ='AP_4_SCP_Scrap_Baling'!G7 | K25: ='AP_4_SCP_Scrap_Baling'!H7 | L25: ='AP_4_SCP_Scrap_Baling'!J7
A26: MRO | B26: Tooling, Maintenance & Asset Longevity | E26: =COUNTA('AP_5_MRO_Asset_Tooling'!A12:A16) | F26: ='AP_5_MRO_Asset_Tooling'!M17 | G26: ='AP_5_MRO_Asset_Tooling'!L17 | H26: =IF(F26>0, G26/F26, 0) | I26: ='AP_5_MRO_Asset_Tooling'!F7 | J26: ='AP_5_MRO_Asset_Tooling'!G7 | K26: ='AP_5_MRO_Asset_Tooling'!H7 | L26: ='AP_5_MRO_Asset_Tooling'!J7
A27: LOC | B27: Warehousing, Logistics & Dispatch Integrity | E27: =COUNTA('AP_6_LOC_Warehouse_Dispatch'!A12:A16) | F27: ='AP_6_LOC_Warehouse_Dispatch'!M17 | G27: ='AP_6_LOC_Warehouse_Dispatch'!L17 | H27: =IF(F27>0, G27/F27, 0) | I27: ='AP_6_LOC_Warehouse_Dispatch'!F7 | J27: ='AP_6_LOC_Warehouse_Dispatch'!G7 | K27: ='AP_6_LOC_Warehouse_Dispatch'!H7 | L27: ='AP_6_LOC_Warehouse_Dispatch'!J7
A28: EHS | B28: Boiler House, Safety & Catastrophic Continuity | E28: =COUNTA('AP_7_EHS_Boiler_Continuity'!A12:A16) | F28: ='AP_7_EHS_Boiler_Continuity'!M17 | G28: ='AP_7_EHS_Boiler_Continuity'!L17 | H28: =IF(F28>0, G28/F28, 0) | I28: ='AP_7_EHS_Boiler_Continuity'!F7 | J28: ='AP_7_EHS_Boiler_Continuity'!G7 | K28: ='AP_7_EHS_Boiler_Continuity'!H7 | L28: ='AP_7_EHS_Boiler_Continuity'!J7
A29: TOTAL OPERATIONAL DOMAIN POINTS | E29: =SUM(E22:E28) | F29: =SUM(F22:F28) | G29: =SUM(G22:G28) | H29: =IF(F29>0, G29/F29, 0) | I29: =SUM(I22:I28) | J29: =SUM(J22:J28) | K29: =SUM(K22:K28) | L29: =IF(I29>0, "Critical Failure Override", IF(H29>=0.85, "Substantial", IF(H29>=0.70, "Satisfactory", "Unsatisfactory")))
A31: SECTION 3: EXECUTIVE HIGH-RISK & CRITICAL DEFICIENCIES REQUIRING IMMEDIATE MITIGATION
A32: Ref ID | B32: Severity | C32: Deficiency Title & Operational Finding | F32: Assurance Pillar & Strategic Impact | I32: Mandated Management Remediation Plan | L32: Target Date | M32: Accountable Action Owner
A33: ='AP_1_RAW_Paper_Logistics'!A12 | B33: ='AP_1_RAW_Paper_Logistics'!N12 | C33: ='AP_1_RAW_Paper_Logistics'!I12 | F33: ='AP_1_RAW_Paper_Logistics'!D12 | I33: ='AP_1_RAW_Paper_Logistics'!O12 | L33: ='AP_1_RAW_Paper_Logistics'!P12 | M33: ='AP_1_RAW_Paper_Logistics'!Q12
A34: ='AP_4_SCP_Scrap_Baling'!A15 | B34: ='AP_4_SCP_Scrap_Baling'!N15 | C34: ='AP_4_SCP_Scrap_Baling'!I15 | F34: ='AP_4_SCP_Scrap_Baling'!D15 | I34: ='AP_4_SCP_Scrap_Baling'!O15 | L34: ='AP_4_SCP_Scrap_Baling'!P15 | M34: ='AP_4_SCP_Scrap_Baling'!Q15
A35: ='AP_7_EHS_Boiler_Continuity'!A12 | B35: ='AP_7_EHS_Boiler_Continuity'!N12 | C35: ='AP_7_EHS_Boiler_Continuity'!I12 | F35: ='AP_7_EHS_Boiler_Continuity'!D12 | I35: ='AP_7_EHS_Boiler_Continuity'!O12 | L35: ='AP_7_EHS_Boiler_Continuity'!P12 | M35: ='AP_7_EHS_Boiler_Continuity'!Q12
A36: ='AP_1_RAW_Paper_Logistics'!A14 | B36: ='AP_1_RAW_Paper_Logistics'!N14 | C36: ='AP_1_RAW_Paper_Logistics'!I14 | F36: ='AP_1_RAW_Paper_Logistics'!D14 | I36: ='AP_1_RAW_Paper_Logistics'!O14 | L36: ='AP_1_RAW_Paper_Logistics'!P14 | M36: ='AP_1_RAW_Paper_Logistics'!Q14
A37: ='AP_2_COR_Corrugator'!A12 | B37: ='AP_2_COR_Corrugator'!N12 | C37: ='AP_2_COR_Corrugator'!I12 | F37: ='AP_2_COR_Corrugator'!D12 | I37: ='AP_2_COR_Corrugator'!O12 | L37: ='AP_2_COR_Corrugator'!P12 | M37: ='AP_2_COR_Corrugator'!Q12
A38: ='AP_7_EHS_Boiler_Continuity'!A14 | B38: ='AP_7_EHS_Boiler_Continuity'!N14 | C38: ='AP_7_EHS_Boiler_Continuity'!I14 | F38: ='AP_7_EHS_Boiler_Continuity'!D14 | I38: ='AP_7_EHS_Boiler_Continuity'!O14 | L38: ='AP_7_EHS_Boiler_Continuity'!P14 | M38: ='AP_7_EHS_Boiler_Continuity'!Q14
A40: SECTION 4: MODEL ARCHITECTURE, THOUGHT LEADERSHIP & ASSURANCE PROFILES
A41: Framework Architect: | C41: Majid Mumtaz | CIA (IIA), ACA (ICAEW UK), FCCA (ACCA UK), GRCP & GRCA (OCEG), COSO ERM Certified
A42: The Audit Signal Newsletter: | C42: The Audit Signal — Technical Articles on Continuous Auditing & EBITDA Defense (LinkedIn)
A43: Continuous Controls Monitoring: | C43: Interactive Audit & Continuous Controls Monitoring Portfolio (majidrajpar.github.io/portfolio_my)
A44: Author Executive Profile: | C44: LinkedIn Executive Profile: Majid Mumtaz

Sheet AP_1_RAW_Paper_Logistics
A2: PLANT AUDIT PROGRAM: RAW MATERIAL MANAGEMENT & PAPER REEL LOGISTICS
A3: Facility: Al-Quoz Industrial Packaging Plant #4 (DIC) | Sector: Secondary Corrugated Packaging | Domain Code: RAW | Working Paper: WP-RAW-00
A5: Domain Scope: | B5: Inbound weighbridge verification, paper reel moisture/GSM validation, core tare deductions, clamp truck handling, clamp damage scrap, barcode roll-tag traceability, and high-density yard reel storage. | L5: Lead Specialty: | M5: Raw Materials Procurement & Material Handling Auditor
A7: DOMAIN PERFORMANCE ROLLUP | C7: =SUM(M12:M16) | D7: =SUM(L12:L16) | E7: =IF(C7>0, D7/C7, 0) | F7: =COUNTIF(N12:N16, "Critical") | G7: =COUNTIF(N12:N16, "High") | H7: =COUNTIF(N12:N16, "Medium") | I7: =COUNTIF(N12:N16, "Low") | J7: =IF(F7>0, "Critical Failure", IF(E7>=0.85, "Substantial", IF(E7>=0.70, "Satisfactory", IF(E7>=0.55, "Limited", "Unsatisfactory"))))
A11: Ref ID | B11: Risk Title & Trench Reality (Parallax View) | C11: Inherent Risk | D11: Assigned Assurance Pillar | E11: Specific Audit Test Procedure | F11: Telemetry & Evidence Sources | G11: Sample Population & Scope | H11: WP Ref | I11: Auditor Field Observations & Testing Notes | J11: Control Status | K11: Risk Weight | L11: Earned Pts | M11: Max Pts | N11: Finding Severity | O11: Management Action Plan & Remediation | P11: Target Date | Q11: Action Owner
A12: RAW-01 | B12: INBOUND PAPER REEL MOISTURE & WEIGHBRIDGE WEIGHT RECONCILIATION FRAUD • HQ Assumption: HQ assumes that delivered reel weights match vendor invoice weights within standard 0.5% commercial moisture tolerance, verified by automated weighbridge gross-tare tickets and QA lab moisture testing prior to GRN booking. • Floor Reality: Under turnaround pressure to clear truck demurrage, security records weighbridge gross weight while drivers stay inside the cab. Mill roll moisture tests are forged or taken from outer wrapper only. Reels delivered with 11-13% moisture (spec 7.0-8.0%) from open flatbed rain exposure are booked at full invoice weight. The mill pays virgin kraft paper rates for absorbed water, which evaporates as steam at the preheaters, leaving a massive unrecorded paper fiber shortage. | C12: Critical | D12: 1. Margin Truthfulness | E12: 1. Extract 100% weighbridge gross/tare/net log entries for paper delivery trucks over the audit period and match against ERP Goods Receipt Notes (GRN) and Vendor Invoices. 2. Audit weighbridge load-cell calibration certificates (ISO/IEC 17025 accredited) and zero-balance drift logs. 3. Cross-reference automated weighbridge CCTV footage for a sample of 25 deliveries to verify truck driver de-boarding during tare weighing. 4. Compare QA handheld moisture meter logs against ERP moisture deductions; inspect raw handheld meter internal calibration and memory buffer. 5. Pull 30 sample reel roll-tags, cut 100mm core-to-surface samples, and perform gravimetric oven-drying (bone-dry weight method per ISO 287 / TAPPI T412) to calculate actual moisture percentage vs GRN recorded moisture. 6. Quantify total financial variance where billed moisture exceeded spec without vendor credit memo debit notes. | F12: Automated Weighbridge digital indicator logs (RS-232/Ethernet stream), ERP Purchasing & GRN tables (EKPO, MSEG), Weighbridge CCTV timestamped footage, ISO 17025 load-cell calibration certificates, Lab Gravimetric Drying Oven logs (TAPPI T412), Handheld Dielectric Moisture Meter internal memory dumps. | G12: 100% continuous data reconciliation of all inbound paper deliveries (12-month ERP/Weighbridge population); Physical audit of 30 active reel tags and 10 bone-dry oven destructive lab tests. | H12: WP-RAW-01 | I12: Weighbridge telemetry unlinked to ERP GRN. Drivers observed remaining in cab during tare weighing. Lab moisture tests skipped on 18 of 30 tested reels; billed moisture averaged 11.4% vs 7.5% spec without vendor debit memos raised ($148k estimated water weight paid as virgin fiber). | J12: Ineffective | K12: =IF(C12="Critical", 10, IF(C12="High", 5, IF(C12="Medium", 3, 1))) | L12: =IF(J12="Effective", K12*4, IF(J12="Partially Effective", K12*2, IF(J12="Ineffective", K12*1, 0))) | M12: =IF(J12="N/A", 0, K12*4) | N12: =IF(J12="Effective", "None", IF(J12="N/A", "None", IF(AND(C12="Critical", J12="Ineffective"), "Critical", IF(OR(AND(C12="Critical", J12="Partially Effective"), AND(C12="High", J12="Ineffective")), "High", IF(OR(AND(C12="High", J12="Partially Effective"), AND(C12="Medium", J12="Ineffective")), "Medium", "Low"))))) | O12: Implement automated RS-232 weighbridge-to-ERP interface with driver cabin infrared de-boarding interlocks. Institute mandatory automated dielectric moisture probe checks on 100% of inbound reels with automated ERP vendor debit notes for moisture >8.0%. | P12: 2026-12-15 | Q12: Procurement Director & Plant Weighbridge Lead
A13: RAW-02 | B13: PAPER REEL CORE TARE WEIGHT INFLATION & UNCREDITED CORE RETURNS • HQ Assumption: HQ assumes standard core tare weights (typically 30-50 kg per reel depending on 4-inch or 6-inch core diameter) are accurately deducted during paper consumption and returned to mills for full salvage deposit credits. • Floor Reality: Paper mills systematically deliver heavy-wall cardboard/steel-reinforced cores weighing up to 75 kg while standard ERP deduction remains hardcoded at 35 kg. The extra 40 kg per reel is charged to the plant as paper. On the shop floor, spent cores are crushed by clamp trucks, discarded into paper balers as OCC scrap, or stolen by scrap cartels instead of being credited by paper mills. | C13: Medium | D13: 3. Mass Balance & Anti-Theft | E13: 1. Inspect ERP Item Master data for all paper reel stock keeping units (SKUs) to verify standard core tare deduction parameters. 2. Physically weigh 50 empty cores across all supplying paper mills (separating 76mm/3-inch, 100mm/4-inch, and 150mm/6-inch inner diameter cores) using calibrated floor platform scales. 3. Calculate the delta between actual physical core tare and the ERP standard deduction. 4. Audit the reconciliation of spent core inventory: compare total reels consumed on corrugators against total cores returned to paper mills (vendor credit notes) plus scrap core sales tickets. 5. Inspect baler pit surveillance footage to determine if intact or crushed cores are being fed into export OCC balers to artificially inflate scrap bale counts. | F13: ERP Material Master core tare parameters (MARA/MARC tables), Calibrated Platform Scale calibration certificates, Splicer Butt-Roll reel unwinding telemetry, Paper Mill core credit notes, Scrap baling scale tickets, Baler staging bay CCTV footage. | G13: Physical weigh-sampling of 50 spent cores from 5 distinct paper suppliers; 100% reconciliation of corrugator reel consumption vs core return credits over trailing 6 months. | H13: WP-RAW-02 | I13: Platform scales calibrated. Core tare weights checked across 50 spent rolls; average core weight variance was 1.2 kg against 35 kg standard. Spent cores crushed and documented under export OCC baler tickets. | J13: Effective | K13: =IF(C13="Critical", 10, IF(C13="High", 5, IF(C13="Medium", 3, 1))) | L13: =IF(J13="Effective", K13*4, IF(J13="Partially Effective", K13*2, IF(J13="Ineffective", K13*1, 0))) | M13: =IF(J13="N/A", 0, K13*4) | N13: =IF(J13="Effective", "None", IF(J13="N/A", "None", IF(AND(C13="Critical", J13="Ineffective"), "Critical", IF(OR(AND(C13="Critical", J13="Partially Effective"), AND(C13="High", J13="Ineffective")), "High", IF(OR(AND(C13="High", J13="Partially Effective"), AND(C13="Medium", J13="Ineffective")), "Medium", "Low"))))) | O13: Maintain bi-monthly scale calibration and continue spot-checking core weights across unlisted paper suppliers. | P13: 2027-01-31 | Q13: Raw Materials Warehouse Supervisor
A14: RAW-03 | B14: CLAMP TRUCK HANDLING ABUSE & REEL BARREL DELAMINATION WASTE • HQ Assumption: HQ assumes paper reels are handled by trained operators utilizing hydraulic clamp pressure regulators calibrated to reel weight and paper grade, preserving roll integrity until corrugator loading. • Floor Reality: Clamp truck operators disable hydraulic clamp pressure limiters to lift reels faster without slippage, crushing roll ends and creating deep ovality ('egg-shaped' reels) that jam the corrugator unwind stands. Drivers drop reels vertically on concrete, cracking the outer 30-50mm of paper fiber ('butt damage'). Operators peel off 100 to 200 kg of good paper per roll before splicing to hide the gouges, booking it as 'mill transit damage' rather than internal handling scrap. | C14: High | D14: 2. Asset Longevity | E14: 1. Inspect all forklift clamp attachments for operational hydraulic pressure regulators, dual-pressure setting switches, and contact pad condition (rubber wear, exposed metal bolts). 2. Audit clamp truck maintenance work orders and pressure gauge calibration records for trailing 12 months. 3. Observe real-time unloading of minimum 5 paper reel trucks and 10 warehouse reel transfers; record instances of horizontal rolling, edge dropping, or heel striking. 4. Analyze corrugator reel preparation area: measure the depth of paper stripped off damaged rolls prior to mounting on roll stands across 20 consecutive reel changes. 5. Reconcile ERP scrap code 'Handling/Peel-Off Waste' against clamp truck telematics shock sensor/impact event logs. 6. Inspect uncoiling reels on corrugator unwind stands for out-of-round oscillation, brake squeal, and web flutter. | F14: Clamp truck telematics impact/shock sensor logs (G-force telemetry), Hydraulic clamp pressure gauge calibration records, Clamp contact pad maintenance logs, Corrugator Reel Stand unwinder tension telemetry, ERP Scrap Reason Code analysis (Peel-Off / Transit vs Handling). | G14: Physical inspection of 100% clamp truck fleet (all attachments/regulators); Unannounced observation of 20 reel changeovers at wet end; 100% scrap booking transaction analysis for trailing 6 months. | H14: WP-RAW-03 | I14: Clamp trucks lack automated hydraulic pressure limiters. Drivers frequently operate at max hydraulic pressure to prevent roll slippage during rapid unloading, causing reel end ovality and 120-160 kg barrel delamination strip waste on 4 of 20 observed setups. | J14: Partially Effective | K14: =IF(C14="Critical", 10, IF(C14="High", 5, IF(C14="Medium", 3, 1))) | L14: =IF(J14="Effective", K14*4, IF(J14="Partially Effective", K14*2, IF(J14="Ineffective", K14*1, 0))) | M14: =IF(J14="N/A", 0, K14*4) | N14: =IF(J14="Effective", "None", IF(J14="N/A", "None", IF(AND(C14="Critical", J14="Ineffective"), "Critical", IF(OR(AND(C14="Critical", J14="Partially Effective"), AND(C14="High", J14="Ineffective")), "High", IF(OR(AND(C14="High", J14="Partially Effective"), AND(C14="Medium", J14="Ineffective")), "Medium", "Low"))))) | O14: Retrofit all clamp truck attachments with 3-stage proportional hydraulic pressure regulation valves matched to paper reel diameter/grade. Retrain forklift drivers on roll-handling protocols. | P14: 2027-01-15 | Q14: Logistics & Mobile Equipment Fleet Manager
A15: RAW-04 | B15: PAPER SUB-SPEC GRADE SUBSTITUTION & GRAMMAGE (GSM) CHEATING • HQ Assumption: HQ assumes the paper stock issued to the corrugator strictly complies with the Bill of Materials (BOM) flute-liner recipe (e.g., Kraftliner 175g, Fluting 125g, Testliner 150g). • Floor Reality: When the warehouse runs out of specified virgin Kraftliner or heavy semi-chemical fluting, production supervisors secretly substitute cheaper recycled Testliner or lower-GSM paper without updating the production order BOM in ERP to keep line speeds high. Alternatively, suppliers deliver paper that is 5-10% below nominal GSM (e.g., 160 GSM delivered as 175 GSM). The plant produces boxes that fail customer BCT/ECT specs, leading to crushing during high-humidity pallet stacking at client warehouses. | C15: Critical | D15: 5. Customer Bailee & Spec Integrity | E15: 1. Extract BOM specifications for the top 20 revenue-generating SKU corrugation run orders and identify nominal liner/medium GSM, burst strength, and paper grades. 2. Pull 50 sample paper swatches directly from corrugator unwind stands during active production runs across all flute combinations (A, B, C, E flutes). 3. Conduct conditioned laboratory testing per ISO 536 / TAPPI T410 for exact Grammage (GSM) after conditioning samples at 23°C and 50% RH for 24 hours. 4. Perform Mullen Burst Test (ISO 2759 / TAPPI T807) and Ring Crush Test / Short Span Compression Test (SCT, ISO 9895) on the sample swatches. 5. Compare lab test results against the supplier certificate of analysis (COA), ERP reel master data, and production order BOM. 6. Trace ERP inventory movements for forced manual batch substitutions (movement type 311/261) executed without QA engineering deviation approval. | F15: ERP Production Order BOM execution logs, Raw Material Batch Traceability tables, Lab GSM Scale (0.001g precision) data logs, Mullen Burst Tester digital readouts, Short Span Compression Tester (SCT) telemetry, Corrugator wet-end roll-tag barcode scans. | G15: 50 physical paper sample extractions across 5 operating shifts; 100% audit of BOM vs actual batch issues for top 20 SKUs over trailing 90 days. | H15: WP-RAW-04 | I15: Barcode roll-tags scanned at wet-end infeed. 25 sample batch rolls tested in QA lab: bone-dry conditioned GSM and Short Span Compression (SCT) matched technical data sheets and client BOM specs within +/-1.8%. | J15: Effective | K15: =IF(C15="Critical", 10, IF(C15="High", 5, IF(C15="Medium", 3, 1))) | L15: =IF(J15="Effective", K15*4, IF(J15="Partially Effective", K15*2, IF(J15="Ineffective", K15*1, 0))) | M15: =IF(J15="N/A", 0, K15*4) | N15: =IF(J15="Effective", "None", IF(J15="N/A", "None", IF(AND(C15="Critical", J15="Ineffective"), "Critical", IF(OR(AND(C15="Critical", J15="Partially Effective"), AND(C15="High", J15="Ineffective")), "High", IF(OR(AND(C15="High", J15="Partially Effective"), AND(C15="Medium", J15="Ineffective")), "Medium", "Low"))))) | O15: Maintain automated barcode scanning interlock on roll stands to prevent unapproved paper grade splicing. | P15: 2027-02-28 | Q15: Quality Assurance Manager
A16: RAW-05 | B16: PAPER REEL YARD FIRE LOADING & SPRINKLER CLEARANCE DEFICIENCIES • HQ Assumption: HQ assumes reel stock storage adheres strictly to NFPA 13 guidelines for roll paper storage (maximum stack height, minimum 36-inch clearance beneath sprinkler heads, 8-foot flue space aisles). • Floor Reality: To maximize covered storage capacity, warehouse supervisors stack reels 4 to 5 rolls high (reaching within 12 inches of sprinkler deflectors), bridging flue spaces and blocking wall hydrants. Clamp operators park reels across fire exit doors and in front of sprinkler control valves. In the event of a roll paper fire, intense vertical chimney drafts will overwhelm the sprinkler deluge system, leading to total warehouse destruction. | C16: Critical | D16: 4. Catastrophic Continuity | E16: 1. Measure physical vertical clearance between topmost paper rolls and automatic sprinkler deflectors across 100% of warehouse storage bays. 2. Audit horizontal flue spaces between double-row and multi-row roll stacks against NFPA 13 Roll Paper Storage design criteria (minimum 6-inch longitudinal flue spaces). 3. Inspect all wall-mounted fire hose reels, fire extinguishers, and sprinkler sectional control riser valves for unobstructed 36-inch clear access. 4. Review annual fire insurance risk engineering survey reports (e.g., FM Global, AXA XL) and test closure status of prior recommendation points. 5. Test operation of warehouse flame/smoke beam detectors and verify weekly diesel fire pump auto-start test logs. 6. Audit clamp truck electrical charging stations located in paper roll storage areas for thermal run-away protection and flammable clearance. | F16: Laser distance meter measurements of sprinkler clearances, Annual Insurance Risk Engineering Survey compliance matrices, Sprinkler riser water pressure gauges and tamper switch SCADA alarms, Fire pump controller weekly test logs, Fire alarm panel historical event logs. | G16: 100% physical survey of all paper reel storage bays; Physical inspection of 100% fire risers, extinguishers, and hydrants in warehouse zones. | H16: WP-RAW-05 | I16: Reel yard stacking maintained at maximum 4-high (under 5.5m) with certified 1.2m flue spacing. Laser measurement confirmed 42 inches clearance from highest roll top to sprinkler deflectors (NFPA 13 minimum 36 in). Fire risers unobstructed. | J16: Effective | K16: =IF(C16="Critical", 10, IF(C16="High", 5, IF(C16="Medium", 3, 1))) | L16: =IF(J16="Effective", K16*4, IF(J16="Partially Effective", K16*2, IF(J16="Ineffective", K16*1, 0))) | M16: =IF(J16="N/A", 0, K16*4) | N16: =IF(J16="Effective", "None", IF(J16="N/A", "None", IF(AND(C16="Critical", J16="Ineffective"), "Critical", IF(OR(AND(C16="Critical", J16="Partially Effective"), AND(C16="High", J16="Ineffective")), "High", IF(OR(AND(C16="High", J16="Partially Effective"), AND(C16="Medium", J16="Ineffective")), "Medium", "Low"))))) | O16: Continue weekly HSE laser inspection of yard roll stacking heights and maintain yellow floor demarcations. | P16: Ongoing | Q16: Plant HSE Manager
A17: TOTAL DOMAIN POINTS & SUMMARY: RAW MATERIAL MANAGEMENT & PAPER REEL LOGISTICS | K17: =SUM(K12:K16) | L17: =SUM(L12:L16) | M17: =SUM(M12:M16) | N17: =IF(M17>0, TEXT(L17/M17, "0.0%") & " - " & IF(COUNTIF(N12:N16, "Critical")>0, "Critical Failure", IF(L17/M17>=0.85, "Substantial", IF(L17/M17>=0.70, "Satisfactory", "Unsatisfactory"))), "N/A")

Sheet AP_2_COR_Corrugator
A2: PLANT AUDIT PROGRAM: CORRUGATOR WET END & DRY END OPERATIONS
A3: Facility: Al-Quoz Industrial Packaging Plant #4 (DIC) | Sector: Secondary Corrugated Packaging | Domain Code: COR | Working Paper: WP-COR-00
A5: Domain Scope: | B5: Wet-end roll stands, automatic splicers, corrugating roll flute profiling, starch adhesive gelatinization and consumption rates, bridge synchronization, slitter-scorer accuracy, warp control, and cut-off knife accuracy. | L5: Lead Specialty: | M5: Heavy Process & Thermal Energy Corrugation Specialist
A7: DOMAIN PERFORMANCE ROLLUP | C7: =SUM(M12:M16) | D7: =SUM(L12:L16) | E7: =IF(C7>0, D7/C7, 0) | F7: =COUNTIF(N12:N16, "Critical") | G7: =COUNTIF(N12:N16, "High") | H7: =COUNTIF(N12:N16, "Medium") | I7: =COUNTIF(N12:N16, "Low") | J7: =IF(F7>0, "Critical Failure", IF(E7>=0.85, "Substantial", IF(E7>=0.70, "Satisfactory", IF(E7>=0.55, "Limited", "Unsatisfactory"))))
A11: Ref ID | B11: Risk Title & Trench Reality (Parallax View) | C11: Inherent Risk | D11: Assigned Assurance Pillar | E11: Specific Audit Test Procedure | F11: Telemetry & Evidence Sources | G11: Sample Population & Scope | H11: WP Ref | I11: Auditor Field Observations & Testing Notes | J11: Control Status | K11: Risk Weight | L11: Earned Pts | M11: Max Pts | N11: Finding Severity | O11: Management Action Plan & Remediation | P11: Target Date | Q11: Action Owner
A12: COR-01 | B12: BUTT-ROLL INVENTORY PHANTOM WRITE-OFFS & SPLICER WASTE SKIMMING • HQ Assumption: HQ assumes paper reels returned from the corrugator unwind stands (butt rolls) with residual paper are accurately weighed, barcoded with remaining weight, and returned to ERP inventory. • Floor Reality: Splicer operators do not bother weighing butt rolls when changing reels. They enter estimated remaining meters into the terminal or mark them as zero, writing off 150-300 meters of prime paper (50-100 kg) per reel change as 'splicer scrap'. These butt rolls are either dumped into the scrap baler to inflate waste figures or rolled out the back door to unauthorized small converting workshops for cash. | C12: High | D12: 3. Mass Balance & Anti-Theft | E12: 1. Extract corrugator PLC splicer event logs for 1,000 consecutive reel splices: compare splice diameter sensor reading against reported butt-roll weight returned to ERP. 2. Audit the butt-roll return staging area: physically weigh 30 returned butt rolls on calibrated scale and compare against the printed reprint barcode tag. 3. Calculate the delta between PLC calculated residual paper length: $L = \pi \times (D_{butt}^2 - D_{core}^2) / (4 \times \text{caliper})$ and ERP recorded weight. 4. Trace ERP inventory movement type 551 (scrap write-offs) generated at the corrugator wet end over trailing 6 months. 5. Reconcile corrugator waste conveyor cameras against scrap baling records during shift changes. | F12: Corrugator Splicer PLC laser diameter telemetry, Unwind stand core brake tachometer data, ERP Goods Movement tables (MSEG/AFRU), Butt-roll scale digital memory, Splicer CCTV overhead cameras. | G12: 100% automated reconciliation of 1,000 splicer event logs vs ERP transactions; Physical scale verification of 30 active butt rolls in staging area. | H12: WP-COR-01 | I12: Butt-roll core remnant paper manually logged by operators instead of automated laser diameter encoder backflush. Spot check of 15 demounted rolls showed an average of 45 kg prime paper left on cores booked as standard splicer waste. | J12: Partially Effective | K12: =IF(C12="Critical", 10, IF(C12="High", 5, IF(C12="Medium", 3, 1))) | L12: =IF(J12="Effective", K12*4, IF(J12="Partially Effective", K12*2, IF(J12="Ineffective", K12*1, 0))) | M12: =IF(J12="N/A", 0, K12*4) | N12: =IF(J12="Effective", "None", IF(J12="N/A", "None", IF(AND(C12="Critical", J12="Ineffective"), "Critical", IF(OR(AND(C12="Critical", J12="Partially Effective"), AND(C12="High", J12="Ineffective")), "High", IF(OR(AND(C12="High", J12="Partially Effective"), AND(C12="Medium", J12="Ineffective")), "Medium", "Low"))))) | O12: Commission automated ultrasonic roll diameter sensors on all splicer arms linked to corrugator PLC to automate butt-roll inventory credit before demounting. | P12: 2027-01-31 | Q12: Corrugator Production Superintendent
A13: COR-02 | B13: CORRUGATING FLUTE CALIPER EROSION & WORN ROLL RUNNING • HQ Assumption: HQ assumes corrugating rolls maintain correct flute profile height (e.g., Flute B = 2.5mm, Flute C = 3.6mm) and are replaced at manufacturer-specified running linear meter thresholds. • Floor Reality: Due to CapEx constraints and pressure to meet output targets, maintenance runs tungsten carbide corrugating rolls millions of linear meters past their wear limits. Middle sections of rolls erode from abrasive recycled paper, creating a 'crowned' wear pattern where the center flute height is 15-25% lower than edges. To prevent liner blistering in the center, operators crank up nip pressure and steam heat, crushing paper fibers and manufacturing sub-caliper board that fails customer ECT specs. | C13: Critical | D13: 2. Asset Longevity | E13: 1. Inspect corrugating roll maintenance master logs: extract total accumulated linear meters and running hours for all active single-facer roll cassettes (A, B, C, E flutes). 2. Audit optical/laser corrugating roll profile wear measurement reports performed during roll maintenance shutdowns. 3. Review hydraulic/pneumatic corrugating roll nip loading pressure logs across single-facers over the trailing 90 days. 4. Take 30 caliper micrometer readings (ISO 3034 / TAPPI T411) across the full width of corrugated sheets (drive side, center, operator side) during active production runs. 5. Conduct Edge Crush Resistance testing (ECT per ISO 3037 / TAPPI T811) on samples cut from the center vs edges of the corrugated web. 6. Inspect single-facer labyrinth steam seals and bearing vibration analysis spectra for 1X/2X rotational frequency anomalies indicative of roll eccentricity. | F13: Corrugator SCADA run-meter telemetry, Single-facer nip cylinder pressure transducer logs, Roll profile laser measurement reports, Quality Lab Digital Micrometer logs, Single-facer drive motor vibration spectra (FFT analysis), Board ECT test database. | G13: 100% operational history audit of all active single-facer cassettes; 30 physical cross-web caliper profile micrometer audits during live runs. | H13: WP-COR-02 | I13: B-Flute and C-Flute corrugating rolls running at 14.2M and 18.1M linear meters against 45M OEM life. Optical profilometer inspection verified flute height at 2.65mm (nominal 2.70mm) and uniform tungsten carbide coating. | J13: Effective | K13: =IF(C13="Critical", 10, IF(C13="High", 5, IF(C13="Medium", 3, 1))) | L13: =IF(J13="Effective", K13*4, IF(J13="Partially Effective", K13*2, IF(J13="Ineffective", K13*1, 0))) | M13: =IF(J13="N/A", 0, K13*4) | N13: =IF(J13="Effective", "None", IF(J13="N/A", "None", IF(AND(C13="Critical", J13="Ineffective"), "Critical", IF(OR(AND(C13="Critical", J13="Partially Effective"), AND(C13="High", J13="Ineffective")), "High", IF(OR(AND(C13="High", J13="Partially Effective"), AND(C13="Medium", J13="Ineffective")), "Medium", "Low"))))) | O13: Maintain 5-million-meter profilometer wear audits and quarterly ultrasonic thickness testing. | P13: Ongoing | Q13: Plant Reliability Engineer
A14: COR-03 | B14: STARCH ADHESIVE SOLID SOLIDS DILUTION & EXCESSIVE APPLICATION GRAMMAGE • HQ Assumption: HQ assumes the automated starch kitchen prepares adhesive at strictly controlled Stein-Hall viscosity (35-45 seconds) and solids content (22-25%), applying a standard 3.5 to 5.0 g/m² dry starch film to sheet flutes. • Floor Reality: Starch kitchen operators add excess fresh water or dilute batches with flexo wash-water to stretch raw starch inventory and compensate for uncalibrated batch scales. At the corrugator glue applicator, operators widen doctor roll gaps to soak poorly-heated paper, running starch application rates at 8.0-12.0 g/m². The excess water causes massive sheet warping, damp board, and soft corrugated boxes, while silently inflating starch chemical consumption costs by 40-70% above standard BOM. | C14: High | D14: 1. Margin Truthfulness | E14: 1. Extract starch kitchen automated batching PLC logs for the past 60 days: analyze ratio of native corn/wheat starch, caustic soda, borax, and water. 2. Audit daily QA starch viscosity logs (Love Cup / Zahn Cup test) and temperature telemetry; perform an unannounced live viscosity and gelatinization temperature test on active circulation tanks. 3. Pull doctor roll gap PLC position telemetry from Single-Facers and Double-Backer glue units; compare actual gap settings (mm) against standard operating procedure (SOP) recipes by paper grade. 4. Calculate starch dry solids consumption mass balance: compare total raw starch bags/silo consumption (ERP) against total produced corrugated square meters ($g/m^2$ dry starch). 5. Perform iodine staining test on board cross-sections from 20 production orders to visually assess starch glue line width, penetration depth, and applicator squeeze-out. 6. Inspect double-backer hot plate steam telemetry: verify steam temperature profile ($170-185^\circ\text{C}$) to confirm complete starch gelatinization. | F14: Starch Kitchen PLC batch formulation logs, Glue unit doctor roll servo-motor gap encoder telemetry, Corrugator line speed vs glue unit speed sync ratios, Lab Viscosity Cup test logs, ERP raw starch inventory consumption vs corrugator square-meter output. | G14: 100% starch batch PLC recipe analysis for 60 days; Physical starch mass balance reconciliation for 6 months; 20 physical board iodine stain inspections. | H14: WP-COR-03 | I14: Starch kitchen viscosity and gel temperature within spec (32s / 67°C). However, dry-film starch application rate was running at 5.8 g/m² vs standard BOM of 4.2 g/m² due to manually adjusted doctor roll gaps on Single Facer #2. | J14: Partially Effective | K14: =IF(C14="Critical", 10, IF(C14="High", 5, IF(C14="Medium", 3, 1))) | L14: =IF(J14="Effective", K14*4, IF(J14="Partially Effective", K14*2, IF(J14="Ineffective", K14*1, 0))) | M14: =IF(J14="N/A", 0, K14*4) | N14: =IF(J14="Effective", "None", IF(J14="N/A", "None", IF(AND(C14="Critical", J14="Ineffective"), "Critical", IF(OR(AND(C14="Critical", J14="Partially Effective"), AND(C14="High", J14="Ineffective")), "High", IF(OR(AND(C14="High", J14="Partially Effective"), AND(C14="Medium", J14="Ineffective")), "Medium", "Low"))))) | O14: Lock doctor roll gap servo-controllers to automated line-speed synchronization curves; remove manual gap override keys from operator control consoles. | P14: 2026-12-31 | Q14: Process Engineering Lead
A15: COR-04 | B15: SEVERE CORRUGATOR WARP & IN-LINE WATER SHOWER SUPPRESSION ABUSE • HQ Assumption: HQ assumes corrugator temperature, wrap-arm angles, and web tension are harmonized to produce flat corrugated sheets complying with FEFCO warp standards (<1.5% deflection). • Floor Reality: Because preheaters have dirty internal condensate siphon pipes and operators fail to balance paper liner moisture, sheets suffer extreme up-warp or down-warp that jams converting feeder hoppers. Instead of diagnosing tension or temperature balance, operators turn on manual water spray bars on the corrugator bridge, flooding the top liner with water. This temporarily flattens the board for stacking, but causes severe washboarding, liner delamination, mold growth in transit, and erratic carton foldability. | C15: High | D15: 5. Customer Bailee & Spec Integrity | E15: 1. Inspect preheater drum wrap-arm drive motors and angle position feedback sensors (SCADA) across single-facers and double-facer triple-preheaters. 2. Audit bridge moisture shower / steam shower operation logs and manual override valves; verify whether bridge water showers are running continuously during standard operations. 3. Conduct physical warp measurements on 30 freshly stacked pallets at the corrugator downstacker using standard FEFCO deflection gauges. 4. Audit sheet stack moisture using non-contact infrared moisture scanners across the sheet width at the take-off conveyor. 5. Reconcile converting department downtime logs: extract feeder jam events caused by warped board and trace back to specific corrugator shift production runs. 6. Inspect steam siphon differential pressure gauges on preheater drums to verify continuous condensate evacuation. | F15: Corrugator SCADA wrap-arm angle logs, Bridge water spray solenoid valve telemetry, Downstacker exit Infrared Moisture Camera logs, Converting machine jam fault logs, Preheater condensate return temperature sensors. | G15: Physical warp measurement of 30 freshly palletized loads across 3 shifts; 100% correlation analysis of converting jam downtime vs corrugator bridge spray valve activations over 30 days. | H15: WP-COR-04 | I15: Thermal wrap-arm controls operating under automated infrared moisture feedback. Downstacker infrared moisture telemetry showed consistent 7.2% to 7.8% cross-web profile. Bridge water showers remained isolated during all 5 observed shifts. | J15: Effective | K15: =IF(C15="Critical", 10, IF(C15="High", 5, IF(C15="Medium", 3, 1))) | L15: =IF(J15="Effective", K15*4, IF(J15="Partially Effective", K15*2, IF(J15="Ineffective", K15*1, 0))) | M15: =IF(J15="N/A", 0, K15*4) | N15: =IF(J15="Effective", "None", IF(J15="N/A", "None", IF(AND(C15="Critical", J15="Ineffective"), "Critical", IF(OR(AND(C15="Critical", J15="Partially Effective"), AND(C15="High", J15="Ineffective")), "High", IF(OR(AND(C15="High", J15="Partially Effective"), AND(C15="Medium", J15="Ineffective")), "Medium", "Low"))))) | O15: Maintain automated wrap-arm PID loop calibration and continue weekly IR camera cross-check. | P15: 2027-03-31 | Q15: Quality Assurance Lead
A16: COR-05 | B16: CORRUGATOR STEAM SYSTEM SIPHON BLOWBY & ROTARY JOINT THERMAL STRESS • HQ Assumption: HQ assumes corrugating steam chests, rolls, and preheater drums operate at optimal thermal efficiency (160-185°C) with functional rotary joints and internal siphon clearance (1-2mm from drum shell) maintaining dry steam contact. • Floor Reality: Broken or bent internal siphon pipes allow condensate to pool inside spinning corrugating rolls ('condensate flooding'). This creates severe temperature drops of 30-50°C across the roll face, inducing heavy thermal distortion and mechanical stress on roll journals. Maintenance operators bypass faulty steam traps, dumping live 12-bar steam directly into condensate return lines to clear waterlogging, driving boiler fuel consumption up by 25% while operating rolls in dangerous thermal imbalance. | C16: Critical | D16: 4. Catastrophic Continuity | E16: 1. Perform live thermographic (FLIR infrared) scanning across all spinning corrugating rolls, pressure rolls, and preheater drums during active production; log surface temperature delta between drive side, center, and operator side. 2. Audit acoustic ultrasonic test logs on all corrugator steam traps to detect live steam blow-through or mechanical blockage. 3. Inspect internal siphon pipe gap inspection records from previous roll changeover maintenance logs. 4. Review steam pressure and temperature telemetry at the corrugator main steam header and condensate return manifold. 5. Inspect flexible metal steam hoses and rotary joints on roll journals for signs of angular misalignment, steam weeping, or missing safety retention cables. 6. Reconcile corrugator natural gas / heavy fuel oil (HFO) consumption per ton of paper processed against industry benchmark (0.8 - 1.2 GJ/ton). | F16: Calibrated FLIR Infrared Thermal Images, Ultrasonic Steam Trap Tester logfiles, SCADA Steam Pressure (bar) and Temperature (°C) continuous historians, Boiler Fuel Consumption vs Paper Tonnage telemetry, Rotary joint maintenance records. | G16: 100% thermographic scan of all active single-facer and preheater rotating cylinders; 100% ultrasonic testing of all corrugator steam traps (approx. 25-40 traps). | H16: WP-COR-05 | I16: FLIR thermal imaging of 36 steam-heated cylinders (preheaters and corrugating rolls) showed uniform surface temperatures (174-178°C). Ultrasonic steam trap testing showed 2 blowing traps out of 42 (4.7% failure rate, well within 5% industry threshold). | J16: Effective | K16: =IF(C16="Critical", 10, IF(C16="High", 5, IF(C16="Medium", 3, 1))) | L16: =IF(J16="Effective", K16*4, IF(J16="Partially Effective", K16*2, IF(J16="Ineffective", K16*1, 0))) | M16: =IF(J16="N/A", 0, K16*4) | N16: =IF(J16="Effective", "None", IF(J16="N/A", "None", IF(AND(C16="Critical", J16="Ineffective"), "Critical", IF(OR(AND(C16="Critical", J16="Partially Effective"), AND(C16="High", J16="Ineffective")), "High", IF(OR(AND(C16="High", J16="Partially Effective"), AND(C16="Medium", J16="Ineffective")), "Medium", "Low"))))) | O16: Replace the 2 defective thermodynamic steam traps during next scheduled weekend maintenance window. | P16: 2026-11-20 | Q16: Boiler & Utilities Supervisor
A17: TOTAL DOMAIN POINTS & SUMMARY: CORRUGATOR WET END & DRY END OPERATIONS | K17: =SUM(K12:K16) | L17: =SUM(L12:L16) | M17: =SUM(M12:M16) | N17: =IF(M17>0, TEXT(L17/M17, "0.0%") & " - " & IF(COUNTIF(N12:N16, "Critical")>0, "Critical Failure", IF(L17/M17>=0.85, "Substantial", IF(L17/M17>=0.70, "Satisfactory", "Unsatisfactory"))), "N/A")

Sheet AP_3_CON_Converting
A2: PLANT AUDIT PROGRAM: CONVERTING, PRINTING & FINISHING OPERATIONS
A3: Facility: Al-Quoz Industrial Packaging Plant #4 (DIC) | Sector: Secondary Corrugated Packaging | Domain Code: CON | Working Paper: WP-CON-00
A5: Domain Scope: | B5: Flexo Folder Gluers (FFG), Rotary Die Cutters (RDC), anilox roll cell volume (BCM), cold-set PVA/hotmelt glue bond integrity, score cracking, printing plate (stereo) registration, and bundling/strapping. | L5: Lead Specialty: | M5: Converting Machinery & Packaging Quality Assurance Auditor
A7: DOMAIN PERFORMANCE ROLLUP | C7: =SUM(M12:M16) | D7: =SUM(L12:L16) | E7: =IF(C7>0, D7/C7, 0) | F7: =COUNTIF(N12:N16, "Critical") | G7: =COUNTIF(N12:N16, "High") | H7: =COUNTIF(N12:N16, "Medium") | I7: =COUNTIF(N12:N16, "Low") | J7: =IF(F7>0, "Critical Failure", IF(E7>=0.85, "Substantial", IF(E7>=0.70, "Satisfactory", IF(E7>=0.55, "Limited", "Unsatisfactory"))))
A11: Ref ID | B11: Risk Title & Trench Reality (Parallax View) | C11: Inherent Risk | D11: Assigned Assurance Pillar | E11: Specific Audit Test Procedure | F11: Telemetry & Evidence Sources | G11: Sample Population & Scope | H11: WP Ref | I11: Auditor Field Observations & Testing Notes | J11: Control Status | K11: Risk Weight | L11: Earned Pts | M11: Max Pts | N11: Finding Severity | O11: Management Action Plan & Remediation | P11: Target Date | Q11: Action Owner
A12: CON-01 | B12: FLEXO ANILOX ROLL CELL VOLUME DEGRADATION & INK OVER-CONSUMPTION • HQ Assumption: HQ assumes Flexo Folder Gluers (FFGs) and Rotary Die Cutters (RDCs) operate with clean, calibrated ceramic anilox rolls delivering precise ink film thickness matching approved color lab formulas (Delta E < 2.0). • Floor Reality: Anilox roll cells become clogged with dried polymer ink or eroded from abrasive ceramic doctor blades, dropping cell volume (BCM) from 8.0 to 4.0. To achieve required print density on dark kraft liners, press operators add excessive ammonia and raw pigment, or dump dark ink directly into light ink sumps. Operators run ink viscosity high (30+ seconds vs 18-22 sec spec), flooding the board, causing ink smear, rub-off during transit, and burning 35% more ink than standard job costing. | C12: Medium | D12: 1. Margin Truthfulness | E12: 1. Audit the anilox roll asset register: extract historical microscopic cell volume (BCM/cm³) audit logs for all printing decks across converting lines. 2. Perform optical interferometer or liquid cell volume test (Capatch / Volu-Test) on 10 active anilox rolls to verify actual vs rated cell volume. 3. Inspect daily ink viscosity and pH measurement sheets at printing stations; compare against ink technician formulation standards (Shell/Zahn Cup seconds and pH 8.5-9.5). 4. Review automatic ink wash-up cycle telemetry: verify if ink recovery cycles pump residual ink back to drums or dump it into the wastewater drain. 5. Reconcile total flexo ink purchased vs standard ink costed on converted square meters across top 30 printing jobs. 6. Conduct Sutherland Rub Test (ASTM D5264) on 20 printed production samples to evaluate dry and wet scuff resistance. | F12: Anilox Roll Interferometer / BCM inspection certificates, Press Viscometer automated sensor logs, Ink Lab Formulation database (X-Rite Spectrophotometer Delta E logs), ERP Ink Goods Movement records (movement 261), Wash-up recovery meter telemetry. | G12: Physical BCM inspection of 10 anilox rolls across 4 converting machines; 100% ink consumption variance analysis for top 30 high-volume print jobs over 6 months; 20 physical rub tests. | H12: WP-CON-01 | I12: Capatch volume testing on 12 flexo anilox rolls verified ink carrying capacity within 5% of nominal BCM (6.2 BCM). Automated ink dispensing system reconciled within 1.8% of theoretical ink consumption across tested job runs. | J12: Effective | K12: =IF(C12="Critical", 10, IF(C12="High", 5, IF(C12="Medium", 3, 1))) | L12: =IF(J12="Effective", K12*4, IF(J12="Partially Effective", K12*2, IF(J12="Ineffective", K12*1, 0))) | M12: =IF(J12="N/A", 0, K12*4) | N12: =IF(J12="Effective", "None", IF(J12="N/A", "None", IF(AND(C12="Critical", J12="Ineffective"), "Critical", IF(OR(AND(C12="Critical", J12="Partially Effective"), AND(C12="High", J12="Ineffective")), "High", IF(OR(AND(C12="High", J12="Partially Effective"), AND(C12="Medium", J12="Ineffective")), "Medium", "Low"))))) | O12: Continue monthly ultrasonic anilox cleaning rotation and quarterly BCM verification. | P12: 2027-02-15 | Q12: Converting Shift Supervisor
A13: CON-02 | B13: FOLDER-GLUING COLD-SET ADHESIVE FAILURE & SCORE LINER CRACKING • HQ Assumption: HQ assumes folder-gluer extrusion systems apply continuous, bonded adhesive glue lines achieving 100% fiber tear, while creasing tooling preserves liner integrity without tensile rupture. • Floor Reality: To avoid nozzle clogging during micro-stops, operators disable automated electronic glue pattern detectors or move glue guns away from the tab, leading to unglued 'open-joint' boxes. To prevent board jamming, operators crush creasing profiles or run with excessively dry board, fracturing the outer liner along score lines. Boxes fail catastrophically on high-speed customer automated packing lines, triggering major commercial rejections. | C13: Critical | D13: 5. Customer Bailee & Spec Integrity | E13: 1. Inspect folder-gluer optical glue detection sensors (e.g., Baumer hhs, Valco Melton) on all active FFG lines to verify sensors are enabled, calibrated, and interlocked to eject defective boxes. 2. Review electronic defect ejection event logs: cross-check detected glue gaps against physical scrap bin counts at machine tail. 3. Perform manual Fiber Tear Bond Tests on 50 sample glued cartons across 5 converting lines: inspect joint after 24-hour cure (pass criteria: >85% substrate fiber separation along glue flap). 4. Examine score lines for 180-degree fold cracking on both outer Kraftliner and inner medium; measure score depth using digital depth gauges. 5. Pull customer quality complaint log for trailing 12 months: isolate all occurrences of 'open glue joints' or 'cracked scores' and trace back to machine, operator, and shift. 6. Inspect glue storage totes and pumps for skinning, contamination, or water dilution. | F13: Folder-gluer automated glue verification camera/sensor logs, Defective carton ejector pneumatic actuation counters, Converting machine speed and downtime logs, QA Fiber Tear Destructive Test logsheets, Customer RMA/Credit Memo register. | G13: Physical inspection of 100% glue sensor interlocks across all folder-gluers; 50 physical fiber tear tests; 100% analysis of customer glue failure complaints over trailing 12 months. | H13: WP-CON-02 | I13: Folder-Gluer optical UV glue detectors functioning on Lines 1 and 2, but disabled on Line 3 due to frequent false rejections caused by dust accumulation. Destructive tear tests identified 3 unglued bundles in quarantine. | J13: Partially Effective | K13: =IF(C13="Critical", 10, IF(C13="High", 5, IF(C13="Medium", 3, 1))) | L13: =IF(J13="Effective", K13*4, IF(J13="Partially Effective", K13*2, IF(J13="Ineffective", K13*1, 0))) | M13: =IF(J13="N/A", 0, K13*4) | N13: =IF(J13="Effective", "None", IF(J13="N/A", "None", IF(AND(C13="Critical", J13="Ineffective"), "Critical", IF(OR(AND(C13="Critical", J13="Partially Effective"), AND(C13="High", J13="Ineffective")), "High", IF(OR(AND(C13="High", J13="Partially Effective"), AND(C13="Medium", J13="Ineffective")), "Medium", "Low"))))) | O13: Clean and realign optical glue sensors on Line 3. Implement hard PLC interlock preventing machine run if glue detection sensors are bypassed or muted. | P13: 2026-12-10 | Q13: Converting Maintenance Lead
A14: CON-03 | B14: ROTARY DIE-CUTTER POLYURETHANE ANVIL BLANKET WEAR & SCALLOPED CUT WASTE • HQ Assumption: HQ assumes rotary die-cutters operate with automated anvil blanket oscillation, regular anvil trimming/grinding, and timely blanket rotation to maintain clean cutting and stripping. • Floor Reality: Anvil oscillation drives break down and are left un-repaired. Die blades strike the exact same spot on polyurethane blankets, carving deep trenches. Die-cut blanks emerge with hanging shreds, scalloped edges, and un-stripped waste matrix. Instead of replacing worn blankets, machine operators increase die cylinder cutting pressure, dulling expensive serrated rule steel dies and crushing sheet flutes around cutouts, destroying box structural rigidity. | C14: High | D14: 2. Asset Longevity | E14: 1. Inspect anvil blanket cylinder oscillation mechanisms and motorized micro-grinding trimming attachments across all Rotary Die Cutters. 2. Measure polyurethane anvil blanket thickness and surface groove depth using a depth micrometer across 5 positions per cylinder. 3. Review CMMS work orders for anvil rotation, grinding cycles, and blanket segment replacements over trailing 12 months. 4. Inspect cutting dies currently mounted on machines: examine cutting rules for flattening, rolled edges, or chipped teeth caused by excessive impression pressure. 5. Examine cut quality on 30 sample die-cut blanks: check for hanging chads, jagged edge scallops, and board crushing along perimeter cuts. 6. Audit scrap baler matrix waste for excessive finished product blanks chewed up and pulled into waste conveyors due to dull die rules. | F14: Rotary Die Cutter anvil drive motor run-hours, Anvil blanket micrometer surface depth logs, CMMS Die Cutting Rule maintenance records, Cutting cylinder hydraulic impression pressure gauges, Scrap baler matrix inspection logs. | G14: Physical inspection of 100% active rotary die cutters (all anvil cylinders and oscillation drives); Microscopic edge check of 10 cutting dies; 30 physical die-cut blank inspections. | H14: WP-CON-03 | I14: Rotary die-cutter polyurethane anvil blankets rotated per manufacturer schedule (every 500k impressions). Anvil oscillation drive operational with uniform wear pattern; carton cut edges showed clean shearing with zero scalloping. | J14: Effective | K14: =IF(C14="Critical", 10, IF(C14="High", 5, IF(C14="Medium", 3, 1))) | L14: =IF(J14="Effective", K14*4, IF(J14="Partially Effective", K14*2, IF(J14="Ineffective", K14*1, 0))) | M14: =IF(J14="N/A", 0, K14*4) | N14: =IF(J14="Effective", "None", IF(J14="N/A", "None", IF(AND(C14="Critical", J14="Ineffective"), "Critical", IF(OR(AND(C14="Critical", J14="Partially Effective"), AND(C14="High", J14="Ineffective")), "High", IF(OR(AND(C14="High", J14="Partially Effective"), AND(C14="Medium", J14="Ineffective")), "Medium", "Low"))))) | O14: Maintain anvil rotation logbook and bi-weekly micrometer depth checks. | P14: Ongoing | Q14: Tooling & Die Specialist
A15: CON-04 | B15: CONVERTING OVER-PRODUCTION SKIMMING & GHOST BUNDLE CONVERSION • HQ Assumption: HQ assumes converting machines produce strictly to authorized ERP production order quantities (within standard +/- 5% trade allowance), with all over-runs booked to inventory or crushed as reported scrap. • Floor Reality: Converting crews run extra corrugated sheets from unrecorded buffer stock to produce 500-2,000 extra finished cartons per job. These extra bundles are stacked on unmarked pallets, bypassed past the automated strapping counter, and loaded onto outbound customer delivery trucks without ERP delivery notes to fulfill unrecorded cash orders or compensate for previous off-the-books customer shortages. | C15: High | D15: 3. Mass Balance & Anti-Theft | E15: 1. Extract machine PLC sheet counter telemetry from converting line feed hoppers and compare against palletizer automated stacker exit counts for 50 production orders. 2. Reconcile total sheets fed into converting machines vs total good finished cartons declared in ERP production confirmation (movement type 101) plus declared converting scrap. 3. Audit automated bundle strapper cycle counters and cross-reference against pallet packing slips for the sample runs. 4. Review CCTV footage of converting outfeed conveyors and palletizing staging areas during end-of-shift periods. 5. Reconcile customer Proof of Delivery (POD) physical receipt carton counts against ERP invoiced quantities for recurring high-volume accounts. 6. Inspect plant temporary holding zones, rework corners, and maintenance mezzanines for hidden stacks of un-palletized finished cartons. | F15: Converting machine PLC Infeed Optical Sensor counts, Automated Palletizer / Strapper digital cycle counters, ERP Confirmation tables (AFRU), Warehouse CCTV footage of finishing lines, Customer signed POD records. | G15: 100% automated telemetry reconciliation of PLC infeed vs ERP confirmation for 50 high-volume converting runs; Physical search of plant floor holding areas. | H15: WP-CON-04 | I15: Job counter reconciliation: Infeed optical counters on FFG lines reconciled within 0.4% against automated bundle strapper and palletizer counts. Scrap sheets shredded and vacuumed into baler ducting. | J15: Effective | K15: =IF(C15="Critical", 10, IF(C15="High", 5, IF(C15="Medium", 3, 1))) | L15: =IF(J15="Effective", K15*4, IF(J15="Partially Effective", K15*2, IF(J15="Ineffective", K15*1, 0))) | M15: =IF(J15="N/A", 0, K15*4) | N15: =IF(J15="Effective", "None", IF(J15="N/A", "None", IF(AND(C15="Critical", J15="Ineffective"), "Critical", IF(OR(AND(C15="Critical", J15="Partially Effective"), AND(C15="High", J15="Ineffective")), "High", IF(OR(AND(C15="High", J15="Partially Effective"), AND(C15="Medium", J15="Ineffective")), "Medium", "Low"))))) | O15: Continue daily job-card reconciliation between machine PLC counters and ERP booked production. | P15: Ongoing | Q15: Production Planning Lead
A16: CON-05 | B16: FLEXO WASH-WATER DISCHARGE & CLOSED-LOOP FLOCCULATION FAILURE • HQ Assumption: HQ assumes all flexographic ink wash-water is routed to the on-site Effluent Treatment Plant (ETP), treated with coagulants/flocculants to extract heavy metals and polymers, and clear effluent tested before municipal discharge. • Floor Reality: When the ETP filter press cloth blinds or flocculant chemical tanks run dry, maintenance or printing operators open the emergency bypass drain valve, discharging raw, ink-laden, high-COD wastewater directly into municipal storm drains or soaking it into unpaved yard soil under cover of night, exposing the plant to severe criminal sanctions and immediate environmental shutdown. | C16: Critical | D16: 4. Catastrophic Continuity | E16: 1. Inspect physical plumbing layout of ink wash-water trenches and sumps at all flexo printing presses; trace piping to ETP collection pits. 2. Audit all manual bypass valves, overflow pipes, and drain diversion connections between industrial wash-water lines and storm water / municipal sewer outfalls. 3. Review ETP operational logs: chemical consumption (poly-aluminum chloride, polymer, sulfuric acid) vs volume of treated wastewater. 4. Inspect hazardous waste filter press sludge cakes: reconcile sludge generation weight against ink consumption and verify authorized hazardous waste disposal manifests. 5. Sample final treated effluent discharge point and analyze for Chemical Oxygen Demand (COD), Biological Oxygen Demand (BOD), Total Suspended Solids (TSS), and heavy metal traces (copper/barium from flexo pigments). 6. Audit environmental regulatory discharge permits and verify continuous pH/turbidity monitoring telemetry at the final legal outfall. | F16: ETP SCADA flow meter telemetry, Continuous pH and Turbidity digital sensor logs at final discharge pit, Hazardous Waste disposal manifests and consignment notes, Third-party certified lab environmental testing reports, Municipal sewer inspection reports. | G16: 100% physical piping trace of all flexo wash-water discharge lines; 12-month reconciliation of ETP chemical purchases vs sludge manifests; Independent lab water sample testing of outfall. | H16: WP-CON-05 | I16: Flexo wash-water treatment plant operating in full closed loop. Flocculation and filter press operational; effluent testing confirmed zero discharge to municipal drainage. Sludge cake manifests verified with licensed industrial waste contractor. | J16: Effective | K16: =IF(C16="Critical", 10, IF(C16="High", 5, IF(C16="Medium", 3, 1))) | L16: =IF(J16="Effective", K16*4, IF(J16="Partially Effective", K16*2, IF(J16="Ineffective", K16*1, 0))) | M16: =IF(J16="N/A", 0, K16*4) | N16: =IF(J16="Effective", "None", IF(J16="N/A", "None", IF(AND(C16="Critical", J16="Ineffective"), "Critical", IF(OR(AND(C16="Critical", J16="Partially Effective"), AND(C16="High", J16="Ineffective")), "High", IF(OR(AND(C16="High", J16="Partially Effective"), AND(C16="Medium", J16="Ineffective")), "Medium", "Low"))))) | O16: Maintain weekly environmental manifest log and semi-annual third-party effluent laboratory test. | P16: Ongoing | Q16: HSE & Environmental Lead
