Workbook

Sheet 00_Instructions
A1: CONTINUOUS AUDIT & LOSS PREVENTION: POS CASHIER & TILL FRAUD DETECTION MANUAL
A2: OPERATIONAL SOP: Standard Operating Procedure, POS Data Ingestion Protocols, and Surveillance Review Standards for Audit Teams
A3: Target Scope: Multi-Unit Retail, Food & Beverage, Quick-Service Restaurants | Framework: IIA Continuous Auditing & Monitoring Standards | Version: 2.0
A5: Operational Focus / Step | B5: Field Audit Procedure & Evidentiary Protocol
A6: SECTION 1: OBJECTIVE | B6: 1. AUDIT OBJECTIVE & OPERATIONAL CONTEXT
A7: Operational Context & Till Balancing Limitation | B7: Standard end-of-shift drawer reconciliations confirm only that physical currency matches net recorded POS sales. Cashier misappropriation occurs upstream in the transaction lifecycle by suppressing the record of sale—specifically through post-settlement voids, pre-settlement line item deletions, or unrecorded drawer openings—leaving the register balanced to the penny while currency is diverted.
A8: Electronic Journal (EJ) Transaction Logs | B8: Modern POS systems maintain an append-only Electronic Journal (EJ) recording all terminal events, drawer openings, and supervisory authorizations. Procedural violations leave distinct audit trails: extended latency between ticket opening and cancellation, disproportionate cash tender ratios, and supervisory credential concurrency across separate workstations.
A9: SECTION 2: WORKFLOW | B9: 2. AUDIT PROCEDURE & OPERATING CHECKLIST
A10: Phase 1: Extraction | B10: Export 7 to 30 days of raw POS event logs in CSV format from the POS back-office system. Consult '01_POS_Data_Spec' for system-specific report navigation paths and field mapping schemas (Oracle Micros, NCR Aloha, Toast, Revel, Square).
A11: Phase 2: Master Setup | B11: Open '02_Cashier_Register'. Verify that active cashier rosters, branch terminal assignments, and store baseline parameters (expected cash tender %, normal void rate %, and no-sale drawer benchmark) reflect current operating standards.
A12: Phase 3: Ingestion | B12: Open '03_Raw_POS_Journal'. Populate raw POS transactional data into Columns A through M (Navy Headers #1F4E78) using Paste Special > Values. Preserve Columns N and O (Steel Blue Headers #2F5597), which contain automated calculation formulas for event latency and exception flags.
A13: Phase 4: Analysis | B13: Review calculation tabs '04_Engine_Voids', '05_Engine_Drawer_Kicks', and '06_Engine_Overrides'. The workbook calculates cashier Z-scores, void latency intervals, excess drawer openings, and supervisory authorization concentration without manual formula adjustment.
A14: Phase 5: Risk Prioritization | B14: Open '99_Investigator_Dashboard'. Identify cashiers exhibiting Composite Risk Scores >= 65 (Critical/High Risk) or flagged for supervisory authorization anomalies ('WATCHLIST / HIGH COLLUSION'). Prioritize these personnel for detailed transaction testing.
A15: Phase 6: Video Corroboration | B15: Extract incident timestamps from Table 2 ('Targeted Video Surveillance Review Queue') on '99_Investigator_Dashboard'. Request targeted 5-minute surveillance footage from Loss Prevention / Security to verify physical transaction events prior to administrative follow-up.
A16: SECTION 3: DATA EXTRACTION | B16: 3. POS SYSTEM DATA EXTRACTION PROCEDURES
... A43: [SOFT RED HIGHLIGHTS #FADBD8] | B43: Exception & Risk Flags. Identifies transactions, cashiers, and supervisory accounts exceeding statistical anomaly thresholds.

Sheet 01_POS_Data_Spec
A1: POS SYSTEM FIELD MAPPING & DATA INGESTION SPECIFICATION
A2: OPERATIONAL GUIDANCE: Map extracted POS transaction journal fields to the standardized model parameters below prior to pasting into 03_Raw_POS_Journal.
A4: Model Field Name | B4: Required Format | C4: Description | D4: Oracle Micros Simphony | E4: NCR Aloha | F4: Toast POS | G4: Revel Systems | H4: Square POS
A5: Event_ID | B5: Text (Alpha-Num) | C5: Unique event identifier from POS transaction journal | D5: trans_dtl_seq | E5: EVENT_ID | F5: Event ID | G5: event_id | H5: Event ID
A6: Transaction_ID | B6: Text (Alpha-Num) | C6: Guest check, receipt, or order reference number | D6: check_seq | E6: CHECK_NUM | F6: Order # | G6: order_id | H6: Payment ID
A7: Event_Timestamp | B7: YYYY-MM-DD HH:MM:SS | C7: Exact date and time the POS event was recorded | D7: trans_dtl_tm | E7: SYSTEM_TIME | F7: Opened Time | G7: created_date | H7: Date Time
A8: Branch_ID | B8: Text / Code | C8: Store, restaurant, or site location code | D8: store_num | E8: STORE_ID | F8: Location Code | G8: establishment_id | H8: Location
A9: Terminal_ID | B9: Text / Code | C9: Workstation, register, or tablet terminal identifier | D9: rvc_seq | E9: TERM_ID | F9: Device Name | G9: pos_station_id | H9: Device ID
A10: Cashier_ID | B10: Text / Code | C10: Employee ID currently authenticated on terminal | D10: emp_seq | E10: EMP_ID | F10: Server / Cashier ID | G10: user_id | H10: Employee ID
A11: Supervisor_PIN | B11: Text / Code | C11: Manager or supervisor authorizing void or override | D11: mgr_auth_seq | E11: AUTH_MGR_ID | F11: Manager Override User | G11: authorized_by | H11: Approver ID
A12: Event_Type | B12: Category Text | C12: Event classification (Sale Tender, Post-Bill Void, Line Item Void, No-Sale Drawer Opening) | D12: trans_type_desc | E12: TYPE_NAME | F12: Order Event | G12: type | H12: Event Type
A13: Tender_Type | B13: Category Text | C13: Payment method: Cash, Card, Delivery Aggregator, or N/A | D13: tender_media_name | E13: TENDER_NAME | F13: Payment Method | G13: payment_type | H13: Tender Type
A14: Item_Count | B14: Integer | C14: Number of distinct items on ticket or line voided | D14: item_cnt | E14: QTY | F14: Total Items | G14: line_count | H14: Quantity
A15: Gross_Amount | B15: Currency ($) | C15: Original ticket or item amount before discounts/voids | D15: gross_sales_amt | E15: SUB_TOTAL | F15: Item Amount | G15: gross_amount | H15: Gross Sales
... A17: Order_Start_Time | B17: YYYY-MM-DD HH:MM:SS | C17: Timestamp when check was initially opened / first item scanned | D17: check_open_tm | E17: OPEN_TIME | F17: Order Created At | G17: opened_date | H17: Check Opened

Sheet 02_Cashier_Register
A1: BRANCH BENCHMARKS & CASHIER REGISTRATION DIRECTORY
A2: DATA INPUT & CONFIGURATION: Maintain branch baseline parameters (Rows 5-9) and active cashier roster (Rows 13-28). Blue headers (#1F4E78) designate user-configurable inputs.
A4: BRANCH OPERATING BASELINES & CONTROL THRESHOLDS
A5: Branch ID | B5: Branch Location Name | C5: Total Terminals | D5: Expected Cash % | E5: Normal Void % | F5: No-Sale Benchmark (per 100 Txs)
A6: BR-01 | B6: Downtown Flagship | C6: 4 | D6: 0.35 | E6: 0.018 | F6: 2
A7: BR-02 | B7: Mall Concourse | C7: 4 | D7: 0.4 | E7: 0.021 | F7: 2.5
A8: BR-03 | B8: Airport Terminal 2 | C8: 3 | D8: 0.25 | E8: 0.015 | F8: 1.8
A9: BR-04 | B9: Business Bay Express | C9: 2 | D9: 0.3 | E9: 0.019 | F9: 2.2
A12: ACTIVE CASHIER & WORKSTATION DIRECTORY
A13: Cashier ID | B13: Cashier Full Name | C13: Assigned Branch | D13: Terminal Default | E13: Shift Assignment | F13: Hire Date | G13: Audit Status
A14: C-101 | B14: Marcus Vance | C14: BR-01 | D14: T-01 | E14: Morning | F14: 2024-03-15 | G14: Active
A15: C-102 | B15: Elena Rostova | C15: BR-01 | D15: T-02 | E15: Evening | F15: 2023-11-01 | G15: Active
A16: C-103 | B16: Tariq Mansour | C16: BR-01 | D16: T-01 | E16: Weekend | F16: 2024-07-20 | G16: Active
A17: C-104 | B17: Kevin O'Connor | C17: BR-01 | D17: T-02 | E17: Night | F17: 2025-01-10 | G17: Under Review
A18: C-105 | B18: Sarah Jenkins | C18: BR-02 | D18: T-01 | E18: Morning | F18: 2023-08-14 | G18: Active
A19: C-106 | B19: David Kim | C19: BR-02 | D19: T-02 | E19: Evening | F19: 2024-05-18 | G19: Active
A20: C-107 | B20: Fatima Al-Sayed | C20: BR-02 | D20: T-03 | E20: Weekend | F20: 2024-09-01 | G20: Active
A21: C-108 | B21: Jason Miller | C21: BR-02 | D21: T-01 | E21: Night | F21: 2024-12-05 | G21: Under Review
A22: C-109 | B22: Chloe Dupont | C22: BR-03 | D22: T-01 | E22: Morning | F22: 2023-04-12 | G22: Active
A23: C-110 | B23: Ahmed Hassan | C23: BR-03 | D23: T-02 | E23: Evening | F23: 2024-02-28 | G23: Active
A24: C-111 | B24: Priya Patel | C24: BR-03 | D24: T-01 | E24: Weekend | F24: 2024-10-15 | G24: Active
... A28: C-115 | B28: Samantha Reed | C28: BR-04 | D28: T-01 | E28: Night | F28: 2025-01-22 | G28: Under Review

Sheet 03_Raw_POS_Journal
A1: RAW POS TRANSACTIONAL EVENT JOURNAL
A2: DATA INPUT: Paste raw POS export into Columns A:M (Navy #1F4E78) using Paste Special > Values. Columns N:O (Steel #2F5597) calculate automated latency and audit flags—do not overwrite.
A4: Event_ID | B4: Transaction_ID | C4: Event_Timestamp | D4: Branch_ID | E4: Terminal_ID | F4: Cashier_ID | G4: Supervisor_PIN | H4: Event_Type | I4: Tender_Type | J4: Item_Count | K4: Gross_Amount | L4: Net_Amount | M4: Order_Start_Time | N4: Latency_Seconds | O4: Audit_Flag
A5: EVT-10001 | B5: TX-80001 | C5: 46305.375 | D5: BR-01 | E5: T-02 | F5: C-101 | G5: NONE | H5: Sale Tender | I5: Cash | J5: 6 | K5: 55.61 | L5: 55.61 | M5: 46305.375 | N5: =IFERROR(IF(OR(ISBLANK(M5), M5="", ISBLANK(C5), C5=""), 0, MAX(0, ROUND((C5-M5)*86400, 0))), 0) | O5: =IF(H5="Post-Bill Void", IF(AND(G5="M-904", I5="Cash"), "EXCEPTION: Concurrent Cash Void", IF(AND(I5="Cash", N5>120), "CRITICAL: Delayed Cash Void", IF(N5>120, "EXCEPTION: Delayed Void", "Standard Void"))), IF(H5="Line Item Void", IF(I5="Cash", "EXCEPTION: Cash Line Void", "Standard Line Void"), IF(H5="No-Sale Drawer Opening", "DRAWER OPENING", "Standard Sale")))
A6: EVT-10002 | B6: TX-80002 | C6: 46305.382 | D6: BR-01 | E6: T-01 | F6: C-104 | G6: NONE | H6: Sale Tender | I6: Cash | J6: 5 | K6: 65.08 | L6: 65.08 | M6: 46305.382 | N6: =IFERROR(IF(OR(ISBLANK(M6), M6="", ISBLANK(C6), C6=""), 0, MAX(0, ROUND((C6-M6)*86400, 0))), 0) | O6: =IF(H6="Post-Bill Void", IF(AND(G6="M-904", I6="Cash"), "EXCEPTION: Concurrent Cash Void", IF(AND(I6="Cash", N6>120), "CRITICAL: Delayed Cash Void", IF(N6>120, "EXCEPTION: Delayed Void", "Standard Void"))), IF(H6="Line Item Void", IF(I6="Cash", "EXCEPTION: Cash Line Void", "Standard Line Void"), IF(H6="No-Sale Drawer Opening", "DRAWER OPENING", "Standard Sale")))
A7: EVT-10003 | B7: TX-80003 | C7: 46305.389 | D7: BR-02 | E7: T-01 | F7: C-108 | G7: NONE | H7: Sale Tender | I7: Card | J7: 1 | K7: 14.19 | L7: 14.19 | M7: 46305.389 | N7: =IFERROR(IF(OR(ISBLANK(M7), M7="", ISBLANK(C7), C7=""), 0, MAX(0, ROUND((C7-M7)*86400, 0))), 0) | O7: =IF(H7="Post-Bill Void", IF(AND(G7="M-904", I7="Cash"), "EXCEPTION: Concurrent Cash Void", IF(AND(I7="Cash", N7>120), "CRITICAL: Delayed Cash Void", IF(N7>120, "EXCEPTION: Delayed Void", "Standard Void"))), IF(H7="Line Item Void", IF(I7="Cash", "EXCEPTION: Cash Line Void", "Standard Line Void"), IF(H7="No-Sale Drawer Opening", "DRAWER OPENING", "Standard Sale")))
A8: EVT-10004 | B8: TX-80004 | C8: 46305.396 | D8: BR-04 | E8: T-01 | F8: C-114 | G8: NONE | H8: Sale Tender | I8: Delivery Aggregator | J8: 3 | K8: 27.8 | L8: 27.8 | M8: 46305.395 | N8: =IFERROR(IF(OR(ISBLANK(M8), M8="", ISBLANK(C8), C8=""), 0, MAX(0, ROUND((C8-M8)*86400, 0))), 0) | O8: =IF(H8="Post-Bill Void", IF(AND(G8="M-904", I8="Cash"), "EXCEPTION: Concurrent Cash Void", IF(AND(I8="Cash", N8>120), "CRITICAL: Delayed Cash Void", IF(N8>120, "EXCEPTION: Delayed Void", "Standard Void"))), IF(H8="Line Item Void", IF(I8="Cash", "EXCEPTION: Cash Line Void", "Standard Line Void"), IF(H8="No-Sale Drawer Opening", "DRAWER OPENING", "Standard Sale")))
A9: EVT-10005 | B9: TX-80005 | C9: 46305.403 | D9: BR-01 | E9: T-02 | F9: C-103 | G9: NONE | H9: Sale Tender | I9: Card | J9: 6 | K9: 71.67 | L9: 71.67 | M9: 46305.402 | N9: =IFERROR(IF(OR(ISBLANK(M9), M9="", ISBLANK(C9), C9=""), 0, MAX(0, ROUND((C9-M9)*86400, 0))), 0) | O9: =IF(H9="Post-Bill Void", IF(AND(G9="M-904", I9="Cash"), "EXCEPTION: Concurrent Cash Void", IF(AND(I9="Cash", N9>120), "CRITICAL: Delayed Cash Void", IF(N9>120, "EXCEPTION: Delayed Void", "Standard Void"))), IF(H9="Line Item Void", IF(I9="Cash", "EXCEPTION: Cash Line Void", "Standard Line Void"), IF(H9="No-Sale Drawer Opening", "DRAWER OPENING", "Standard Sale")))
A10: EVT-10006 | B10: TX-80006 | C10: 46305.41 | D10: BR-04 | E10: T-01 | F10: C-113 | G10: NONE | H10: Sale Tender | I10: Card | J10: 6 | K10: 54.13 | L10: 54.13 | M10: 46305.409 | N10: =IFERROR(IF(OR(ISBLANK(M10), M10="", ISBLANK(C10), C10=""), 0, MAX(0, ROUND((C10-M10)*86400, 0))), 0) | O10: =IF(H10="Post-Bill Void", IF(AND(G10="M-904", I10="Cash"), "EXCEPTION: Concurrent Cash Void", IF(AND(I10="Cash", N10>120), "CRITICAL: Delayed Cash Void", IF(N10>120, "EXCEPTION: Delayed Void", "Standard Void"))), IF(H10="Line Item Void", IF(I10="Cash", "EXCEPTION: Cash Line Void", "Standard Line Void"), IF(H10="No-Sale Drawer Opening", "DRAWER OPENING", "Standard Sale")))
A11: EVT-10007 | B11: TX-80007 | C11: 46305.417 | D11: BR-02 | E11: T-02 | F11: C-107 | G11: NONE | H11: Sale Tender | I11: Delivery Aggregator | J11: 4 | K11: 42.34 | L11: 42.34 | M11: 46305.417 | N11: =IFERROR(IF(OR(ISBLANK(M11), M11="", ISBLANK(C11), C11=""), 0, MAX(0, ROUND((C11-M11)*86400, 0))), 0) | O11: =IF(H11="Post-Bill Void", IF(AND(G11="M-904", I11="Cash"), "EXCEPTION: Concurrent Cash Void", IF(AND(I11="Cash", N11>120), "CRITICAL: Delayed Cash Void", IF(N11>120, "EXCEPTION: Delayed Void", "Standard Void"))), IF(H11="Line Item Void", IF(I11="Cash", "EXCEPTION: Cash Line Void", "Standard Line Void"), IF(H11="No-Sale Drawer Opening", "DRAWER OPENING", "Standard Sale")))
A12: EVT-10008 | B12: TX-80008 | C12: 46305.424 | D12: BR-03 | E12: T-01 | F12: C-110 | G12: NONE | H12: Sale Tender | I12: Card | J12: 6 | K12: 93.15 | L12: 93.15 | M12: 46305.423 | N12: =IFERROR(IF(OR(ISBLANK(M12), M12="", ISBLANK(C12), C12=""), 0, MAX(0, ROUND((C12-M12)*86400, 0))), 0) | O12: =IF(H12="Post-Bill Void", IF(AND(G12="M-904", I12="Cash"), "EXCEPTION: Concurrent Cash Void", IF(AND(I12="Cash", N12>120), "CRITICAL: Delayed Cash Void", IF(N12>120, "EXCEPTION: Delayed Void", "Standard Void"))), IF(H12="Line Item Void", IF(I12="Cash", "EXCEPTION: Cash Line Void", "Standard Line Void"), IF(H12="No-Sale Drawer Opening", "DRAWER OPENING", "Standard Sale")))
A13: EVT-10009 | B13: TX-80009 | C13: 46305.431 | D13: BR-01 | E13: T-01 | F13: C-102 | G13: NONE | H13: Sale Tender | I13: Cash | J13: 4 | K13: 42.1 | L13: 42.1 | M13: 46305.43 | N13: =IFERROR(IF(OR(ISBLANK(M13), M13="", ISBLANK(C13), C13=""), 0, MAX(0, ROUND((C13-M13)*86400, 0))), 0) | O13: =IF(H13="Post-Bill Void", IF(AND(G13="M-904", I13="Cash"), "EXCEPTION: Concurrent Cash Void", IF(AND(I13="Cash", N13>120), "CRITICAL: Delayed Cash Void", IF(N13>120, "EXCEPTION: Delayed Void", "Standard Void"))), IF(H13="Line Item Void", IF(I13="Cash", "EXCEPTION: Cash Line Void", "Standard Line Void"), IF(H13="No-Sale Drawer Opening", "DRAWER OPENING", "Standard Sale")))
A14: EVT-10010 | B14: TX-80010 | C14: 46305.438 | D14: BR-02 | E14: T-02 | F14: C-107 | G14: NONE | H14: Sale Tender | I14: Cash | J14: 1 | K14: 14.54 | L14: 14.54 | M14: 46305.438 | N14: =IFERROR(IF(OR(ISBLANK(M14), M14="", ISBLANK(C14), C14=""), 0, MAX(0, ROUND((C14-M14)*86400, 0))), 0) | O14: =IF(H14="Post-Bill Void", IF(AND(G14="M-904", I14="Cash"), "EXCEPTION: Concurrent Cash Void", IF(AND(I14="Cash", N14>120), "CRITICAL: Delayed Cash Void", IF(N14>120, "EXCEPTION: Delayed Void", "Standard Void"))), IF(H14="Line Item Void", IF(I14="Cash", "EXCEPTION: Cash Line Void", "Standard Line Void"), IF(H14="No-Sale Drawer Opening", "DRAWER OPENING", "Standard Sale")))
A15: EVT-10011 | B15: TX-80011 | C15: 46305.445 | D15: BR-03 | E15: T-01 | F15: C-109 | G15: NONE | H15: Sale Tender | I15: Cash | J15: 4 | K15: 45.87 | L15: 45.87 | M15: 46305.444 | N15: =IFERROR(IF(OR(ISBLANK(M15), M15="", ISBLANK(C15), C15=""), 0, MAX(0, ROUND((C15-M15)*86400, 0))), 0) | O15: =IF(H15="Post-Bill Void", IF(AND(G15="M-904", I15="Cash"), "EXCEPTION: Concurrent Cash Void", IF(AND(I15="Cash", N15>120), "CRITICAL: Delayed Cash Void", IF(N15>120, "EXCEPTION: Delayed Void", "Standard Void"))), IF(H15="Line Item Void", IF(I15="Cash", "EXCEPTION: Cash Line Void", "Standard Line Void"), IF(H15="No-Sale Drawer Opening", "DRAWER OPENING", "Standard Sale")))
A16: EVT-10012 | B16: TX-80012 | C16: 46305.452 | D16: BR-04 | E16: T-01 | F16: C-113 | G16: NONE | H16: Sale Tender | I16: Card | J16: 5 | K16: 52.35 | L16: 52.35 | M16: 46305.451 | N16: =IFERROR(IF(OR(ISBLANK(M16), M16="", ISBLANK(C16), C16=""), 0, MAX(0, ROUND((C16-M16)*86400, 0))), 0) | O16: =IF(H16="Post-Bill Void", IF(AND(G16="M-904", I16="Cash"), "EXCEPTION: Concurrent Cash Void", IF(AND(I16="Cash", N16>120), "CRITICAL: Delayed Cash Void", IF(N16>120, "EXCEPTION: Delayed Void", "Standard Void"))), IF(H16="Line Item Void", IF(I16="Cash", "EXCEPTION: Cash Line Void", "Standard Line Void"), IF(H16="No-Sale Drawer Opening", "DRAWER OPENING", "Standard Sale")))
... A678: EVT-10581 | B678: TX-80581 | C678: 46312.265 | D678: BR-02 | E678: T-01 | F678: C-108 | G678: M-902 | H678: Line Item Void | I678: Cash | J678: 2 | K678: 38.2 | L678: 0 | M678: 46312.265 | N678: =IFERROR(IF(OR(ISBLANK(M678), M678="", ISBLANK(C678), C678=""), 0, MAX(0, ROUND((C678-M678)*86400, 0))), 0) | O678: =IF(H678="Post-Bill Void", IF(AND(G678="M-904", I678="Cash"), "EXCEPTION: Concurrent Cash Void", IF(AND(I678="Cash", N678>120), "CRITICAL: Delayed Cash Void", IF(N678>120, "EXCEPTION: Delayed Void", "Standard Void"))), IF(H678="Line Item Void", IF(I678="Cash", "EXCEPTION: Cash Line Void", "Standard Line Void"), IF(H678="No-Sale Drawer Opening", "DRAWER OPENING", "Standard Sale")))

Sheet 04_Engine_Voids
A1: AUDIT ENGINE 1: POST-SETTLEMENT CASH VOID ANALYSIS
A2: AUTOMATED CALCULATION: Evaluates post-settlement void frequency, cash concentration, and elapsed latency between order initiation and cancellation. Steel headers (#2F5597) update dynamically.
A4: Cashier ID | B4: Cashier Name | C4: Branch | D4: Total Sales Count | E4: Cash Sales Count | F4: Total Voids | G4: Cash Voids | H4: Cash Void Rate % | I4: Avg Void Latency (s) | J4: Delayed Voids (>120s) | K4: Critical Cash Voids (>120s) | L4: Void Exposure ($) | M4: Cash Void Z-Score | N4: Void Risk Classification
A5: C-101 | B5: =IFERROR(VLOOKUP(A5, '02_Cashier_Register'!$A$14:$G$28, 2, FALSE), "Unknown") | C5: =IFERROR(VLOOKUP(A5, '02_Cashier_Register'!$A$14:$G$28, 3, FALSE), "Unknown") | D5: =COUNTIFS('03_Raw_POS_Journal'!$F$5:$F$678, A5, '03_Raw_POS_Journal'!$H$5:$H$678, "Sale Tender") | E5: =COUNTIFS('03_Raw_POS_Journal'!$F$5:$F$678, A5, '03_Raw_POS_Journal'!$H$5:$H$678, "Sale Tender", '03_Raw_POS_Journal'!$I$5:$I$678, "Cash") | F5: =COUNTIFS('03_Raw_POS_Journal'!$F$5:$F$678, A5, '03_Raw_POS_Journal'!$H$5:$H$678, "Post-Bill Void") | G5: =COUNTIFS('03_Raw_POS_Journal'!$F$5:$F$678, A5, '03_Raw_POS_Journal'!$H$5:$H$678, "Post-Bill Void", '03_Raw_POS_Journal'!$I$5:$I$678, "Cash") | H5: =IFERROR(IF(E5>0, G5/E5, 0), 0) | I5: =IFERROR(AVERAGEIFS('03_Raw_POS_Journal'!$N$5:$N$678, '03_Raw_POS_Journal'!$F$5:$F$678, A5, '03_Raw_POS_Journal'!$H$5:$H$678, "Post-Bill Void"), 0) | J5: =COUNTIFS('03_Raw_POS_Journal'!$F$5:$F$678, A5, '03_Raw_POS_Journal'!$H$5:$H$678, "Post-Bill Void", '03_Raw_POS_Journal'!$N$5:$N$678, ">120") | K5: =COUNTIFS('03_Raw_POS_Journal'!$F$5:$F$678, A5, '03_Raw_POS_Journal'!$H$5:$H$678, "Post-Bill Void", '03_Raw_POS_Journal'!$I$5:$I$678, "Cash", '03_Raw_POS_Journal'!$N$5:$N$678, ">120") | L5: =SUMIFS('03_Raw_POS_Journal'!$K$5:$K$678, '03_Raw_POS_Journal'!$F$5:$F$678, A5, '03_Raw_POS_Journal'!$H$5:$H$678, "Post-Bill Void", '03_Raw_POS_Journal'!$I$5:$I$678, "Cash") | M5: =IFERROR(IF(_xlfn.STDEV.S($H$5:$H$19)=0, 0, (H5 - AVERAGE($H$5:$H$19)) / _xlfn.STDEV.S($H$5:$H$19)), 0) | N5: =IF(K5>=5, "CRITICAL RISK", IF(OR(K5>=2, M5>=1.5, G5>=5), "ELEVATED RISK", "STANDARD"))
A6: C-102 | B6: =IFERROR(VLOOKUP(A6, '02_Cashier_Register'!$A$14:$G$28, 2, FALSE), "Unknown") | C6: =IFERROR(VLOOKUP(A6, '02_Cashier_Register'!$A$14:$G$28, 3, FALSE), "Unknown") | D6: =COUNTIFS('03_Raw_POS_Journal'!$F$5:$F$678, A6, '03_Raw_POS_Journal'!$H$5:$H$678, "Sale Tender") | E6: =COUNTIFS('03_Raw_POS_Journal'!$F$5:$F$678, A6, '03_Raw_POS_Journal'!$H$5:$H$678, "Sale Tender", '03_Raw_POS_Journal'!$I$5:$I$678, "Cash") | F6: =COUNTIFS('03_Raw_POS_Journal'!$F$5:$F$678, A6, '03_Raw_POS_Journal'!$H$5:$H$678, "Post-Bill Void") | G6: =COUNTIFS('03_Raw_POS_Journal'!$F$5:$F$678, A6, '03_Raw_POS_Journal'!$H$5:$H$678, "Post-Bill Void", '03_Raw_POS_Journal'!$I$5:$I$678, "Cash") | H6: =IFERROR(IF(E6>0, G6/E6, 0), 0) | I6: =IFERROR(AVERAGEIFS('03_Raw_POS_Journal'!$N$5:$N$678, '03_Raw_POS_Journal'!$F$5:$F$678, A6, '03_Raw_POS_Journal'!$H$5:$H$678, "Post-Bill Void"), 0) | J6: =COUNTIFS('03_Raw_POS_Journal'!$F$5:$F$678, A6, '03_Raw_POS_Journal'!$H$5:$H$678, "Post-Bill Void", '03_Raw_POS_Journal'!$N$5:$N$678, ">120") | K6: =COUNTIFS('03_Raw_POS_Journal'!$F$5:$F$678, A6, '03_Raw_POS_Journal'!$H$5:$H$678, "Post-Bill Void", '03_Raw_POS_Journal'!$I$5:$I$678, "Cash", '03_Raw_POS_Journal'!$N$5:$N$678, ">120") | L6: =SUMIFS('03_Raw_POS_Journal'!$K$5:$K$678, '03_Raw_POS_Journal'!$F$5:$F$678, A6, '03_Raw_POS_Journal'!$H$5:$H$678, "Post-Bill Void", '03_Raw_POS_Journal'!$I$5:$I$678, "Cash") | M6: =IFERROR(IF(_xlfn.STDEV.S($H$5:$H$19)=0, 0, (H6 - AVERAGE($H$5:$H$19)) / _xlfn.STDEV.S($H$5:$H$19)), 0) | N6: =IF(K6>=5, "CRITICAL RISK", IF(OR(K6>=2, M6>=1.5, G6>=5), "ELEVATED RISK", "STANDARD"))
A7: C-103 | B7: =IFERROR(VLOOKUP(A7, '02_Cashier_Register'!$A$14:$G$28, 2, FALSE), "Unknown") | C7: =IFERROR(VLOOKUP(A7, '02_Cashier_Register'!$A$14:$G$28, 3, FALSE), "Unknown") | D7: =COUNTIFS('03_Raw_POS_Journal'!$F$5:$F$678, A7, '03_Raw_POS_Journal'!$H$5:$H$678, "Sale Tender") | E7: =COUNTIFS('03_Raw_POS_Journal'!$F$5:$F$678, A7, '03_Raw_POS_Journal'!$H$5:$H$678, "Sale Tender", '03_Raw_POS_Journal'!$I$5:$I$678, "Cash") | F7: =COUNTIFS('03_Raw_POS_Journal'!$F$5:$F$678, A7, '03_Raw_POS_Journal'!$H$5:$H$678, "Post-Bill Void") | G7: =COUNTIFS('03_Raw_POS_Journal'!$F$5:$F$678, A7, '03_Raw_POS_Journal'!$H$5:$H$678, "Post-Bill Void", '03_Raw_POS_Journal'!$I$5:$I$678, "Cash") | H7: =IFERROR(IF(E7>0, G7/E7, 0), 0) | I7: =IFERROR(AVERAGEIFS('03_Raw_POS_Journal'!$N$5:$N$678, '03_Raw_POS_Journal'!$F$5:$F$678, A7, '03_Raw_POS_Journal'!$H$5:$H$678, "Post-Bill Void"), 0) | J7: =COUNTIFS('03_Raw_POS_Journal'!$F$5:$F$678, A7, '03_Raw_POS_Journal'!$H$5:$H$678, "Post-Bill Void", '03_Raw_POS_Journal'!$N$5:$N$678, ">120") | K7: =COUNTIFS('03_Raw_POS_Journal'!$F$5:$F$678, A7, '03_Raw_POS_Journal'!$H$5:$H$678, "Post-Bill Void", '03_Raw_POS_Journal'!$I$5:$I$678, "Cash", '03_Raw_POS_Journal'!$N$5:$N$678, ">120") | L7: =SUMIFS('03_Raw_POS_Journal'!$K$5:$K$678, '03_Raw_POS_Journal'!$F$5:$F$678, A7, '03_Raw_POS_Journal'!$H$5:$H$678, "Post-Bill Void", '03_Raw_POS_Journal'!$I$5:$I$678, "Cash") | M7: =IFERROR(IF(_xlfn.STDEV.S($H$5:$H$19)=0, 0, (H7 - AVERAGE($H$5:$H$19)) / _xlfn.STDEV.S($H$5:$H$19)), 0) | N7: =IF(K7>=5, "CRITICAL RISK", IF(OR(K7>=2, M7>=1.5, G7>=5), "ELEVATED RISK", "STANDARD"))
A8: C-104 | B8: =IFERROR(VLOOKUP(A8, '02_Cashier_Register'!$A$14:$G$28, 2, FALSE), "Unknown") | C8: =IFERROR(VLOOKUP(A8, '02_Cashier_Register'!$A$14:$G$28, 3, FALSE), "Unknown") | D8: =COUNTIFS('03_Raw_POS_Journal'!$F$5:$F$678, A8, '03_Raw_POS_Journal'!$H$5:$H$678, "Sale Tender") | E8: =COUNTIFS('03_Raw_POS_Journal'!$F$5:$F$678, A8, '03_Raw_POS_Journal'!$H$5:$H$678, "Sale Tender", '03_Raw_POS_Journal'!$I$5:$I$678, "Cash") | F8: =COUNTIFS('03_Raw_POS_Journal'!$F$5:$F$678, A8, '03_Raw_POS_Journal'!$H$5:$H$678, "Post-Bill Void") | G8: =COUNTIFS('03_Raw_POS_Journal'!$F$5:$F$678, A8, '03_Raw_POS_Journal'!$H$5:$H$678, "Post-Bill Void", '03_Raw_POS_Journal'!$I$5:$I$678, "Cash") | H8: =IFERROR(IF(E8>0, G8/E8, 0), 0) | I8: =IFERROR(AVERAGEIFS('03_Raw_POS_Journal'!$N$5:$N$678, '03_Raw_POS_Journal'!$F$5:$F$678, A8, '03_Raw_POS_Journal'!$H$5:$H$678, "Post-Bill Void"), 0) | J8: =COUNTIFS('03_Raw_POS_Journal'!$F$5:$F$678, A8, '03_Raw_POS_Journal'!$H$5:$H$678, "Post-Bill Void", '03_Raw_POS_Journal'!$N$5:$N$678, ">120") | K8: =COUNTIFS('03_Raw_POS_Journal'!$F$5:$F$678, A8, '03_Raw_POS_Journal'!$H$5:$H$678, "Post-Bill Void", '03_Raw_POS_Journal'!$I$5:$I$678, "Cash", '03_Raw_POS_Journal'!$N$5:$N$678, ">120") | L8: =SUMIFS('03_Raw_POS_Journal'!$K$5:$K$678, '03_Raw_POS_Journal'!$F$5:$F$678, A8, '03_Raw_POS_Journal'!$H$5:$H$678, "Post-Bill Void", '03_Raw_POS_Journal'!$I$5:$I$678, "Cash") | M8: =IFERROR(IF(_xlfn.STDEV.S($H$5:$H$19)=0, 0, (H8 - AVERAGE($H$5:$H$19)) / _xlfn.STDEV.S($H$5:$H$19)), 0) | N8: =IF(K8>=5, "CRITICAL RISK", IF(OR(K8>=2, M8>=1.5, G8>=5), "ELEVATED RISK", "STANDARD"))
A9: C-105 | B9: =IFERROR(VLOOKUP(A9, '02_Cashier_Register'!$A$14:$G$28, 2, FALSE), "Unknown") | C9: =IFERROR(VLOOKUP(A9, '02_Cashier_Register'!$A$14:$G$28, 3, FALSE), "Unknown") | D9: =COUNTIFS('03_Raw_POS_Journal'!$F$5:$F$678, A9, '03_Raw_POS_Journal'!$H$5:$H$678, "Sale Tender") | E9: =COUNTIFS('03_Raw_POS_Journal'!$F$5:$F$678, A9, '03_Raw_POS_Journal'!$H$5:$H$678, "Sale Tender", '03_Raw_POS_Journal'!$I$5:$I$678, "Cash") | F9: =COUNTIFS('03_Raw_POS_Journal'!$F$5:$F$678, A9, '03_Raw_POS_Journal'!$H$5:$H$678, "Post-Bill Void") | G9: =COUNTIFS('03_Raw_POS_Journal'!$F$5:$F$678, A9, '03_Raw_POS_Journal'!$H$5:$H$678, "Post-Bill Void", '03_Raw_POS_Journal'!$I$5:$I$678, "Cash") | H9: =IFERROR(IF(E9>0, G9/E9, 0), 0) | I9: =IFERROR(AVERAGEIFS('03_Raw_POS_Journal'!$N$5:$N$678, '03_Raw_POS_Journal'!$F$5:$F$678, A9, '03_Raw_POS_Journal'!$H$5:$H$678, "Post-Bill Void"), 0) | J9: =COUNTIFS('03_Raw_POS_Journal'!$F$5:$F$678, A9, '03_Raw_POS_Journal'!$H$5:$H$678, "Post-Bill Void", '03_Raw_POS_Journal'!$N$5:$N$678, ">120") | K9: =COUNTIFS('03_Raw_POS_Journal'!$F$5:$F$678, A9, '03_Raw_POS_Journal'!$H$5:$H$678, "Post-Bill Void", '03_Raw_POS_Journal'!$I$5:$I$678, "Cash", '03_Raw_POS_Journal'!$N$5:$N$678, ">120") | L9: =SUMIFS('03_Raw_POS_Journal'!$K$5:$K$678, '03_Raw_POS_Journal'!$F$5:$F$678, A9, '03_Raw_POS_Journal'!$H$5:$H$678, "Post-Bill Void", '03_Raw_POS_Journal'!$I$5:$I$678, "Cash") | M9: =IFERROR(IF(_xlfn.STDEV.S($H$5:$H$19)=0, 0, (H9 - AVERAGE($H$5:$H$19)) / _xlfn.STDEV.S($H$5:$H$19)), 0) | N9: =IF(K9>=5, "CRITICAL RISK", IF(OR(K9>=2, M9>=1.5, G9>=5), "ELEVATED RISK", "STANDARD"))
A10: C-106 | B10: =IFERROR(VLOOKUP(A10, '02_Cashier_Register'!$A$14:$G$28, 2, FALSE), "Unknown") | C10: =IFERROR(VLOOKUP(A10, '02_Cashier_Register'!$A$14:$G$28, 3, FALSE), "Unknown") | D10: =COUNTIFS('03_Raw_POS_Journal'!$F$5:$F$678, A10, '03_Raw_POS_Journal'!$H$5:$H$678, "Sale Tender") | E10: =COUNTIFS('03_Raw_POS_Journal'!$F$5:$F$678, A10, '03_Raw_POS_Journal'!$H$5:$H$678, "Sale Tender", '03_Raw_POS_Journal'!$I$5:$I$678, "Cash") | F10: =COUNTIFS('03_Raw_POS_Journal'!$F$5:$F$678, A10, '03_Raw_POS_Journal'!$H$5:$H$678, "Post-Bill Void") | G10: =COUNTIFS('03_Raw_POS_Journal'!$F$5:$F$678, A10, '03_Raw_POS_Journal'!$H$5:$H$678, "Post-Bill Void", '03_Raw_POS_Journal'!$I$5:$I$678, "Cash") | H10: =IFERROR(IF(E10>0, G10/E10, 0), 0) | I10: =IFERROR(AVERAGEIFS('03_Raw_POS_Journal'!$N$5:$N$678, '03_Raw_POS_Journal'!$F$5:$F$678, A10, '03_Raw_POS_Journal'!$H$5:$H$678, "Post-Bill Void"), 0) | J10: =COUNTIFS('03_Raw_POS_Journal'!$F$5:$F$678, A10, '03_Raw_POS_Journal'!$H$5:$H$678, "Post-Bill Void", '03_Raw_POS_Journal'!$N$5:$N$678, ">120") | K10: =COUNTIFS('03_Raw_POS_Journal'!$F$5:$F$678, A10, '03_Raw_POS_Journal'!$H$5:$H$678, "Post-Bill Void", '03_Raw_POS_Journal'!$I$5:$I$678, "Cash", '03_Raw_POS_Journal'!$N$5:$N$678, ">120") | L10: =SUMIFS('03_Raw_POS_Journal'!$K$5:$K$678, '03_Raw_POS_Journal'!$F$5:$F$678, A10, '03_Raw_POS_Journal'!$H$5:$H$678, "Post-Bill Void", '03_Raw_POS_Journal'!$I$5:$I$678, "Cash") | M10: =IFERROR(IF(_xlfn.STDEV.S($H$5:$H$19)=0, 0, (H10 - AVERAGE($H$5:$H$19)) / _xlfn.STDEV.S($H$5:$H$19)), 0) | N10: =IF(K10>=5, "CRITICAL RISK", IF(OR(K10>=2, M10>=1.5, G10>=5), "ELEVATED RISK", "STANDARD"))
A11: C-107 | B11: =IFERROR(VLOOKUP(A11, '02_Cashier_Register'!$A$14:$G$28, 2, FALSE), "Unknown") | C11: =IFERROR(VLOOKUP(A11, '02_Cashier_Register'!$A$14:$G$28, 3, FALSE), "Unknown") | D11: =COUNTIFS('03_Raw_POS_Journal'!$F$5:$F$678, A11, '03_Raw_POS_Journal'!$H$5:$H$678, "Sale Tender") | E11: =COUNTIFS('03_Raw_POS_Journal'!$F$5:$F$678, A11, '03_Raw_POS_Journal'!$H$5:$H$678, "Sale Tender", '03_Raw_POS_Journal'!$I$5:$I$678, "Cash") | F11: =COUNTIFS('03_Raw_POS_Journal'!$F$5:$F$678, A11, '03_Raw_POS_Journal'!$H$5:$H$678, "Post-Bill Void") | G11: =COUNTIFS('03_Raw_POS_Journal'!$F$5:$F$678, A11, '03_Raw_POS_Journal'!$H$5:$H$678, "Post-Bill Void", '03_Raw_POS_Journal'!$I$5:$I$678, "Cash") | H11: =IFERROR(IF(E11>0, G11/E11, 0), 0) | I11: =IFERROR(AVERAGEIFS('03_Raw_POS_Journal'!$N$5:$N$678, '03_Raw_POS_Journal'!$F$5:$F$678, A11, '03_Raw_POS_Journal'!$H$5:$H$678, "Post-Bill Void"), 0) | J11: =COUNTIFS('03_Raw_POS_Journal'!$F$5:$F$678, A11, '03_Raw_POS_Journal'!$H$5:$H$678, "Post-Bill Void", '03_Raw_POS_Journal'!$N$5:$N$678, ">120") | K11: =COUNTIFS('03_Raw_POS_Journal'!$F$5:$F$678, A11, '03_Raw_POS_Journal'!$H$5:$H$678, "Post-Bill Void", '03_Raw_POS_Journal'!$I$5:$I$678, "Cash", '03_Raw_POS_Journal'!$N$5:$N$678, ">120") | L11: =SUMIFS('03_Raw_POS_Journal'!$K$5:$K$678, '03_Raw_POS_Journal'!$F$5:$F$678, A11, '03_Raw_POS_Journal'!$H$5:$H$678, "Post-Bill Void", '03_Raw_POS_Journal'!$I$5:$I$678, "Cash") | M11: =IFERROR(IF(_xlfn.STDEV.S($H$5:$H$19)=0, 0, (H11 - AVERAGE($H$5:$H$19)) / _xlfn.STDEV.S($H$5:$H$19)), 0) | N11: =IF(K11>=5, "CRITICAL RISK", IF(OR(K11>=2, M11>=1.5, G11>=5), "ELEVATED RISK", "STANDARD"))
A12: C-108 | B12: =IFERROR(VLOOKUP(A12, '02_Cashier_Register'!$A$14:$G$28, 2, FALSE), "Unknown") | C12: =IFERROR(VLOOKUP(A12, '02_Cashier_Register'!$A$14:$G$28, 3, FALSE), "Unknown") | D12: =COUNTIFS('03_Raw_POS_Journal'!$F$5:$F$678, A12, '03_Raw_POS_Journal'!$H$5:$H$678, "Sale Tender") | E12: =COUNTIFS('03_Raw_POS_Journal'!$F$5:$F$678, A12, '03_Raw_POS_Journal'!$H$5:$H$678, "Sale Tender", '03_Raw_POS_Journal'!$I$5:$I$678, "Cash") | F12: =COUNTIFS('03_Raw_POS_Journal'!$F$5:$F$678, A12, '03_Raw_POS_Journal'!$H$5:$H$678, "Post-Bill Void") | G12: =COUNTIFS('03_Raw_POS_Journal'!$F$5:$F$678, A12, '03_Raw_POS_Journal'!$H$5:$H$678, "Post-Bill Void", '03_Raw_POS_Journal'!$I$5:$I$678, "Cash") | H12: =IFERROR(IF(E12>0, G12/E12, 0), 0) | I12: =IFERROR(AVERAGEIFS('03_Raw_POS_Journal'!$N$5:$N$678, '03_Raw_POS_Journal'!$F$5:$F$678, A12, '03_Raw_POS_Journal'!$H$5:$H$678, "Post-Bill Void"), 0) | J12: =COUNTIFS('03_Raw_POS_Journal'!$F$5:$F$678, A12, '03_Raw_POS_Journal'!$H$5:$H$678, "Post-Bill Void", '03_Raw_POS_Journal'!$N$5:$N$678, ">120") | K12: =COUNTIFS('03_Raw_POS_Journal'!$F$5:$F$678, A12, '03_Raw_POS_Journal'!$H$5:$H$678, "Post-Bill Void", '03_Raw_POS_Journal'!$I$5:$I$678, "Cash", '03_Raw_POS_Journal'!$N$5:$N$678, ">120") | L12: =SUMIFS('03_Raw_POS_Journal'!$K$5:$K$678, '03_Raw_POS_Journal'!$F$5:$F$678, A12, '03_Raw_POS_Journal'!$H$5:$H$678, "Post-Bill Void", '03_Raw_POS_Journal'!$I$5:$I$678, "Cash") | M12: =IFERROR(IF(_xlfn.STDEV.S($H$5:$H$19)=0, 0, (H12 - AVERAGE($H$5:$H$19)) / _xlfn.STDEV.S($H$5:$H$19)), 0) | N12: =IF(K12>=5, "CRITICAL RISK", IF(OR(K12>=2, M12>=1.5, G12>=5), "ELEVATED RISK", "STANDARD"))
A13: C-109 | B13: =IFERROR(VLOOKUP(A13, '02_Cashier_Register'!$A$14:$G$28, 2, FALSE), "Unknown") | C13: =IFERROR(VLOOKUP(A13, '02_Cashier_Register'!$A$14:$G$28, 3, FALSE), "Unknown") | D13: =COUNTIFS('03_Raw_POS_Journal'!$F$5:$F$678, A13, '03_Raw_POS_Journal'!$H$5:$H$678, "Sale Tender") | E13: =COUNTIFS('03_Raw_POS_Journal'!$F$5:$F$678, A13, '03_Raw_POS_Journal'!$H$5:$H$678, "Sale Tender", '03_Raw_POS_Journal'!$I$5:$I$678, "Cash") | F13: =COUNTIFS('03_Raw_POS_Journal'!$F$5:$F$678, A13, '03_Raw_POS_Journal'!$H$5:$H$678, "Post-Bill Void") | G13: =COUNTIFS('03_Raw_POS_Journal'!$F$5:$F$678, A13, '03_Raw_POS_Journal'!$H$5:$H$678, "Post-Bill Void", '03_Raw_POS_Journal'!$I$5:$I$678, "Cash") | H13: =IFERROR(IF(E13>0, G13/E13, 0), 0) | I13: =IFERROR(AVERAGEIFS('03_Raw_POS_Journal'!$N$5:$N$678, '03_Raw_POS_Journal'!$F$5:$F$678, A13, '03_Raw_POS_Journal'!$H$5:$H$678, "Post-Bill Void"), 0) | J13: =COUNTIFS('03_Raw_POS_Journal'!$F$5:$F$678, A13, '03_Raw_POS_Journal'!$H$5:$H$678, "Post-Bill Void", '03_Raw_POS_Journal'!$N$5:$N$678, ">120") | K13: =COUNTIFS('03_Raw_POS_Journal'!$F$5:$F$678, A13, '03_Raw_POS_Journal'!$H$5:$H$678, "Post-Bill Void", '03_Raw_POS_Journal'!$I$5:$I$678, "Cash", '03_Raw_POS_Journal'!$N$5:$N$678, ">120") | L13: =SUMIFS('03_Raw_POS_Journal'!$K$5:$K$678, '03_Raw_POS_Journal'!$F$5:$F$678, A13, '03_Raw_POS_Journal'!$H$5:$H$678, "Post-Bill Void", '03_Raw_POS_Journal'!$I$5:$I$678, "Cash") | M13: =IFERROR(IF(_xlfn.STDEV.S($H$5:$H$19)=0, 0, (H13 - AVERAGE($H$5:$H$19)) / _xlfn.STDEV.S($H$5:$H$19)), 0) | N13: =IF(K13>=5, "CRITICAL RISK", IF(OR(K13>=2, M13>=1.5, G13>=5), "ELEVATED RISK", "STANDARD"))
A14: C-110 | B14: =IFERROR(VLOOKUP(A14, '02_Cashier_Register'!$A$14:$G$28, 2, FALSE), "Unknown") | C14: =IFERROR(VLOOKUP(A14, '02_Cashier_Register'!$A$14:$G$28, 3, FALSE), "Unknown") | D14: =COUNTIFS('03_Raw_POS_Journal'!$F$5:$F$678, A14, '03_Raw_POS_Journal'!$H$5:$H$678, "Sale Tender") | E14: =COUNTIFS('03_Raw_POS_Journal'!$F$5:$F$678, A14, '03_Raw_POS_Journal'!$H$5:$H$678, "Sale Tender", '03_Raw_POS_Journal'!$I$5:$I$678, "Cash") | F14: =COUNTIFS('03_Raw_POS_Journal'!$F$5:$F$678, A14, '03_Raw_POS_Journal'!$H$5:$H$678, "Post-Bill Void") | G14: =COUNTIFS('03_Raw_POS_Journal'!$F$5:$F$678, A14, '03_Raw_POS_Journal'!$H$5:$H$678, "Post-Bill Void", '03_Raw_POS_Journal'!$I$5:$I$678, "Cash") | H14: =IFERROR(IF(E14>0, G14/E14, 0), 0) | I14: =IFERROR(AVERAGEIFS('03_Raw_POS_Journal'!$N$5:$N$678, '03_Raw_POS_Journal'!$F$5:$F$678, A14, '03_Raw_POS_Journal'!$H$5:$H$678, "Post-Bill Void"), 0) | J14: =COUNTIFS('03_Raw_POS_Journal'!$F$5:$F$678, A14, '03_Raw_POS_Journal'!$H$5:$H$678, "Post-Bill Void", '03_Raw_POS_Journal'!$N$5:$N$678, ">120") | K14: =COUNTIFS('03_Raw_POS_Journal'!$F$5:$F$678, A14, '03_Raw_POS_Journal'!$H$5:$H$678, "Post-Bill Void", '03_Raw_POS_Journal'!$I$5:$I$678, "Cash", '03_Raw_POS_Journal'!$N$5:$N$678, ">120") | L14: =SUMIFS('03_Raw_POS_Journal'!$K$5:$K$678, '03_Raw_POS_Journal'!$F$5:$F$678, A14, '03_Raw_POS_Journal'!$H$5:$H$678, "Post-Bill Void", '03_Raw_POS_Journal'!$I$5:$I$678, "Cash") | M14: =IFERROR(IF(_xlfn.STDEV.S($H$5:$H$19)=0, 0, (H14 - AVERAGE($H$5:$H$19)) / _xlfn.STDEV.S($H$5:$H$19)), 0) | N14: =IF(K14>=5, "CRITICAL RISK", IF(OR(K14>=2, M14>=1.5, G14>=5), "ELEVATED RISK", "STANDARD"))
A15: C-111 | B15: =IFERROR(VLOOKUP(A15, '02_Cashier_Register'!$A$14:$G$28, 2, FALSE), "Unknown") | C15: =IFERROR(VLOOKUP(A15, '02_Cashier_Register'!$A$14:$G$28, 3, FALSE), "Unknown") | D15: =COUNTIFS('03_Raw_POS_Journal'!$F$5:$F$678, A15, '03_Raw_POS_Journal'!$H$5:$H$678, "Sale Tender") | E15: =COUNTIFS('03_Raw_POS_Journal'!$F$5:$F$678, A15, '03_Raw_POS_Journal'!$H$5:$H$678, "Sale Tender", '03_Raw_POS_Journal'!$I$5:$I$678, "Cash") | F15: =COUNTIFS('03_Raw_POS_Journal'!$F$5:$F$678, A15, '03_Raw_POS_Journal'!$H$5:$H$678, "Post-Bill Void") | G15: =COUNTIFS('03_Raw_POS_Journal'!$F$5:$F$678, A15, '03_Raw_POS_Journal'!$H$5:$H$678, "Post-Bill Void", '03_Raw_POS_Journal'!$I$5:$I$678, "Cash") | H15: =IFERROR(IF(E15>0, G15/E15, 0), 0) | I15: =IFERROR(AVERAGEIFS('03_Raw_POS_Journal'!$N$5:$N$678, '03_Raw_POS_Journal'!$F$5:$F$678, A15, '03_Raw_POS_Journal'!$H$5:$H$678, "Post-Bill Void"), 0) | J15: =COUNTIFS('03_Raw_POS_Journal'!$F$5:$F$678, A15, '03_Raw_POS_Journal'!$H$5:$H$678, "Post-Bill Void", '03_Raw_POS_Journal'!$N$5:$N$678, ">120") | K15: =COUNTIFS('03_Raw_POS_Journal'!$F$5:$F$678, A15, '03_Raw_POS_Journal'!$H$5:$H$678, "Post-Bill Void", '03_Raw_POS_Journal'!$I$5:$I$678, "Cash", '03_Raw_POS_Journal'!$N$5:$N$678, ">120") | L15: =SUMIFS('03_Raw_POS_Journal'!$K$5:$K$678, '03_Raw_POS_Journal'!$F$5:$F$678, A15, '03_Raw_POS_Journal'!$H$5:$H$678, "Post-Bill Void", '03_Raw_POS_Journal'!$I$5:$I$678, "Cash") | M15: =IFERROR(IF(_xlfn.STDEV.S($H$5:$H$19)=0, 0, (H15 - AVERAGE($H$5:$H$19)) / _xlfn.STDEV.S($H$5:$H$19)), 0) | N15: =IF(K15>=5, "CRITICAL RISK", IF(OR(K15>=2, M15>=1.5, G15>=5), "ELEVATED RISK", "STANDARD"))
A16: C-112 | B16: =IFERROR(VLOOKUP(A16, '02_Cashier_Register'!$A$14:$G$28, 2, FALSE), "Unknown") | C16: =IFERROR(VLOOKUP(A16, '02_Cashier_Register'!$A$14:$G$28, 3, FALSE), "Unknown") | D16: =COUNTIFS('03_Raw_POS_Journal'!$F$5:$F$678, A16, '03_Raw_POS_Journal'!$H$5:$H$678, "Sale Tender") | E16: =COUNTIFS('03_Raw_POS_Journal'!$F$5:$F$678, A16, '03_Raw_POS_Journal'!$H$5:$H$678, "Sale Tender", '03_Raw_POS_Journal'!$I$5:$I$678, "Cash") | F16: =COUNTIFS('03_Raw_POS_Journal'!$F$5:$F$678, A16, '03_Raw_POS_Journal'!$H$5:$H$678, "Post-Bill Void") | G16: =COUNTIFS('03_Raw_POS_Journal'!$F$5:$F$678, A16, '03_Raw_POS_Journal'!$H$5:$H$678, "Post-Bill Void", '03_Raw_POS_Journal'!$I$5:$I$678, "Cash") | H16: =IFERROR(IF(E16>0, G16/E16, 0), 0) | I16: =IFERROR(AVERAGEIFS('03_Raw_POS_Journal'!$N$5:$N$678, '03_Raw_POS_Journal'!$F$5:$F$678, A16, '03_Raw_POS_Journal'!$H$5:$H$678, "Post-Bill Void"), 0) | J16: =COUNTIFS('03_Raw_POS_Journal'!$F$5:$F$678, A16, '03_Raw_POS_Journal'!$H$5:$H$678, "Post-Bill Void", '03_Raw_POS_Journal'!$N$5:$N$678, ">120") | K16: =COUNTIFS('03_Raw_POS_Journal'!$F$5:$F$678, A16, '03_Raw_POS_Journal'!$H$5:$H$678, "Post-Bill Void", '03_Raw_POS_Journal'!$I$5:$I$678, "Cash", '03_Raw_POS_Journal'!$N$5:$N$678, ">120") | L16: =SUMIFS('03_Raw_POS_Journal'!$K$5:$K$678, '03_Raw_POS_Journal'!$F$5:$F$678, A16, '03_Raw_POS_Journal'!$H$5:$H$678, "Post-Bill Void", '03_Raw_POS_Journal'!$I$5:$I$678, "Cash") | M16: =IFERROR(IF(_xlfn.STDEV.S($H$5:$H$19)=0, 0, (H16 - AVERAGE($H$5:$H$19)) / _xlfn.STDEV.S($H$5:$H$19)), 0) | N16: =IF(K16>=5, "CRITICAL RISK", IF(OR(K16>=2, M16>=1.5, G16>=5), "ELEVATED RISK", "STANDARD"))
... A19: C-115 | B19: =IFERROR(VLOOKUP(A19, '02_Cashier_Register'!$A$14:$G$28, 2, FALSE), "Unknown") | C19: =IFERROR(VLOOKUP(A19, '02_Cashier_Register'!$A$14:$G$28, 3, FALSE), "Unknown") | D19: =COUNTIFS('03_Raw_POS_Journal'!$F$5:$F$678, A19, '03_Raw_POS_Journal'!$H$5:$H$678, "Sale Tender") | E19: =COUNTIFS('03_Raw_POS_Journal'!$F$5:$F$678, A19, '03_Raw_POS_Journal'!$H$5:$H$678, "Sale Tender", '03_Raw_POS_Journal'!$I$5:$I$678, "Cash") | F19: =COUNTIFS('03_Raw_POS_Journal'!$F$5:$F$678, A19, '03_Raw_POS_Journal'!$H$5:$H$678, "Post-Bill Void") | G19: =COUNTIFS('03_Raw_POS_Journal'!$F$5:$F$678, A19, '03_Raw_POS_Journal'!$H$5:$H$678, "Post-Bill Void", '03_Raw_POS_Journal'!$I$5:$I$678, "Cash") | H19: =IFERROR(IF(E19>0, G19/E19, 0), 0) | I19: =IFERROR(AVERAGEIFS('03_Raw_POS_Journal'!$N$5:$N$678, '03_Raw_POS_Journal'!$F$5:$F$678, A19, '03_Raw_POS_Journal'!$H$5:$H$678, "Post-Bill Void"), 0) | J19: =COUNTIFS('03_Raw_POS_Journal'!$F$5:$F$678, A19, '03_Raw_POS_Journal'!$H$5:$H$678, "Post-Bill Void", '03_Raw_POS_Journal'!$N$5:$N$678, ">120") | K19: =COUNTIFS('03_Raw_POS_Journal'!$F$5:$F$678, A19, '03_Raw_POS_Journal'!$H$5:$H$678, "Post-Bill Void", '03_Raw_POS_Journal'!$I$5:$I$678, "Cash", '03_Raw_POS_Journal'!$N$5:$N$678, ">120") | L19: =SUMIFS('03_Raw_POS_Journal'!$K$5:$K$678, '03_Raw_POS_Journal'!$F$5:$F$678, A19, '03_Raw_POS_Journal'!$H$5:$H$678, "Post-Bill Void", '03_Raw_POS_Journal'!$I$5:$I$678, "Cash") | M19: =IFERROR(IF(_xlfn.STDEV.S($H$5:$H$19)=0, 0, (H19 - AVERAGE($H$5:$H$19)) / _xlfn.STDEV.S($H$5:$H$19)), 0) | N19: =IF(K19>=5, "CRITICAL RISK", IF(OR(K19>=2, M19>=1.5, G19>=5), "ELEVATED RISK", "STANDARD"))
A20: TOTAL / BENCHMARK | D20: =SUM(D5:D19) | E20: =SUM(E5:E19) | F20: =SUM(F5:F19) | G20: =SUM(G5:G19) | H20: =IFERROR(IF(E20>0, G20/E20, 0), 0) | I20: =IFERROR(AVERAGEIFS('03_Raw_POS_Journal'!$N$5:$N$678, '03_Raw_POS_Journal'!$H$5:$H$678, "Post-Bill Void"), 0) | J20: =SUM(J5:J19) | K20: =SUM(K5:K19) | L20: =SUM(L5:L19)

Sheet 05_Engine_Drawer_Kicks
A1: AUDIT ENGINE 2: NO-SALE DRAWER ACTIVITY ANALYSIS
A2: AUTOMATED CALCULATION: Benchmarks unrecorded till openings against peer averages and store baselines to detect off-book cash trade. Steel headers (#2F5597) update dynamically.
A4: Cashier ID | B4: Cashier Name | C4: Branch | D4: Total Paid Sales | E4: No-Sale Drawer Openings | F4: Openings per 100 Sales | G4: Branch Benchmark Rate | H4: Excess Drawer Openings | I4: Avg Ticket Size ($) | J4: Est. Unrecorded Exposure ($) | K4: Opening Rate Z-Score | L4: Drawer Risk Classification
A5: C-101 | B5: =IFERROR(VLOOKUP(A5, '02_Cashier_Register'!$A$14:$G$28, 2, FALSE), "Unknown") | C5: =IFERROR(VLOOKUP(A5, '02_Cashier_Register'!$A$14:$G$28, 3, FALSE), "Unknown") | D5: =COUNTIFS('03_Raw_POS_Journal'!$F$5:$F$678, A5, '03_Raw_POS_Journal'!$H$5:$H$678, "Sale Tender") | E5: =COUNTIFS('03_Raw_POS_Journal'!$F$5:$F$678, A5, '03_Raw_POS_Journal'!$H$5:$H$678, "No-Sale Drawer Opening") | F5: =IFERROR(IF(D5>0, (E5/D5)*100, 0), 0) | G5: =IFERROR(VLOOKUP(C5, '02_Cashier_Register'!$A$6:$F$9, 6, FALSE), 2.0) | H5: =MAX(0, E5 - (D5 * G5 / 100)) | I5: =IFERROR(AVERAGEIFS('03_Raw_POS_Journal'!$K$5:$K$678, '03_Raw_POS_Journal'!$D$5:$D$678, C5, '03_Raw_POS_Journal'!$H$5:$H$678, "Sale Tender"), IFERROR(AVERAGEIFS('03_Raw_POS_Journal'!$K$5:$K$678, '03_Raw_POS_Journal'!$H$5:$H$678, "Sale Tender"), 25.0)) | J5: =H5 * I5 * 0.40 | K5: =IFERROR(IF(_xlfn.STDEV.S($F$5:$F$19)=0, 0, (F5 - AVERAGE($F$5:$F$19)) / _xlfn.STDEV.S($F$5:$F$19)), 0) | L5: =IF(K5>=2.0, "HIGH RISK", IF(K5>=1.0, "ELEVATED RISK", "STANDARD"))
A6: C-102 | B6: =IFERROR(VLOOKUP(A6, '02_Cashier_Register'!$A$14:$G$28, 2, FALSE), "Unknown") | C6: =IFERROR(VLOOKUP(A6, '02_Cashier_Register'!$A$14:$G$28, 3, FALSE), "Unknown") | D6: =COUNTIFS('03_Raw_POS_Journal'!$F$5:$F$678, A6, '03_Raw_POS_Journal'!$H$5:$H$678, "Sale Tender") | E6: =COUNTIFS('03_Raw_POS_Journal'!$F$5:$F$678, A6, '03_Raw_POS_Journal'!$H$5:$H$678, "No-Sale Drawer Opening") | F6: =IFERROR(IF(D6>0, (E6/D6)*100, 0), 0) | G6: =IFERROR(VLOOKUP(C6, '02_Cashier_Register'!$A$6:$F$9, 6, FALSE), 2.0) | H6: =MAX(0, E6 - (D6 * G6 / 100)) | I6: =IFERROR(AVERAGEIFS('03_Raw_POS_Journal'!$K$5:$K$678, '03_Raw_POS_Journal'!$D$5:$D$678, C6, '03_Raw_POS_Journal'!$H$5:$H$678, "Sale Tender"), IFERROR(AVERAGEIFS('03_Raw_POS_Journal'!$K$5:$K$678, '03_Raw_POS_Journal'!$H$5:$H$678, "Sale Tender"), 25.0)) | J6: =H6 * I6 * 0.40 | K6: =IFERROR(IF(_xlfn.STDEV.S($F$5:$F$19)=0, 0, (F6 - AVERAGE($F$5:$F$19)) / _xlfn.STDEV.S($F$5:$F$19)), 0) | L6: =IF(K6>=2.0, "HIGH RISK", IF(K6>=1.0, "ELEVATED RISK", "STANDARD"))
A7: C-103 | B7: =IFERROR(VLOOKUP(A7, '02_Cashier_Register'!$A$14:$G$28, 2, FALSE), "Unknown") | C7: =IFERROR(VLOOKUP(A7, '02_Cashier_Register'!$A$14:$G$28, 3, FALSE), "Unknown") | D7: =COUNTIFS('03_Raw_POS_Journal'!$F$5:$F$678, A7, '03_Raw_POS_Journal'!$H$5:$H$678, "Sale Tender") | E7: =COUNTIFS('03_Raw_POS_Journal'!$F$5:$F$678, A7, '03_Raw_POS_Journal'!$H$5:$H$678, "No-Sale Drawer Opening") | F7: =IFERROR(IF(D7>0, (E7/D7)*100, 0), 0) | G7: =IFERROR(VLOOKUP(C7, '02_Cashier_Register'!$A$6:$F$9, 6, FALSE), 2.0) | H7: =MAX(0, E7 - (D7 * G7 / 100)) | I7: =IFERROR(AVERAGEIFS('03_Raw_POS_Journal'!$K$5:$K$678, '03_Raw_POS_Journal'!$D$5:$D$678, C7, '03_Raw_POS_Journal'!$H$5:$H$678, "Sale Tender"), IFERROR(AVERAGEIFS('03_Raw_POS_Journal'!$K$5:$K$678, '03_Raw_POS_Journal'!$H$5:$H$678, "Sale Tender"), 25.0)) | J7: =H7 * I7 * 0.40 | K7: =IFERROR(IF(_xlfn.STDEV.S($F$5:$F$19)=0, 0, (F7 - AVERAGE($F$5:$F$19)) / _xlfn.STDEV.S($F$5:$F$19)), 0) | L7: =IF(K7>=2.0, "HIGH RISK", IF(K7>=1.0, "ELEVATED RISK", "STANDARD"))
A8: C-104 | B8: =IFERROR(VLOOKUP(A8, '02_Cashier_Register'!$A$14:$G$28, 2, FALSE), "Unknown") | C8: =IFERROR(VLOOKUP(A8, '02_Cashier_Register'!$A$14:$G$28, 3, FALSE), "Unknown") | D8: =COUNTIFS('03_Raw_POS_Journal'!$F$5:$F$678, A8, '03_Raw_POS_Journal'!$H$5:$H$678, "Sale Tender") | E8: =COUNTIFS('03_Raw_POS_Journal'!$F$5:$F$678, A8, '03_Raw_POS_Journal'!$H$5:$H$678, "No-Sale Drawer Opening") | F8: =IFERROR(IF(D8>0, (E8/D8)*100, 0), 0) | G8: =IFERROR(VLOOKUP(C8, '02_Cashier_Register'!$A$6:$F$9, 6, FALSE), 2.0) | H8: =MAX(0, E8 - (D8 * G8 / 100)) | I8: =IFERROR(AVERAGEIFS('03_Raw_POS_Journal'!$K$5:$K$678, '03_Raw_POS_Journal'!$D$5:$D$678, C8, '03_Raw_POS_Journal'!$H$5:$H$678, "Sale Tender"), IFERROR(AVERAGEIFS('03_Raw_POS_Journal'!$K$5:$K$678, '03_Raw_POS_Journal'!$H$5:$H$678, "Sale Tender"), 25.0)) | J8: =H8 * I8 * 0.40 | K8: =IFERROR(IF(_xlfn.STDEV.S($F$5:$F$19)=0, 0, (F8 - AVERAGE($F$5:$F$19)) / _xlfn.STDEV.S($F$5:$F$19)), 0) | L8: =IF(K8>=2.0, "HIGH RISK", IF(K8>=1.0, "ELEVATED RISK", "STANDARD"))
A9: C-105 | B9: =IFERROR(VLOOKUP(A9, '02_Cashier_Register'!$A$14:$G$28, 2, FALSE), "Unknown") | C9: =IFERROR(VLOOKUP(A9, '02_Cashier_Register'!$A$14:$G$28, 3, FALSE), "Unknown") | D9: =COUNTIFS('03_Raw_POS_Journal'!$F$5:$F$678, A9, '03_Raw_POS_Journal'!$H$5:$H$678, "Sale Tender") | E9: =COUNTIFS('03_Raw_POS_Journal'!$F$5:$F$678, A9, '03_Raw_POS_Journal'!$H$5:$H$678, "No-Sale Drawer Opening") | F9: =IFERROR(IF(D9>0, (E9/D9)*100, 0), 0) | G9: =IFERROR(VLOOKUP(C9, '02_Cashier_Register'!$A$6:$F$9, 6, FALSE), 2.0) | H9: =MAX(0, E9 - (D9 * G9 / 100)) | I9: =IFERROR(AVERAGEIFS('03_Raw_POS_Journal'!$K$5:$K$678, '03_Raw_POS_Journal'!$D$5:$D$678, C9, '03_Raw_POS_Journal'!$H$5:$H$678, "Sale Tender"), IFERROR(AVERAGEIFS('03_Raw_POS_Journal'!$K$5:$K$678, '03_Raw_POS_Journal'!$H$5:$H$678, "Sale Tender"), 25.0)) | J9: =H9 * I9 * 0.40 | K9: =IFERROR(IF(_xlfn.STDEV.S($F$5:$F$19)=0, 0, (F9 - AVERAGE($F$5:$F$19)) / _xlfn.STDEV.S($F$5:$F$19)), 0) | L9: =IF(K9>=2.0, "HIGH RISK", IF(K9>=1.0, "ELEVATED RISK", "STANDARD"))
A10: C-106 | B10: =IFERROR(VLOOKUP(A10, '02_Cashier_Register'!$A$14:$G$28, 2, FALSE), "Unknown") | C10: =IFERROR(VLOOKUP(A10, '02_Cashier_Register'!$A$14:$G$28, 3, FALSE), "Unknown") | D10: =COUNTIFS('03_Raw_POS_Journal'!$F$5:$F$678, A10, '03_Raw_POS_Journal'!$H$5:$H$678, "Sale Tender") | E10: =COUNTIFS('03_Raw_POS_Journal'!$F$5:$F$678, A10, '03_Raw_POS_Journal'!$H$5:$H$678, "No-Sale Drawer Opening") | F10: =IFERROR(IF(D10>0, (E10/D10)*100, 0), 0) | G10: =IFERROR(VLOOKUP(C10, '02_Cashier_Register'!$A$6:$F$9, 6, FALSE), 2.0) | H10: =MAX(0, E10 - (D10 * G10 / 100)) | I10: =IFERROR(AVERAGEIFS('03_Raw_POS_Journal'!$K$5:$K$678, '03_Raw_POS_Journal'!$D$5:$D$678, C10, '03_Raw_POS_Journal'!$H$5:$H$678, "Sale Tender"), IFERROR(AVERAGEIFS('03_Raw_POS_Journal'!$K$5:$K$678, '03_Raw_POS_Journal'!$H$5:$H$678, "Sale Tender"), 25.0)) | J10: =H10 * I10 * 0.40 | K10: =IFERROR(IF(_xlfn.STDEV.S($F$5:$F$19)=0, 0, (F10 - AVERAGE($F$5:$F$19)) / _xlfn.STDEV.S($F$5:$F$19)), 0) | L10: =IF(K10>=2.0, "HIGH RISK", IF(K10>=1.0, "ELEVATED RISK", "STANDARD"))
A11: C-107 | B11: =IFERROR(VLOOKUP(A11, '02_Cashier_Register'!$A$14:$G$28, 2, FALSE), "Unknown") | C11: =IFERROR(VLOOKUP(A11, '02_Cashier_Register'!$A$14:$G$28, 3, FALSE), "Unknown") | D11: =COUNTIFS('03_Raw_POS_Journal'!$F$5:$F$678, A11, '03_Raw_POS_Journal'!$H$5:$H$678, "Sale Tender") | E11: =COUNTIFS('03_Raw_POS_Journal'!$F$5:$F$678, A11, '03_Raw_POS_Journal'!$H$5:$H$678, "No-Sale Drawer Opening") | F11: =IFERROR(IF(D11>0, (E11/D11)*100, 0), 0) | G11: =IFERROR(VLOOKUP(C11, '02_Cashier_Register'!$A$6:$F$9, 6, FALSE), 2.0) | H11: =MAX(0, E11 - (D11 * G11 / 100)) | I11: =IFERROR(AVERAGEIFS('03_Raw_POS_Journal'!$K$5:$K$678, '03_Raw_POS_Journal'!$D$5:$D$678, C11, '03_Raw_POS_Journal'!$H$5:$H$678, "Sale Tender"), IFERROR(AVERAGEIFS('03_Raw_POS_Journal'!$K$5:$K$678, '03_Raw_POS_Journal'!$H$5:$H$678, "Sale Tender"), 25.0)) | J11: =H11 * I11 * 0.40 | K11: =IFERROR(IF(_xlfn.STDEV.S($F$5:$F$19)=0, 0, (F11 - AVERAGE($F$5:$F$19)) / _xlfn.STDEV.S($F$5:$F$19)), 0) | L11: =IF(K11>=2.0, "HIGH RISK", IF(K11>=1.0, "ELEVATED RISK", "STANDARD"))
A12: C-108 | B12: =IFERROR(VLOOKUP(A12, '02_Cashier_Register'!$A$14:$G$28, 2, FALSE), "Unknown") | C12: =IFERROR(VLOOKUP(A12, '02_Cashier_Register'!$A$14:$G$28, 3, FALSE), "Unknown") | D12: =COUNTIFS('03_Raw_POS_Journal'!$F$5:$F$678, A12, '03_Raw_POS_Journal'!$H$5:$H$678, "Sale Tender") | E12: =COUNTIFS('03_Raw_POS_Journal'!$F$5:$F$678, A12, '03_Raw_POS_Journal'!$H$5:$H$678, "No-Sale Drawer Opening") | F12: =IFERROR(IF(D12>0, (E12/D12)*100, 0), 0) | G12: =IFERROR(VLOOKUP(C12, '02_Cashier_Register'!$A$6:$F$9, 6, FALSE), 2.0) | H12: =MAX(0, E12 - (D12 * G12 / 100)) | I12: =IFERROR(AVERAGEIFS('03_Raw_POS_Journal'!$K$5:$K$678, '03_Raw_POS_Journal'!$D$5:$D$678, C12, '03_Raw_POS_Journal'!$H$5:$H$678, "Sale Tender"), IFERROR(AVERAGEIFS('03_Raw_POS_Journal'!$K$5:$K$678, '03_Raw_POS_Journal'!$H$5:$H$678, "Sale Tender"), 25.0)) | J12: =H12 * I12 * 0.40 | K12: =IFERROR(IF(_xlfn.STDEV.S($F$5:$F$19)=0, 0, (F12 - AVERAGE($F$5:$F$19)) / _xlfn.STDEV.S($F$5:$F$19)), 0) | L12: =IF(K12>=2.0, "HIGH RISK", IF(K12>=1.0, "ELEVATED RISK", "STANDARD"))
A13: C-109 | B13: =IFERROR(VLOOKUP(A13, '02_Cashier_Register'!$A$14:$G$28, 2, FALSE), "Unknown") | C13: =IFERROR(VLOOKUP(A13, '02_Cashier_Register'!$A$14:$G$28, 3, FALSE), "Unknown") | D13: =COUNTIFS('03_Raw_POS_Journal'!$F$5:$F$678, A13, '03_Raw_POS_Journal'!$H$5:$H$678, "Sale Tender") | E13: =COUNTIFS('03_Raw_POS_Journal'!$F$5:$F$678, A13, '03_Raw_POS_Journal'!$H$5:$H$678, "No-Sale Drawer Opening") | F13: =IFERROR(IF(D13>0, (E13/D13)*100, 0), 0) | G13: =IFERROR(VLOOKUP(C13, '02_Cashier_Register'!$A$6:$F$9, 6, FALSE), 2.0) | H13: =MAX(0, E13 - (D13 * G13 / 100)) | I13: =IFERROR(AVERAGEIFS('03_Raw_POS_Journal'!$K$5:$K$678, '03_Raw_POS_Journal'!$D$5:$D$678, C13, '03_Raw_POS_Journal'!$H$5:$H$678, "Sale Tender"), IFERROR(AVERAGEIFS('03_Raw_POS_Journal'!$K$5:$K$678, '03_Raw_POS_Journal'!$H$5:$H$678, "Sale Tender"), 25.0)) | J13: =H13 * I13 * 0.40 | K13: =IFERROR(IF(_xlfn.STDEV.S($F$5:$F$19)=0, 0, (F13 - AVERAGE($F$5:$F$19)) / _xlfn.STDEV.S($F$5:$F$19)), 0) | L13: =IF(K13>=2.0, "HIGH RISK", IF(K13>=1.0, "ELEVATED RISK", "STANDARD"))
A14: C-110 | B14: =IFERROR(VLOOKUP(A14, '02_Cashier_Register'!$A$14:$G$28, 2, FALSE), "Unknown") | C14: =IFERROR(VLOOKUP(A14, '02_Cashier_Register'!$A$14:$G$28, 3, FALSE), "Unknown") | D14: =COUNTIFS('03_Raw_POS_Journal'!$F$5:$F$678, A14, '03_Raw_POS_Journal'!$H$5:$H$678, "Sale Tender") | E14: =COUNTIFS('03_Raw_POS_Journal'!$F$5:$F$678, A14, '03_Raw_POS_Journal'!$H$5:$H$678, "No-Sale Drawer Opening") | F14: =IFERROR(IF(D14>0, (E14/D14)*100, 0), 0) | G14: =IFERROR(VLOOKUP(C14, '02_Cashier_Register'!$A$6:$F$9, 6, FALSE), 2.0) | H14: =MAX(0, E14 - (D14 * G14 / 100)) | I14: =IFERROR(AVERAGEIFS('03_Raw_POS_Journal'!$K$5:$K$678, '03_Raw_POS_Journal'!$D$5:$D$678, C14, '03_Raw_POS_Journal'!$H$5:$H$678, "Sale Tender"), IFERROR(AVERAGEIFS('03_Raw_POS_Journal'!$K$5:$K$678, '03_Raw_POS_Journal'!$H$5:$H$678, "Sale Tender"), 25.0)) | J14: =H14 * I14 * 0.40 | K14: =IFERROR(IF(_xlfn.STDEV.S($F$5:$F$19)=0, 0, (F14 - AVERAGE($F$5:$F$19)) / _xlfn.STDEV.S($F$5:$F$19)), 0) | L14: =IF(K14>=2.0, "HIGH RISK", IF(K14>=1.0, "ELEVATED RISK", "STANDARD"))
A15: C-111 | B15: =IFERROR(VLOOKUP(A15, '02_Cashier_Register'!$A$14:$G$28, 2, FALSE), "Unknown") | C15: =IFERROR(VLOOKUP(A15, '02_Cashier_Register'!$A$14:$G$28, 3, FALSE), "Unknown") | D15: =COUNTIFS('03_Raw_POS_Journal'!$F$5:$F$678, A15, '03_Raw_POS_Journal'!$H$5:$H$678, "Sale Tender") | E15: =COUNTIFS('03_Raw_POS_Journal'!$F$5:$F$678, A15, '03_Raw_POS_Journal'!$H$5:$H$678, "No-Sale Drawer Opening") | F15: =IFERROR(IF(D15>0, (E15/D15)*100, 0), 0) | G15: =IFERROR(VLOOKUP(C15, '02_Cashier_Register'!$A$6:$F$9, 6, FALSE), 2.0) | H15: =MAX(0, E15 - (D15 * G15 / 100)) | I15: =IFERROR(AVERAGEIFS('03_Raw_POS_Journal'!$K$5:$K$678, '03_Raw_POS_Journal'!$D$5:$D$678, C15, '03_Raw_POS_Journal'!$H$5:$H$678, "Sale Tender"), IFERROR(AVERAGEIFS('03_Raw_POS_Journal'!$K$5:$K$678, '03_Raw_POS_Journal'!$H$5:$H$678, "Sale Tender"), 25.0)) | J15: =H15 * I15 * 0.40 | K15: =IFERROR(IF(_xlfn.STDEV.S($F$5:$F$19)=0, 0, (F15 - AVERAGE($F$5:$F$19)) / _xlfn.STDEV.S($F$5:$F$19)), 0) | L15: =IF(K15>=2.0, "HIGH RISK", IF(K15>=1.0, "ELEVATED RISK", "STANDARD"))
A16: C-112 | B16: =IFERROR(VLOOKUP(A16, '02_Cashier_Register'!$A$14:$G$28, 2, FALSE), "Unknown") | C16: =IFERROR(VLOOKUP(A16, '02_Cashier_Register'!$A$14:$G$28, 3, FALSE), "Unknown") | D16: =COUNTIFS('03_Raw_POS_Journal'!$F$5:$F$678, A16, '03_Raw_POS_Journal'!$H$5:$H$678, "Sale Tender") | E16: =COUNTIFS('03_Raw_POS_Journal'!$F$5:$F$678, A16, '03_Raw_POS_Journal'!$H$5:$H$678, "No-Sale Drawer Opening") | F16: =IFERROR(IF(D16>0, (E16/D16)*100, 0), 0) | G16: =IFERROR(VLOOKUP(C16, '02_Cashier_Register'!$A$6:$F$9, 6, FALSE), 2.0) | H16: =MAX(0, E16 - (D16 * G16 / 100)) | I16: =IFERROR(AVERAGEIFS('03_Raw_POS_Journal'!$K$5:$K$678, '03_Raw_POS_Journal'!$D$5:$D$678, C16, '03_Raw_POS_Journal'!$H$5:$H$678, "Sale Tender"), IFERROR(AVERAGEIFS('03_Raw_POS_Journal'!$K$5:$K$678, '03_Raw_POS_Journal'!$H$5:$H$678, "Sale Tender"), 25.0)) | J16: =H16 * I16 * 0.40 | K16: =IFERROR(IF(_xlfn.STDEV.S($F$5:$F$19)=0, 0, (F16 - AVERAGE($F$5:$F$19)) / _xlfn.STDEV.S($F$5:$F$19)), 0) | L16: =IF(K16>=2.0, "HIGH RISK", IF(K16>=1.0, "ELEVATED RISK", "STANDARD"))
... A19: C-115 | B19: =IFERROR(VLOOKUP(A19, '02_Cashier_Register'!$A$14:$G$28, 2, FALSE), "Unknown") | C19: =IFERROR(VLOOKUP(A19, '02_Cashier_Register'!$A$14:$G$28, 3, FALSE), "Unknown") | D19: =COUNTIFS('03_Raw_POS_Journal'!$F$5:$F$678, A19, '03_Raw_POS_Journal'!$H$5:$H$678, "Sale Tender") | E19: =COUNTIFS('03_Raw_POS_Journal'!$F$5:$F$678, A19, '03_Raw_POS_Journal'!$H$5:$H$678, "No-Sale Drawer Opening") | F19: =IFERROR(IF(D19>0, (E19/D19)*100, 0), 0) | G19: =IFERROR(VLOOKUP(C19, '02_Cashier_Register'!$A$6:$F$9, 6, FALSE), 2.0) | H19: =MAX(0, E19 - (D19 * G19 / 100)) | I19: =IFERROR(AVERAGEIFS('03_Raw_POS_Journal'!$K$5:$K$678, '03_Raw_POS_Journal'!$D$5:$D$678, C19, '03_Raw_POS_Journal'!$H$5:$H$678, "Sale Tender"), IFERROR(AVERAGEIFS('03_Raw_POS_Journal'!$K$5:$K$678, '03_Raw_POS_Journal'!$H$5:$H$678, "Sale Tender"), 25.0)) | J19: =H19 * I19 * 0.40 | K19: =IFERROR(IF(_xlfn.STDEV.S($F$5:$F$19)=0, 0, (F19 - AVERAGE($F$5:$F$19)) / _xlfn.STDEV.S($F$5:$F$19)), 0) | L19: =IF(K19>=2.0, "HIGH RISK", IF(K19>=1.0, "ELEVATED RISK", "STANDARD"))
A20: TOTAL / BENCHMARK | D20: =SUM(D5:D19) | E20: =SUM(E5:E19) | F20: =IFERROR(IF(D20>0, (E20/D20)*100, 0), 0) | H20: =SUM(H5:H19) | J20: =SUM(J5:J19)

Sheet 06_Engine_Overrides
A1: AUDIT ENGINE 3: LINE-ITEM VOIDS & SUPERVISORY AUTHORIZATIONS
A2: AUTOMATED CALCULATION: Analyzes pre-settlement line item deletions and evaluates supervisor credential concentration and terminal concurrency. Steel headers (#2F5597) update dynamically.
A4: PART 1: CASHIER PRE-SETTLEMENT LINE ITEM DELETIONS
A5: Cashier ID | B5: Cashier Name | C5: Branch | D5: Total Line Voids | E5: Cash Line Voids | F5: Total Line Void $ | G5: Cash Line Void $ | H5: Cash Line Void Ratio % | I5: Line Void Z-Score | J5: Line Void Risk Classification | K5: Total Overrides | L5: Concurrent Overrides | M5: Supervisor Authorization Tier
A6: C-101 | B6: =IFERROR(VLOOKUP(A6, '02_Cashier_Register'!$A$14:$G$28, 2, FALSE), "Unknown") | C6: =IFERROR(VLOOKUP(A6, '02_Cashier_Register'!$A$14:$G$28, 3, FALSE), "Unknown") | D6: =COUNTIFS('03_Raw_POS_Journal'!$F$5:$F$678, A6, '03_Raw_POS_Journal'!$H$5:$H$678, "Line Item Void") | E6: =COUNTIFS('03_Raw_POS_Journal'!$F$5:$F$678, A6, '03_Raw_POS_Journal'!$H$5:$H$678, "Line Item Void", '03_Raw_POS_Journal'!$I$5:$I$678, "Cash") | F6: =SUMIFS('03_Raw_POS_Journal'!$K$5:$K$678, '03_Raw_POS_Journal'!$F$5:$F$678, A6, '03_Raw_POS_Journal'!$H$5:$H$678, "Line Item Void") | G6: =SUMIFS('03_Raw_POS_Journal'!$K$5:$K$678, '03_Raw_POS_Journal'!$F$5:$F$678, A6, '03_Raw_POS_Journal'!$H$5:$H$678, "Line Item Void", '03_Raw_POS_Journal'!$I$5:$I$678, "Cash") | H6: =IFERROR(IF(D6>0, E6/D6, 0), 0) | I6: =IFERROR(IF(_xlfn.STDEV.S($E$6:$E$20)=0, 0, (E6 - AVERAGE($E$6:$E$20)) / _xlfn.STDEV.S($E$6:$E$20)), 0) | J6: =IF(I6>=2.0, "HIGH RISK", IF(I6>=1.0, "ELEVATED RISK", "STANDARD")) | K6: =COUNTIFS('03_Raw_POS_Journal'!$F$5:$F$678, A6, '03_Raw_POS_Journal'!$G$5:$G$678, "<>NONE") | L6: =IF(AND(ISNUMBER(SEARCH("COLLUSION", INDEX($I$25:$I$28, MATCH(C6, $C$25:$C$28, 0)))), ISNUMBER(SEARCH(A6, INDEX($F$25:$F$28, MATCH(C6, $C$25:$C$28, 0))))), COUNTIFS('03_Raw_POS_Journal'!$F$5:$F$678, A6, '03_Raw_POS_Journal'!$G$5:$G$678, INDEX($A$25:$A$28, MATCH(C6, $C$25:$C$28, 0))), 0) | M6: =IF(L6>=10, "HIGH CONCURRENCY", IF(L6>=3, "WATCHLIST", "STANDARD"))
A7: C-102 | B7: =IFERROR(VLOOKUP(A7, '02_Cashier_Register'!$A$14:$G$28, 2, FALSE), "Unknown") | C7: =IFERROR(VLOOKUP(A7, '02_Cashier_Register'!$A$14:$G$28, 3, FALSE), "Unknown") | D7: =COUNTIFS('03_Raw_POS_Journal'!$F$5:$F$678, A7, '03_Raw_POS_Journal'!$H$5:$H$678, "Line Item Void") | E7: =COUNTIFS('03_Raw_POS_Journal'!$F$5:$F$678, A7, '03_Raw_POS_Journal'!$H$5:$H$678, "Line Item Void", '03_Raw_POS_Journal'!$I$5:$I$678, "Cash") | F7: =SUMIFS('03_Raw_POS_Journal'!$K$5:$K$678, '03_Raw_POS_Journal'!$F$5:$F$678, A7, '03_Raw_POS_Journal'!$H$5:$H$678, "Line Item Void") | G7: =SUMIFS('03_Raw_POS_Journal'!$K$5:$K$678, '03_Raw_POS_Journal'!$F$5:$F$678, A7, '03_Raw_POS_Journal'!$H$5:$H$678, "Line Item Void", '03_Raw_POS_Journal'!$I$5:$I$678, "Cash") | H7: =IFERROR(IF(D7>0, E7/D7, 0), 0) | I7: =IFERROR(IF(_xlfn.STDEV.S($E$6:$E$20)=0, 0, (E7 - AVERAGE($E$6:$E$20)) / _xlfn.STDEV.S($E$6:$E$20)), 0) | J7: =IF(I7>=2.0, "HIGH RISK", IF(I7>=1.0, "ELEVATED RISK", "STANDARD")) | K7: =COUNTIFS('03_Raw_POS_Journal'!$F$5:$F$678, A7, '03_Raw_POS_Journal'!$G$5:$G$678, "<>NONE") | L7: =IF(AND(ISNUMBER(SEARCH("COLLUSION", INDEX($I$25:$I$28, MATCH(C7, $C$25:$C$28, 0)))), ISNUMBER(SEARCH(A7, INDEX($F$25:$F$28, MATCH(C7, $C$25:$C$28, 0))))), COUNTIFS('03_Raw_POS_Journal'!$F$5:$F$678, A7, '03_Raw_POS_Journal'!$G$5:$G$678, INDEX($A$25:$A$28, MATCH(C7, $C$25:$C$28, 0))), 0) | M7: =IF(L7>=10, "HIGH CONCURRENCY", IF(L7>=3, "WATCHLIST", "STANDARD"))
A8: C-103 | B8: =IFERROR(VLOOKUP(A8, '02_Cashier_Register'!$A$14:$G$28, 2, FALSE), "Unknown") | C8: =IFERROR(VLOOKUP(A8, '02_Cashier_Register'!$A$14:$G$28, 3, FALSE), "Unknown") | D8: =COUNTIFS('03_Raw_POS_Journal'!$F$5:$F$678, A8, '03_Raw_POS_Journal'!$H$5:$H$678, "Line Item Void") | E8: =COUNTIFS('03_Raw_POS_Journal'!$F$5:$F$678, A8, '03_Raw_POS_Journal'!$H$5:$H$678, "Line Item Void", '03_Raw_POS_Journal'!$I$5:$I$678, "Cash") | F8: =SUMIFS('03_Raw_POS_Journal'!$K$5:$K$678, '03_Raw_POS_Journal'!$F$5:$F$678, A8, '03_Raw_POS_Journal'!$H$5:$H$678, "Line Item Void") | G8: =SUMIFS('03_Raw_POS_Journal'!$K$5:$K$678, '03_Raw_POS_Journal'!$F$5:$F$678, A8, '03_Raw_POS_Journal'!$H$5:$H$678, "Line Item Void", '03_Raw_POS_Journal'!$I$5:$I$678, "Cash") | H8: =IFERROR(IF(D8>0, E8/D8, 0), 0) | I8: =IFERROR(IF(_xlfn.STDEV.S($E$6:$E$20)=0, 0, (E8 - AVERAGE($E$6:$E$20)) / _xlfn.STDEV.S($E$6:$E$20)), 0) | J8: =IF(I8>=2.0, "HIGH RISK", IF(I8>=1.0, "ELEVATED RISK", "STANDARD")) | K8: =COUNTIFS('03_Raw_POS_Journal'!$F$5:$F$678, A8, '03_Raw_POS_Journal'!$G$5:$G$678, "<>NONE") | L8: =IF(AND(ISNUMBER(SEARCH("COLLUSION", INDEX($I$25:$I$28, MATCH(C8, $C$25:$C$28, 0)))), ISNUMBER(SEARCH(A8, INDEX($F$25:$F$28, MATCH(C8, $C$25:$C$28, 0))))), COUNTIFS('03_Raw_POS_Journal'!$F$5:$F$678, A8, '03_Raw_POS_Journal'!$G$5:$G$678, INDEX($A$25:$A$28, MATCH(C8, $C$25:$C$28, 0))), 0) | M8: =IF(L8>=10, "HIGH CONCURRENCY", IF(L8>=3, "WATCHLIST", "STANDARD"))
